Workbook

Sheet 00_LaaS收益来源
A1: 同等条件下：LaaS 相比能源托管的收益体现在哪里
A2: 本页专门回答：在同样灯具规模、同样电价、同样业主年度付费预算下，LaaS相对能源托管的增量收益来自哪里；同时指出LaaS更高CAPEX和平台成本带来的回报压力。
A4: 同等条件快照
A5: 条件项 | B5: 单位 | C5: 数值/状态 | D5: 说明
A6: 灯具数量 | B6: 盏 | C6: ='03_Baseline'!D5 -> 4568 | D6: 两种模式一致
A7: 电价 | B7: 元/kWh | C7: ='03_Baseline'!D11 -> 0.69000015 | D7: 两种模式一致
A8: 基准年电费 | B8: 元/年 | C8: ='03_Baseline'!D12 -> 2120554 | D8: 两种模式一致
A9: 基准年运维费 | B9: 元/年 | C9: ='03_Baseline'!D14 -> 609997 | D9: 两种模式一致
A10: 业主年度付费预算 | B10: 元/年 | C10: ='03_Baseline'!D16 -> 2600000 | D10: 默认两种模式均为100万元/年，可在Inputs修改
A11: 能源托管/LaaS年费是否相同 | B11: TRUE/FALSE | C11: ='04_Mode_Params'!C6='04_Mode_Params'!D6 -> 0 | D11: TRUE表示在同样业主付费条件下比较
A13: LaaS 相对能源托管的增量收益/成本拆解
A14: 维度 | B14: 口径 | C14: 能源托管/EMC | D14: LaaS/AI订阅 | E14: LaaS相对增益 | F14: 增益归属 | G14: 结论 | H14: 说明
A15: 综合节电率 | B15: 越高越好 | C15: ='04_Mode_Params'!C8 -> 0.51521961 | D15: ='04_Mode_Params'!D8 -> 0.75 | E15: =D15-C15 | F15: 业主/承担电费方 | G15: =IF(E15>0,"LaaS更优","未体现优势") | H15: LaaS通过AI调光、异常识别、精细化控制提升节电率。
A16: 首年节电量 | B16: kWh/年，越高越好 | C16: ='03_Baseline'!D10*'04_Mode_Params'!C8 -> 1583406.9 | D16: ='03_Baseline'!D10*'04_Mode_Params'!D8 -> 2304949.5 | E16: =D16-C16 | F16: 业主/承担电费方 | G16: =IF(E16>0,"LaaS更优","未体现优势") | H16: 基于现状年用电量×节电率。
A17: 首年电费节省 | B17: 元/年，越高越好 | C17: ='03_Baseline'!D12-'04_Mode_Params'!C9 -> 1092551 | D17: ='03_Baseline'!D12-'04_Mode_Params'!D9 -> 1590415.5 | E17: =D17-C17 | F17: 业主/承担电费方 | G17: =IF(E17>0,"LaaS更优","未体现优势") | H17: 如果业主继续付电费，该收益主要归业主；如果服务商承担电费，该收益归服务商。
A18: 业主年度总支出 | B18: 元/年，越低越好 | C18: ='04_Mode_Params'!C19 -> 3370303 | D18: ='04_Mode_Params'!D19 -> 2730138.5 | E18: =C18-D18 -> 640164.5 | F18: 业主 | G18: =IF(E18>0,"LaaS让业主少支出",IF(E18<0,"LaaS让业主多支出","相同")) | H18: 服务费+业主承担电费+保留管理成本。
A19: 业主年度净节省 | B19: 元/年，越高越好 | C19: ='04_Mode_Params'!C20 -> -639752 | D19: ='04_Mode_Params'!D20 -> 412.5 | E19: =D19-C19 -> 640164.5 | F19: 业主 | G19: =IF(E19>0,"LaaS让业主多节省",IF(E19<0,"能源托管更多节省","相同")) | H19: 相对不改造基准总成本。
A20: 服务商年度收入合计 | B20: 元/年，越高越好 | C20: ='04_Mode_Params'!C16 -> 2342300 | D20: ='04_Mode_Params'!D16 -> 2200000 | E20: =D20-C20 -> -142300 | F20: 服务商 | G20: =IF(E20>0,"LaaS收入更高",IF(E20<0,"能源托管收入更高","相同")) | H20: 固定服务/订阅费+第三方收入；默认年费相同，收入增量通常来自增值服务。
A21: 服务商年度现金成本合计 | B21: 元/年，越低越好 | C21: ='04_Mode_Params'!C17 -> 609997 | D21: ='04_Mode_Params'!D17 -> 409500 | E21: =C21-D21 -> 200497 | F21: 服务商 | G21: =IF(E21>0,"LaaS成本更低",IF(E21<0,"LaaS成本更高","相同")) | H21: LaaS运维可能下降，但平台AI与升级成本通常上升。
A22: 其中：运维成本 | B22: 元/年，越低越好 | C22: ='04_Mode_Params'!C13 -> 394236.88 | D22: ='04_Mode_Params'!D13 -> 144992.46 | E22: =C22-D22 -> 249244.43 | F22: 服务商 | G22: =IF(E22>0,"LaaS运维省钱",IF(E22<0,"LaaS运维更贵","相同")) | H22: LaaS通过远程诊断、工单系统、预测性维护降低人工巡检与抢修。
A23: 其中：平台/升级成本 | B23: 元/年，越低越好 | C23: ='04_Mode_Params'!C14+'04_Mode_Params'!C15 -> 161820.09 | D23: ='04_Mode_Params'!D14+'04_Mode_Params'!D15 -> 185155.28 | E23: =C23-D23 -> -23335.194 | F23: 服务商 | G23: =IF(E23>0,"LaaS平台/升级成本更低",IF(E23<0,"LaaS平台/升级成本更高","相同")) | H23: LaaS通常更高，这是其商业模型必须覆盖的成本。
A24: 服务商年度净经营现金流 | B24: 元/年，越高越好 | C24: ='04_Mode_Params'!C18 -> 1732303 | D24: ='04_Mode_Params'!D18 -> 1790500 | E24: =D24-C24 -> 58197 | F24: 服务商 | G24: =IF(E24>0,"LaaS经营现金流更高",IF(E24<0,"能源托管经营现金流更高","相同")) | H24: 收入合计−年度现金成本，不含Y0 CAPEX。
A25: 初始CAPEX总额 | B25: 元，越低越好 | C25: ='04_Mode_Params'!C5 -> 3539400 | D25: ='04_Mode_Params'!D5 -> 3539400 | E25: =C25-D25 -> 0 | F25: 服务商/资方 | G25: =IF(E25>0,"LaaS初始投资更低",IF(E25<0,"LaaS初始投资更高","相同")) | H25: LaaS硬件与平台配置更高时，CAPEX劣势会拖累回收。
A26: 10年累计净现金流 | B26: 元，越高越好 | C26: ='05_Annual_Model'!M24 -> 13783630 | D26: ='05_Annual_Model'!M51 -> 14365600 | E26: =D26-C26 -> 581970 | F26: 服务商/资方 | G26: =IF(E26>0,"LaaS累计现金流更好",IF(E26<0,"能源托管累计现金流更好","相同")) | H26: 含Y0 CAPEX，是服务商是否回本的硬指标。
A27: NPV | B27: 元，越高越好 | C27: ='05_Annual_Model'!C25 -> 7423046.1 | D27: ='05_Annual_Model'!C52 -> 7122361.1 | E27: =D27-C27 -> -300685.01 | F27: 服务商/资方 | G27: =IF(E27>0,"LaaS NPV更好",IF(E27<0,"能源托管NPV更好","相同")) | H27: 折现后判断是否达到资金成本要求。
A28: IRR | B28: %，越高越好 | C28: ='05_Annual_Model'!C26 -> 0.4797081 | D28: ='05_Annual_Model'!C53 -> 0.63551735 | E28: =D28-C28 -> 0.15580925 | F28: 服务商/资方 | G28: =IF(E28>0,"LaaS IRR更高",IF(E28<0,"能源托管IRR更高","相同")) | H28: 与资金成本比较。
A29: NPV=0所需年费 | B29: 元/年，越低越好 | C29: ='06_Sensitivity'!C5 | D29: ='06_Sensitivity'!C6 | E29: =C29-D29 | F29: 服务商/业主谈判 | G29: =IF(E29>0,"LaaS所需年费更低",IF(E29<0,"LaaS所需年费更高","相同")) | H29: 若LaaS所需年费更高，需要用增值收益、资产转让或降本补齐。
A31: 结论框架
A32: 业主侧结论
B33: LaaS是否更适合业主，核心看“业主年度总支出是否更低、净节省是否更高”。默认假设下，LaaS因节电率更高，业主侧节省通常更明显。
A34: 服务商侧结论
B35: LaaS的运维成本可能下降，但更高CAPEX、平台AI成本和升级储备会稀释收益。若年费同为100万元，必须检查NPV、IRR和10年累计现金流是否能覆盖投资。

Sheet 01_Dashboard
A1: 通用版财务模型｜能源托管 vs LaaS/AI订阅
A2: 先看 00_LaaS收益来源 判断Laas增量价值，再到本页看双方核心财务指标。
A4: 项目基准
A5: 灯具数量 | B5: 盏 | C5: ='03_Baseline'!D5
A6: 基准年电费 | B6: 元/年 | C6: ='03_Baseline'!D12
A7: 基准年运维费 | B7: 元/年 | C7: ='03_Baseline'!D14
A8: 基准年总成本 | B8: 元/年 | C8: ='03_Baseline'!D15
A9: 业主10年预算总额 | B9: 元 | C9: ='03_Baseline'!D17
A10: 10年不改造总成本 | B10: 元 | C10: ='03_Baseline'!D18
A12: 两种模式核心结果
A13: 指标 | B13: 单位 | C13: 能源托管/EMC | D13: LaaS/AI订阅 | E13: LaaS相对差异 | F13: 判断 | G13: 说明
A14: 初始CAPEX总额 | B14: 元 | C14: ='04_Mode_Params'!C5 | D14: ='04_Mode_Params'!D5 | E14: =C14-D14 | F14: =IF(E14>0,"LaaS更优/成本更低",IF(E14<0,"能源托管更优/成本更低","相同")) | G14: 服务商Y0投入，越低越容易回本
A15: 服务商年度收入合计 | B15: 元/年 | C15: ='04_Mode_Params'!C16 | D15: ='04_Mode_Params'!D16 | E15: =D15-C15 | F15: =IF(E15>0,"LaaS更高",IF(E15<0,"能源托管更高","相同")) | G15: 服务费/订阅费+其他第三方收入
A16: 服务商年度现金成本合计 | B16: 元/年 | C16: ='04_Mode_Params'!C17 | D16: ='04_Mode_Params'!D17 | E16: =C16-D16 | F16: =IF(E16>0,"LaaS更优/成本更低",IF(E16<0,"能源托管更优/成本更低","相同")) | G16: 电费成本+运维+平台+备件，不含CAPEX
A17: 服务商年度净经营现金流 | B17: 元/年 | C17: ='04_Mode_Params'!C18 | D17: ='04_Mode_Params'!D18 | E17: =D17-C17 | F17: =IF(E17>0,"LaaS更高",IF(E17<0,"能源托管更高","相同")) | G17: 年度收入−年度现金成本，不含Y0 CAPEX
A18: 10年累计净现金流 | B18: 元 | C18: ='05_Annual_Model'!M24 -> 13783630 | D18: ='05_Annual_Model'!M51 -> 14365600 | E18: =D18-C18 | F18: =IF(E18>0,"LaaS更高",IF(E18<0,"能源托管更高","相同")) | G18: 含Y0 CAPEX
A19: NPV | B19: 元 | C19: ='05_Annual_Model'!C25 -> 7423046.1 | D19: ='05_Annual_Model'!C52 -> 7122361.1 | E19: =D19-C19 | F19: =IF(E19>0,"LaaS更高",IF(E19<0,"能源托管更高","相同")) | G19: 折现率来自Inputs
A20: IRR | B20: % | C20: ='05_Annual_Model'!C26 -> 0.4797081 | D20: ='05_Annual_Model'!C53 -> 0.63551735 | E20: =D20-C20 | F20: =IF(E20>0,"LaaS更高",IF(E20<0,"能源托管更高","相同")) | G20: 服务商项目内部收益率
A21: 10年ROI | B21: % | C21: ='05_Annual_Model'!C27 -> 4.8943408 | D21: ='05_Annual_Model'!C54 -> 5.058767 | E21: =D21-C21 | F21: =IF(E21>0,"LaaS更高",IF(E21<0,"能源托管更高","相同")) | G21: 10年累计净现金流÷初始CAPEX
A22: 静态回收期 | B22: 年 | C22: ='05_Annual_Model'!C28 | D22: ='05_Annual_Model'!C55 | E22: =IF(OR(C22="未回收",D22="未回收"),"看回收状态",C22-D22) | F22: =IF(D22=C22,"相同",IF(D22="未回收","能源托管回收更好",IF(C22="未回收","LaaS回收更好",IF(D22<C22,"LaaS回收更快","能源托管回收更快")))) | G22: 累计现金流首次转正年份
A23: 业主年度总支出 | B23: 元/年 | C23: ='04_Mode_Params'!C19 | D23: ='04_Mode_Params'!D19 | E23: =C23-D23 | F23: =IF(E23>0,"LaaS更优/成本更低",IF(E23<0,"能源托管更优/成本更低","相同")) | G23: 业主支付电费+服务费+保留管理成本
A24: 业主年度净节省 | B24: 元/年 | C24: ='04_Mode_Params'!C20 | D24: ='04_Mode_Params'!D20 | E24: =D24-C24 | F24: =IF(E24>0,"LaaS更高",IF(E24<0,"能源托管更高","相同")) | G24: 相对不改造情形
A25: 业主节省率 | B25: % | C25: ='04_Mode_Params'!C21 | D25: ='04_Mode_Params'!D21 | E25: =D25-C25 | F25: =IF(E25>0,"LaaS更高",IF(E25<0,"能源托管更高","相同")) | G25: 业主净节省÷基准年总成本
A26: NPV=0所需年费 | B26: 元/年 | C26: ='06_Sensitivity'!C5 | D26: ='06_Sensitivity'!C6 | E26: =C26-D26 | F26: =IF(E26>0,"LaaS更优/成本更低",IF(E26<0,"能源托管更优/成本更低","相同")) | G26: 服务商达到折现率要求的参考底价
A28: 读法提示
A29: 1 | B29: 业主侧先看“业主年度总支出”是否低于基准年总成本。服务费不是业主收入，而是业主支出。
A30: 2 | B30: 服务商侧先看“年度净经营现金流”是否能覆盖Y0 CAPEX；如果10年累计现金流仍为负，则年费/成本/CAPEX结构需要重做。
A31: 3 | B31: Laas的优势不应只看节电率，还要看运维成本下降、持续升级能力、增值收入和客户黏性；但这些优势必须覆盖更高CAPEX和平台成本。
A32: 4 | B32: 本版已避免“成本用负数列示再相加”带来的误读，所有成本均为正数并在公式中扣减。

Sheet 02_Inputs
A1: 通用输入假设｜能源托管 vs LaaS/AI订阅
A2: 蓝色数字为可修改输入。所有成本均按“正数成本/支出”录入，净现金流采用显性减法，避免把成本当收入相加。
A4: 模块 | B4: 参数 | C4: 单位 | D4: 输入值 | E4: 来源/依据 | F4: 是否常改 | G4: 备注 | H4: 校验
A5: 基础参数 | B5: 模型期 | C5: 年 | D5: 10 | E5: 用户示例/通用模型 | F5: 是 | G5: 模板当前展开Y0-Y10；如需15年可继续扩展年度列。 | H5: >0
A6: 基础参数 | B6: 灯具数量 | C6: 盏 | D6: 4568 | E6: 用户示例假设 | F6: 是 | G6: 用于计算总能耗、总运维费、总CAPEX。 | H6: >0
A7: 基础参数 | B7: 业主年度服务费预算/付费上限 | C7: 元/年 | D7: 2600000 | E7: 用户示例假设 | F7: 是 | G7: 这里是业主每年可支付给服务商的固定预算，不是业主一次性CAPEX。 | H7: >=0
A8: 基础参数 | B8: 电价 | C8: 元/kWh | D8: 0.69000015 | E8: 用户示例假设 | F8: 是 | G8: 如存在峰谷电价，可替换为加权平均电价。 | H8: >=0
A9: 基础参数 | B9: 现状单灯功率 | C9: W/盏 | D9: 167.567 | E9: 模型默认假设，需现场替换 | F9: 是 | G9: 用于估算现状年用电量。 | H9: >0
A10: 基础参数 | B10: 每日亮灯小时 | C10: 小时/天 | D10: 11 | E10: 模型默认假设，需现场替换 | F10: 是 | G10: 路灯常按10-12小时估算，具体按当地控制策略替换。 | H10: 0-24
A11: 基础参数 | B11: 年运行天数 | C11: 天/年 | D11: 365 | E11: 模型默认假设 | F11: 是 | G11: 通常取365。 | H11: >0
A12: 基础参数 | B12: 现状运维单价 | C12: 元/盏/年 | D12: 133.537 | E12: 用户示例假设 | F12: 是 | G12: 业主现状运维支出。 | H12: >=0
A13: 基础参数 | B13: 折现率 | C13: % | D13: 0.12 | E13: 模型默认假设 | F13: 是 | G13: 用于服务商NPV，可按资金成本/项目风险调整。 | H13: >=0
A14: 基础参数 | B14: 电价年增长率 | C14: % | D14: 0 | E14: 模型默认假设 | F14: 可选 | G14: 若不确定，可先设为0。 | H14: >=0
A15: 基础参数 | B15: 服务商成本年增长率 | C15: % | D15: 0 | E15: 模型默认假设 | F15: 可选 | G15: 用于运维、平台、备件等成本年度增长。 | H15: >=0
A16: 基础参数 | B16: 服务费年增长率 | C16: % | D16: 0 | E16: 模型默认假设 | F16: 可选 | G16: 若合同约定服务费递增，可在此填写。 | H16: >=0
... A27: 能源托管/EMC | B27: 资产转让收入 | C27: 元 | D27: 0 | E27: 模型默认假设 | F27: 可选 | G27: 资产买断/转让收入；仅在资产转让年份进入服务商现金流。 | H27: >=0
A28: LaaS/AI订阅 | B28: 初始CAPEX单价 | C28: 元/盏 | D28: =VLOOKUP($D$48,$A$52:$G$54,3,FALSE) -> 774.82487 | E28: 模型默认假设，需报价替换 | F28: 是 | G28: 通常含AI、通信、传感、平台接入，可能高于普通托管。 | H28: >=0
A29: LaaS/AI订阅 | B29: 订阅费收入 | C29: 元/年 | D29: 2200000 | E29: 默认等于业主年度预算 | F29: 是 | G29: 服务商每年从业主获得的订阅费。 | H29: >=0
A30: LaaS/AI订阅 | B30: 其他/第三方收入 | C30: 元/年 | D30: 0 | E30: 模型默认假设 | F30: 可选 | G30: 广告、数据服务、城市接口等收入；不自动计入业主支出。 | H30: >=0
A31: LaaS/AI订阅 | B31: 综合节电率 | C31: % | D31: =MAX($D$21+0.03,VLOOKUP($D$48,$A$52:$G$54,2,FALSE)) -> 0.75 | E31: 模型默认假设，需项目测算替换 | F31: 是 | G31: LED+AI调光+异常识别后的综合节电率。 | H31: 0-95%
A32: LaaS/AI订阅 | B32: 服务商运维现金成本 | C32: 元/盏/年 | D32: =VLOOKUP($D$48,$A$52:$G$54,4,FALSE) -> 31.740905 | E32: 模型默认假设，需项目测算替换 | F32: 是 | G32: AI巡检、远程诊断、工单化后可能降低。 | H32: >=0
A33: LaaS/AI订阅 | B33: 平台/AI升级成本 | C33: 元/年 | D33: =VLOOKUP($D$48,$A$52:$G$54,5,FALSE) -> 185155.28 | E33: 模型默认假设 | F33: 是 | G33: 算法、平台、通信、云资源、版本升级等年度成本。 | H33: >=0
A34: LaaS/AI订阅 | B34: 升级/备件储备 | C34: 元/年 | D34: =VLOOKUP($D$48,$A$52:$G$54,6,FALSE) -> 79352.263 | E34: 模型默认假设 | F34: 是 | G34: 硬件升级、备件与系统迭代预留。 | H34: >=0
A35: LaaS/AI订阅 | B35: 服务商是否承担电费 | C35: 0/1 | D35: 0 | E35: 模型开关 | F35: 是 | G35: 0=业主继续支付电费；1=服务商承担电费。 | H35: 0或1
A36: LaaS/AI订阅 | B36: 资产转让年份 | C36: 年 | D36: 0 | E36: 模型默认假设 | F36: 可选 | G36: 0表示不转让；如第5年转让则填5。 | H36: 0-模型期
A37: LaaS/AI订阅 | B37: 资产转让收入 | C37: 元 | D37: 0 | E37: 模型默认假设 | F37: 可选 | G37: 资产买断/转让收入；仅在资产转让年份进入服务商现金流。 | H37: >=0
A44: 商业条款/收费机制（可调整）
A45: 首期款(元)/客户预付 | D45: 0
A46: 后4年年费减免(元/年) | D46: 0
A47: 方案标识 | D47: Tier10_Conservative
A48: 产品类型(product_key) | D48: AI_lightning_grid
A49: 灯杆数量(根) | D49: 2345
A50: 产品对比（来自 defaults.py PRODUCT_ROWS；切换 D48 将联动 D28/D31/D32:D34）
A51: 产品(product_key) | B51: 节电率下限(推导) | C51: LaaS CAPEX/盏 | D51: 人工/维修(元/盏/年) | E51: 平台费(元/年) | F51: 备件(元/年) | G51: 说明
A52: AI_lightning_grid | B52: 0.58695652 | C52: 774.82487 | D52: 31.740905 | E52: 185155.28 | F52: 79352.263 | G52: 基础并网AI灯
A53: AI_battery_integrated_grid | B53: 0.64583333 | C53: 849.28856 | D53: 30.755865 | E53: 179409.21 | F53: 76889.663 | G53: 含电池：应急/出勤更少
A54: AI_plus_solar_offgrid | B54: 0.999 | C54: 734.57423 | D54: 9.8504031 | E54: 57460.685 | F54: 24626.008 | G54: 离网太阳能：电费≈0

Sheet 03_Baseline
A1: 现状基准测算｜不改造情形
A2: 所有节省额均相对于本页“不改造”基准计算。
A4: 项目 | B4: 单位 | C4: 公式/口径 | D4: 计算值 | E4: 备注 | F4: 校验
A5: 灯具数量 | B5: 盏 | C5: 来自Inputs | D5: ='02_Inputs'!D6 | F5: 灯杆数量(根) | G5: ='02_Inputs'!D49
A6: 现状单灯功率 | B6: W/盏 | C6: 来自Inputs | D6: ='02_Inputs'!D9
A7: 每日亮灯小时 | B7: 小时/天 | C7: 来自Inputs | D7: ='02_Inputs'!D10
A8: 年运行天数 | B8: 天/年 | C8: 来自Inputs | D8: ='02_Inputs'!D11
A9: 年运行小时 | B9: 小时/年 | C9: 每日亮灯小时×年运行天数 | D9: =D7*D8
A10: 现状年用电量 | B10: kWh/年 | C10: 灯具数量×单灯功率÷1000×年运行小时 | D10: =D5*D6/1000*D9 -> 3073266
A11: 电价 | B11: 元/kWh | C11: 来自Inputs | D11: ='02_Inputs'!D8 -> 0.69000015
A12: 基准年电费 | B12: 元/年 | C12: 现状年用电量×电价 | D12: =D10*D11 -> 2120554
A13: 现状运维单价 | B13: 元/盏/年 | C13: 来自Inputs | D13: ='02_Inputs'!D12 -> 133.537
A14: 基准年运维费 | B14: 元/年 | C14: 灯具数量×现状运维单价 | D14: =D5*D13 -> 609997
A15: 基准年总成本 | B15: 元/年 | C15: 基准年电费+基准年运维费 | D15: =D12+D14 -> 2730551
A16: 业主年度服务费预算 | B16: 元/年 | C16: 来自Inputs | D16: ='02_Inputs'!D7
A17: 10年业主预算总额 | B17: 元 | C17: 年度预算×模型期 | D17: =D16*'02_Inputs'!D5
A18: 10年不改造总成本 | B18: 元 | C18: 年度基准总成本合计，考虑增长率 | D18: =SUM('05_Annual_Model'!D8:M8)

Sheet 04_Mode_Params
A1: 模式参数对比｜同一项目条件下的两种模式
A2: 注意：业主年度预算、灯具数量、电价、现状运维费等基础条件相同；模式差异只体现在CAPEX、节电率、运维成本、平台成本、备件储备、是否承担电费等。
A4: 项目 | B4: 单位 | C4: 能源托管/EMC | D4: LaaS/AI订阅 | E4: LaaS相对差异 | F4: 计算口径 | G4: 归属方 | H4: 备注
A5: 初始CAPEX总额 | B5: 元 | C5: ='02_Inputs'!D6*'02_Inputs'!D18 | D5: ='02_Inputs'!D6*'02_Inputs'!D28 | E5: =C5-D5 | F5: 灯具数量×CAPEX单价 | G5: 服务商 | H5: Y0一次性投入，现金流中扣减
A6: 年度服务/订阅收入 | B6: 元/年 | C6: ='02_Inputs'!D19 | D6: ='02_Inputs'!D29 | E6: =D6-C6 | F6: 来自输入假设 | G6: 服务商收入/业主支出 | H6: 业主固定支付给服务商
A7: 其他/第三方收入 | B7: 元/年 | C7: ='02_Inputs'!D20 | D7: ='02_Inputs'!D30 | E7: =D7-C7 | F7: 来自输入假设 | G7: 服务商收入 | H7: 默认不计入业主支出，避免双算
A8: 综合节电率 | B8: % | C8: ='02_Inputs'!D21 | D8: ='02_Inputs'!D31 | E8: =D8-C8 | F8: 来自输入假设 | G8: 承担电费一方 | H8: 影响改造后电费
A9: 改造后首年电费总额 | B9: 元/年 | C9: ='03_Baseline'!D12*(1-C8) | D9: ='03_Baseline'!D12*(1-D8) | E9: =C9-D9 | F9: 基准电费×(1-节电率) | G9: 承担电费一方 | H9: 先计算物理电费，再由开关分配承担方
A10: 服务商是否承担电费 | B10: 0/1 | C10: ='02_Inputs'!D25 | D10: ='02_Inputs'!D35 | E10: =D10-C10 | F10: 来自输入假设 | G10: 现金流分配 | H10: 0=业主承担；1=服务商承担
A11: 服务商电费成本 | B11: 元/年 | C11: =C9*C10 | D11: =D9*D10 | E11: =C11-D11 | F11: 改造后电费×开关 | G11: 服务商成本 | H11: 成本为正数，净现金流中扣减
A12: 业主支付电费 | B12: 元/年 | C12: =C9*(1-C10) | D12: =D9*(1-D10) | E12: =D12-C12 | F12: 改造后电费×(1-开关) | G12: 业主支出 | H12: 业主若不承担则为0
A13: 服务商运维成本 | B13: 元/年 | C13: ='02_Inputs'!D6*'02_Inputs'!D22 | D13: ='02_Inputs'!D6*'02_Inputs'!D32 | E13: =C13-D13 | F13: 灯具数量×服务商运维现金成本单价 | G13: 服务商成本 | H13: 成本为正数，净现金流中扣减
A14: 平台/管理/AI成本 | B14: 元/年 | C14: ='02_Inputs'!D23 | D14: ='02_Inputs'!D33 | E14: =C14-D14 | F14: 来自输入假设 | G14: 服务商成本 | H14: 成本为正数，净现金流中扣减
A15: 备件/升级储备 | B15: 元/年 | C15: ='02_Inputs'!D24 | D15: ='02_Inputs'!D34 | E15: =C15-D15 | F15: 来自输入假设 | G15: 服务商成本 | H15: 成本为正数，净现金流中扣减
A16: 服务商年度收入合计 | B16: 元/年 | C16: =C6+C7 | D16: =D6+D7 | E16: =D16-C16 | F16: 服务/订阅收入+其他/第三方收入 | G16: 服务商 | H16: 不含资产转让一次性收入
A17: 服务商年度现金成本合计 | B17: 元/年 | C17: =C11+C13+C14+C15 | D17: =D11+D13+D14+D15 | E17: =C17-D17 | F17: 服务商电费成本+运维成本+平台成本+备件储备 | G17: 服务商 | H17: 不含初始CAPEX
A18: 服务商年度净经营现金流 | B18: 元/年 | C18: =C16-C17 | D18: =D16-D17 | E18: =D18-C18 | F18: 收入合计−现金成本合计 | G18: 服务商 | H18: 不含Y0 CAPEX
A19: 业主年度总支出 | B19: 元/年 | C19: =C12+C6+'02_Inputs'!D17 | D19: =D12+D6+'02_Inputs'!D17 | E19: =C19-D19 | F19: 业主支付电费+服务/订阅费+业主保留管理成本 | G19: 业主 | H19: 不包含服务商第三方收入
A20: 业主年度净节省 | B20: 元/年 | C20: ='03_Baseline'!D15-C19 | D20: ='03_Baseline'!D15-D19 | E20: =D20-C20 | F20: 基准年总成本−业主年度总支出 | G20: 业主 | H20: 正数表示业主省钱
A21: 业主节省率 | B21: % | C21: =C20/'03_Baseline'!D15 | D21: =D20/'03_Baseline'!D15 | E21: =D21-C21 | F21: 业主净节省÷基准年总成本 | G21: 业主 | H21: 用于判断业主接受度

Sheet 05_Annual_Model
A1: 年度现金流模型｜显性减法与承担方拆分版
A2: 本版修正：成本行全部为正数；净现金流=收入−成本；服务商其他/第三方收入不自动算作业主支出；电费按“是否由服务商承担”开关在服务商与业主之间分配。
A4: 模块 | B4: 指标 | C4: Y0 | D4: Y1 | E4: Y2 | F4: Y3 | G4: Y4 | H4: Y5 | I4: Y6 | J4: Y7 | K4: Y8 | L4: Y9 | M4: Y10
A5: A. 基准情形（不改造）
A6: 基准 | B6: 基准年电费 | C6: =0 | D6: ='03_Baseline'!$D$12*(1+'02_Inputs'!$D$14)^(1-1) | E6: ='03_Baseline'!$D$12*(1+'02_Inputs'!$D$14)^(2-1) | F6: ='03_Baseline'!$D$12*(1+'02_Inputs'!$D$14)^(3-1) | G6: ='03_Baseline'!$D$12*(1+'02_Inputs'!$D$14)^(4-1) | H6: ='03_Baseline'!$D$12*(1+'02_Inputs'!$D$14)^(5-1) | I6: ='03_Baseline'!$D$12*(1+'02_Inputs'!$D$14)^(6-1) | J6: ='03_Baseline'!$D$12*(1+'02_Inputs'!$D$14)^(7-1) | K6: ='03_Baseline'!$D$12*(1+'02_Inputs'!$D$14)^(8-1) | L6: ='03_Baseline'!$D$12*(1+'02_Inputs'!$D$14)^(9-1) | M6: ='03_Baseline'!$D$12*(1+'02_Inputs'!$D$14)^(10-1)
A7: 基准 | B7: 基准年运维费 | C7: =0 | D7: ='03_Baseline'!$D$14*(1+'02_Inputs'!$D$15)^(1-1) | E7: ='03_Baseline'!$D$14*(1+'02_Inputs'!$D$15)^(2-1) | F7: ='03_Baseline'!$D$14*(1+'02_Inputs'!$D$15)^(3-1) | G7: ='03_Baseline'!$D$14*(1+'02_Inputs'!$D$15)^(4-1) | H7: ='03_Baseline'!$D$14*(1+'02_Inputs'!$D$15)^(5-1) | I7: ='03_Baseline'!$D$14*(1+'02_Inputs'!$D$15)^(6-1) | J7: ='03_Baseline'!$D$14*(1+'02_Inputs'!$D$15)^(7-1) | K7: ='03_Baseline'!$D$14*(1+'02_Inputs'!$D$15)^(8-1) | L7: ='03_Baseline'!$D$14*(1+'02_Inputs'!$D$15)^(9-1) | M7: ='03_Baseline'!$D$14*(1+'02_Inputs'!$D$15)^(10-1)
A8: 基准 | B8: 基准年总成本 | C8: =0 | D8: =D6+D7 | E8: =E6+E7 | F8: =F6+F7 | G8: =G6+G7 | H8: =H6+H7 | I8: =I6+I7 | J8: =J6+J7 | K8: =K6+K7 | ... M8: =M6+M7
A9: 基准 | B9: 业主年度预算 | C9: =0 | D9: ='02_Inputs'!$D$7*(1+'02_Inputs'!$D$16)^(1-1) | E9: ='02_Inputs'!$D$7*(1+'02_Inputs'!$D$16)^(2-1) | F9: ='02_Inputs'!$D$7*(1+'02_Inputs'!$D$16)^(3-1) | G9: ='02_Inputs'!$D$7*(1+'02_Inputs'!$D$16)^(4-1) | H9: ='02_Inputs'!$D$7*(1+'02_Inputs'!$D$16)^(5-1) | I9: ='02_Inputs'!$D$7*(1+'02_Inputs'!$D$16)^(6-1) | J9: ='02_Inputs'!$D$7*(1+'02_Inputs'!$D$16)^(7-1) | K9: ='02_Inputs'!$D$7*(1+'02_Inputs'!$D$16)^(8-1) | L9: ='02_Inputs'!$D$7*(1+'02_Inputs'!$D$16)^(9-1) | M9: ='02_Inputs'!$D$7*(1+'02_Inputs'!$D$16)^(10-1)
A11: B. 能源托管/EMC｜服务商现金流
A12: 能源托管/EMC｜服务商 | B12: 初始CAPEX支出（正数，扣减） | C12: ='04_Mode_Params'!$C$5 | D12: =0 | E12: =0 | F12: =0 | G12: =0 | H12: =0 | I12: =0 | J12: =0 | K12: =0 | ... M12: =0
A13: 能源托管/EMC｜服务商 | B13: 固定服务费收入 | C13: =0 | D13: ='04_Mode_Params'!$C$6*(1+'02_Inputs'!$D$16)^(1-1) | E13: ='04_Mode_Params'!$C$6*(1+'02_Inputs'!$D$16)^(2-1) | F13: ='04_Mode_Params'!$C$6*(1+'02_Inputs'!$D$16)^(3-1) | G13: ='04_Mode_Params'!$C$6*(1+'02_Inputs'!$D$16)^(4-1) | H13: ='04_Mode_Params'!$C$6*(1+'02_Inputs'!$D$16)^(5-1) | I13: ='04_Mode_Params'!$C$6*(1+'02_Inputs'!$D$16)^(6-1) | J13: ='04_Mode_Params'!$C$6*(1+'02_Inputs'!$D$16)^(7-1) | K13: ='04_Mode_Params'!$C$6*(1+'02_Inputs'!$D$16)^(8-1) | L13: ='04_Mode_Params'!$C$6*(1+'02_Inputs'!$D$16)^(9-1) | M13: ='04_Mode_Params'!$C$6*(1+'02_Inputs'!$D$16)^(10-1)
A14: 能源托管/EMC｜服务商 | B14: 其他/第三方收入 | C14: =0 | D14: ='04_Mode_Params'!$C$7*(1+'02_Inputs'!$D$16)^(1-1) | E14: ='04_Mode_Params'!$C$7*(1+'02_Inputs'!$D$16)^(2-1) | F14: ='04_Mode_Params'!$C$7*(1+'02_Inputs'!$D$16)^(3-1) | G14: ='04_Mode_Params'!$C$7*(1+'02_Inputs'!$D$16)^(4-1) | H14: ='04_Mode_Params'!$C$7*(1+'02_Inputs'!$D$16)^(5-1) | I14: ='04_Mode_Params'!$C$7*(1+'02_Inputs'!$D$16)^(6-1) | J14: ='04_Mode_Params'!$C$7*(1+'02_Inputs'!$D$16)^(7-1) | K14: ='04_Mode_Params'!$C$7*(1+'02_Inputs'!$D$16)^(8-1) | L14: ='04_Mode_Params'!$C$7*(1+'02_Inputs'!$D$16)^(9-1) | M14: ='04_Mode_Params'!$C$7*(1+'02_Inputs'!$D$16)^(10-1)
A15: 能源托管/EMC｜服务商 | B15: 资产转让收入 | C15: =0 | D15: =IF(AND(1='02_Inputs'!$D$26,1>0),'02_Inputs'!$D$27,0) | E15: =IF(AND(2='02_Inputs'!$D$26,2>0),'02_Inputs'!$D$27,0) | F15: =IF(AND(3='02_Inputs'!$D$26,3>0),'02_Inputs'!$D$27,0) | G15: =IF(AND(4='02_Inputs'!$D$26,4>0),'02_Inputs'!$D$27,0) | H15: =IF(AND(5='02_Inputs'!$D$26,5>0),'02_Inputs'!$D$27,0) | I15: =IF(AND(6='02_Inputs'!$D$26,6>0),'02_Inputs'!$D$27,0) | J15: =IF(AND(7='02_Inputs'!$D$26,7>0),'02_Inputs'!$D$27,0) | K15: =IF(AND(8='02_Inputs'!$D$26,8>0),'02_Inputs'!$D$27,0) | L15: =IF(AND(9='02_Inputs'!$D$26,9>0),'02_Inputs'!$D$27,0) | M15: =IF(AND(10='02_Inputs'!$D$26,10>0),'02_Inputs'!$D$27,0)
A16: 能源托管/EMC｜服务商 | B16: 节电后电费总额 | C16: =0 | D16: =D6*(1-'04_Mode_Params'!$C$8) | E16: =E6*(1-'04_Mode_Params'!$C$8) | F16: =F6*(1-'04_Mode_Params'!$C$8) | G16: =G6*(1-'04_Mode_Params'!$C$8) | H16: =H6*(1-'04_Mode_Params'!$C$8) | I16: =I6*(1-'04_Mode_Params'!$C$8) | J16: =J6*(1-'04_Mode_Params'!$C$8) | K16: =K6*(1-'04_Mode_Params'!$C$8) | ... M16: =M6*(1-'04_Mode_Params'!$C$8)
A17: 能源托管/EMC｜服务商 | B17: 服务商承担电费成本（正数，扣减） | C17: =0 | D17: =D16*'04_Mode_Params'!$C$10 | E17: =E16*'04_Mode_Params'!$C$10 | F17: =F16*'04_Mode_Params'!$C$10 | G17: =G16*'04_Mode_Params'!$C$10 | H17: =H16*'04_Mode_Params'!$C$10 | I17: =I16*'04_Mode_Params'!$C$10 | J17: =J16*'04_Mode_Params'!$C$10 | K17: =K16*'04_Mode_Params'!$C$10 | ... M17: =M16*'04_Mode_Params'!$C$10
A18: 能源托管/EMC｜服务商 | B18: 运维成本（正数，扣减） | C18: =0 | D18: ='04_Mode_Params'!$C$13*(1+'02_Inputs'!$D$15)^(1-1) | E18: ='04_Mode_Params'!$C$13*(1+'02_Inputs'!$D$15)^(2-1) | F18: ='04_Mode_Params'!$C$13*(1+'02_Inputs'!$D$15)^(3-1) | G18: ='04_Mode_Params'!$C$13*(1+'02_Inputs'!$D$15)^(4-1) | H18: ='04_Mode_Params'!$C$13*(1+'02_Inputs'!$D$15)^(5-1) | I18: ='04_Mode_Params'!$C$13*(1+'02_Inputs'!$D$15)^(6-1) | J18: ='04_Mode_Params'!$C$13*(1+'02_Inputs'!$D$15)^(7-1) | K18: ='04_Mode_Params'!$C$13*(1+'02_Inputs'!$D$15)^(8-1) | L18: ='04_Mode_Params'!$C$13*(1+'02_Inputs'!$D$15)^(9-1) | M18: ='04_Mode_Params'!$C$13*(1+'02_Inputs'!$D$15)^(10-1)
A19: 能源托管/EMC｜服务商 | B19: 平台/管理成本（正数，扣减） | C19: =0 | D19: ='04_Mode_Params'!$C$14*(1+'02_Inputs'!$D$15)^(1-1) | E19: ='04_Mode_Params'!$C$14*(1+'02_Inputs'!$D$15)^(2-1) | F19: ='04_Mode_Params'!$C$14*(1+'02_Inputs'!$D$15)^(3-1) | G19: ='04_Mode_Params'!$C$14*(1+'02_Inputs'!$D$15)^(4-1) | H19: ='04_Mode_Params'!$C$14*(1+'02_Inputs'!$D$15)^(5-1) | I19: ='04_Mode_Params'!$C$14*(1+'02_Inputs'!$D$15)^(6-1) | J19: ='04_Mode_Params'!$C$14*(1+'02_Inputs'!$D$15)^(7-1) | K19: ='04_Mode_Params'!$C$14*(1+'02_Inputs'!$D$15)^(8-1) | L19: ='04_Mode_Params'!$C$14*(1+'02_Inputs'!$D$15)^(9-1) | M19: ='04_Mode_Params'!$C$14*(1+'02_Inputs'!$D$15)^(10-1)
A20: 能源托管/EMC｜服务商 | B20: 备件/小改造储备（正数，扣减） | C20: =0 | D20: ='04_Mode_Params'!$C$15*(1+'02_Inputs'!$D$15)^(1-1) | E20: ='04_Mode_Params'!$C$15*(1+'02_Inputs'!$D$15)^(2-1) | F20: ='04_Mode_Params'!$C$15*(1+'02_Inputs'!$D$15)^(3-1) | G20: ='04_Mode_Params'!$C$15*(1+'02_Inputs'!$D$15)^(4-1) | H20: ='04_Mode_Params'!$C$15*(1+'02_Inputs'!$D$15)^(5-1) | I20: ='04_Mode_Params'!$C$15*(1+'02_Inputs'!$D$15)^(6-1) | J20: ='04_Mode_Params'!$C$15*(1+'02_Inputs'!$D$15)^(7-1) | K20: ='04_Mode_Params'!$C$15*(1+'02_Inputs'!$D$15)^(8-1) | L20: ='04_Mode_Params'!$C$15*(1+'02_Inputs'!$D$15)^(9-1) | M20: ='04_Mode_Params'!$C$15*(1+'02_Inputs'!$D$15)^(10-1)
A21: 能源托管/EMC｜服务商 | B21: 年度总收入 | C21: =0 | D21: =D13+D14+D15 | E21: =E13+E14+E15 | F21: =F13+F14+F15 | G21: =G13+G14+G15 | H21: =H13+H14+H15 | I21: =I13+I14+I15 | J21: =J13+J14+J15 | K21: =K13+K14+K15 | ... M21: =M13+M14+M15
A22: 能源托管/EMC｜服务商 | B22: 年度总现金成本 | C22: =C12 | D22: =D12+D17+D18+D19+D20 | E22: =E12+E17+E18+E19+E20 | F22: =F12+F17+F18+F19+F20 | G22: =G12+G17+G18+G19+G20 | H22: =H12+H17+H18+H19+H20 | I22: =I12+I17+I18+I19+I20 | J22: =J12+J17+J18+J19+J20 | K22: =K12+K17+K18+K19+K20 | ... M22: =M12+M17+M18+M19+M20
A23: 能源托管/EMC｜服务商 | B23: 年度净现金流 | C23: =C21-C22 | D23: =D21-D22 | E23: =E21-E22 | F23: =F21-F22 | G23: =G21-G22 | H23: =H21-H22 | I23: =I21-I22 | J23: =J21-J22 | ... M23: =M21-M22
A24: 能源托管/EMC｜服务商 | B24: 累计现金流 | C24: =C23 | D24: =C24+D23 | E24: =D24+E23 | F24: =E24+F23 | G24: =F24+G23 | H24: =G24+H23 | I24: =H24+I23 | J24: =I24+J23 | K24: =J24+K23 | ... M24: =L24+M23 -> 13783630
A25: 能源托管/EMC｜服务商 | B25: NPV | C25: =NPV('02_Inputs'!$D$13,D23:M23)+C23 -> 7423046.1
A26: 能源托管/EMC｜服务商 | B26: IRR | C26: =IFERROR(IRR(C23:M23),"n/a") -> 0.4797081
A27: 能源托管/EMC｜服务商 | B27: 10年ROI | C27: =IF(C12=0,"n/a",SUM(C23:M23)/C12) -> 4.8943408
A28: 能源托管/EMC｜服务商 | B28: 静态回收期 | C28: =IF(M24<0,"未回收",IF(C24>=0,C$4,IF(D24>=0,D$4,IF(E24>=0,E$4,IF(F24>=0,F$4,IF(G24>=0,G$4,IF(H24>=0,H$4,IF(I24>=0,I$4,IF(J24>=0,J$4,IF(K24>=0,K$4,IF(L24>=0,L$4,M$4)))))))))))
A30: C. 能源托管/EMC｜业主侧
A31: 能源托管/EMC｜业主 | B31: 业主支付电费 | C31: =0 | D31: =D16*(1-'04_Mode_Params'!$C$10) -> 1028003 | E31: =E16*(1-'04_Mode_Params'!$C$10) -> 1028003 | F31: =F16*(1-'04_Mode_Params'!$C$10) -> 1028003 | G31: =G16*(1-'04_Mode_Params'!$C$10) -> 1028003 | H31: =H16*(1-'04_Mode_Params'!$C$10) -> 1028003 | I31: =I16*(1-'04_Mode_Params'!$C$10) -> 1028003 | J31: =J16*(1-'04_Mode_Params'!$C$10) -> 1028003 | K31: =K16*(1-'04_Mode_Params'!$C$10) -> 1028003 | ... M31: =M16*(1-'04_Mode_Params'!$C$10) -> 1028003
A32: 能源托管/EMC｜业主 | B32: 固定服务费支出 | C32: =0 | D32: =D13 -> 2342300 | E32: =E13 -> 2342300 | F32: =F13 -> 2342300 | G32: =G13 -> 2342300 | H32: =H13 -> 2342300 | I32: =I13 -> 2342300 | J32: =J13 -> 2342300 | K32: =K13 -> 2342300 | ... M32: =M13 -> 2342300
A33: 能源托管/EMC｜业主 | B33: 业主保留管理成本 | C33: =0 | D33: ='02_Inputs'!$D$17*(1+'02_Inputs'!$D$15)^(1-1) | E33: ='02_Inputs'!$D$17*(1+'02_Inputs'!$D$15)^(2-1) | F33: ='02_Inputs'!$D$17*(1+'02_Inputs'!$D$15)^(3-1) | G33: ='02_Inputs'!$D$17*(1+'02_Inputs'!$D$15)^(4-1) | H33: ='02_Inputs'!$D$17*(1+'02_Inputs'!$D$15)^(5-1) | I33: ='02_Inputs'!$D$17*(1+'02_Inputs'!$D$15)^(6-1) | J33: ='02_Inputs'!$D$17*(1+'02_Inputs'!$D$15)^(7-1) | K33: ='02_Inputs'!$D$17*(1+'02_Inputs'!$D$15)^(8-1) | L33: ='02_Inputs'!$D$17*(1+'02_Inputs'!$D$15)^(9-1) | M33: ='02_Inputs'!$D$17*(1+'02_Inputs'!$D$15)^(10-1)
A34: 能源托管/EMC｜业主 | B34: 业主年度总支出 | C34: =0 | D34: =D31+D32+D33 -> 3370303 | E34: =E31+E32+E33 -> 3370303 | F34: =F31+F32+F33 -> 3370303 | G34: =G31+G32+G33 -> 3370303 | H34: =H31+H32+H33 -> 3370303 | I34: =I31+I32+I33 -> 3370303 | J34: =J31+J32+J33 -> 3370303 | K34: =K31+K32+K33 -> 3370303 | ... M34: =M31+M32+M33 -> 3370303
A35: 能源托管/EMC｜业主 | B35: 业主年度净节省 | C35: =0 | D35: =D8-D34 -> -639752 | E35: =E8-E34 -> -639752 | F35: =F8-F34 -> -639752 | G35: =G8-G34 -> -639752 | H35: =H8-H34 -> -639752 | I35: =I8-I34 -> -639752 | J35: =J8-J34 -> -639752 | K35: =K8-K34 -> -639752 | ... M35: =M8-M34 -> -639752
A36: 能源托管/EMC｜业主 | B36: 业主节省率 | C36: =0 | D36: =IF(D8=0,0,D35/D8) | E36: =IF(E8=0,0,E35/E8) | F36: =IF(F8=0,0,F35/F8) | G36: =IF(G8=0,0,G35/G8) | H36: =IF(H8=0,0,H35/H8) | I36: =IF(I8=0,0,I35/I8) | J36: =IF(J8=0,0,J35/J8) | K36: =IF(K8=0,0,K35/K8) | ... M36: =IF(M8=0,0,M35/M8)
A38: D. LaaS/AI订阅｜服务商现金流
A39: LaaS/AI订阅｜服务商 | B39: 初始CAPEX支出（正数，扣减） | C39: ='04_Mode_Params'!$D$5 | D39: =0 | E39: =0 | F39: =0 | G39: =0 | H39: =0 | I39: =0 | J39: =0 | K39: =0 | ... M39: =0
A40: LaaS/AI订阅｜服务商 | B40: 订阅收入 | C40: =0 | D40: =MAX(0,('04_Mode_Params'!$D$6*(1+'02_Inputs'!$D$16)^(1-1))-('02_Inputs'!$D$45/'02_Inputs'!$D$5)) -> 2200000 | E40: =MAX(0,('04_Mode_Params'!$D$6*(1+'02_Inputs'!$D$16)^(2-1))-('02_Inputs'!$D$45/'02_Inputs'!$D$5)) -> 2200000 | F40: =MAX(0,('04_Mode_Params'!$D$6*(1+'02_Inputs'!$D$16)^(3-1))-('02_Inputs'!$D$45/'02_Inputs'!$D$5)) -> 2200000 | G40: =MAX(0,('04_Mode_Params'!$D$6*(1+'02_Inputs'!$D$16)^(4-1))-('02_Inputs'!$D$45/'02_Inputs'!$D$5)) -> 2200000 | H40: =MAX(0,('04_Mode_Params'!$D$6*(1+'02_Inputs'!$D$16)^(5-1))-('02_Inputs'!$D$45/'02_Inputs'!$D$5)) -> 2200000 | I40: =MAX(0,('04_Mode_Params'!$D$6*(1+'02_Inputs'!$D$16)^(6-1))-('02_Inputs'!$D$45/'02_Inputs'!$D$5)) -> 2200000 | J40: =MAX(0,MAX((('04_Mode_Params'!$D$6*(1+'02_Inputs'!$D$16)^(7-1))*0.2),('04_Mode_Params'!$D$6*(1+'02_Inputs'!$D$16)^(7-1))-'02_Inputs'!$D$46)-('02_Inputs'!$D$45/'02_Inputs'!$D$5)) -> 2200000 | K40: =MAX(0,MAX((('04_Mode_Params'!$D$6*(1+'02_Inputs'!$D$16)^(8-1))*0.2),('04_Mode_Params'!$D$6*(1+'02_Inputs'!$D$16)^(8-1))-'02_Inputs'!$D$46)-('02_Inputs'!$D$45/'02_Inputs'!$D$5)) -> 2200000 | L40: =MAX(0,MAX((('04_Mode_Params'!$D$6*(1+'02_Inputs'!$D$16)^(9-1))*0.2),('04_Mode_Params'!$D$6*(1+'02_Inputs'!$D$16)^(9-1))-'02_Inputs'!$D$46)-('02_Inputs'!$D$45/'02_Inputs'!$D$5)) -> 2200000 | M40: =MAX(0,MAX((('04_Mode_Params'!$D$6*(1+'02_Inputs'!$D$16)^(10-1))*0.2),('04_Mode_Params'!$D$6*(1+'02_Inputs'!$D$16)^(10-1))-'02_Inputs'!$D$46)-('02_Inputs'!$D$45/'02_Inputs'!$D$5)) -> 2200000
A41: LaaS/AI订阅｜服务商 | B41: 其他/第三方收入 | C41: ='02_Inputs'!$D$45 | D41: ='04_Mode_Params'!$D$7*(1+'02_Inputs'!$D$16)^(1-1) | E41: ='04_Mode_Params'!$D$7*(1+'02_Inputs'!$D$16)^(2-1) | F41: ='04_Mode_Params'!$D$7*(1+'02_Inputs'!$D$16)^(3-1) | G41: ='04_Mode_Params'!$D$7*(1+'02_Inputs'!$D$16)^(4-1) | H41: ='04_Mode_Params'!$D$7*(1+'02_Inputs'!$D$16)^(5-1) | I41: ='04_Mode_Params'!$D$7*(1+'02_Inputs'!$D$16)^(6-1) | J41: ='04_Mode_Params'!$D$7*(1+'02_Inputs'!$D$16)^(7-1) | K41: ='04_Mode_Params'!$D$7*(1+'02_Inputs'!$D$16)^(8-1) | L41: ='04_Mode_Params'!$D$7*(1+'02_Inputs'!$D$16)^(9-1) | M41: ='04_Mode_Params'!$D$7*(1+'02_Inputs'!$D$16)^(10-1)
A42: LaaS/AI订阅｜服务商 | B42: 资产转让收入 | C42: =0 | D42: =IF(AND(1='02_Inputs'!$D$36,1>0),'02_Inputs'!$D$37,0) | E42: =IF(AND(2='02_Inputs'!$D$36,2>0),'02_Inputs'!$D$37,0) | F42: =IF(AND(3='02_Inputs'!$D$36,3>0),'02_Inputs'!$D$37,0) | G42: =IF(AND(4='02_Inputs'!$D$36,4>0),'02_Inputs'!$D$37,0) | H42: =IF(AND(5='02_Inputs'!$D$36,5>0),'02_Inputs'!$D$37,0) | I42: =IF(AND(6='02_Inputs'!$D$36,6>0),'02_Inputs'!$D$37,0) | J42: =IF(AND(7='02_Inputs'!$D$36,7>0),'02_Inputs'!$D$37,0) | K42: =IF(AND(8='02_Inputs'!$D$36,8>0),'02_Inputs'!$D$37,0) | L42: =IF(AND(9='02_Inputs'!$D$36,9>0),'02_Inputs'!$D$37,0) | M42: =IF(AND(10='02_Inputs'!$D$36,10>0),'02_Inputs'!$D$37,0)
A43: LaaS/AI订阅｜服务商 | B43: 节电后电费总额 | C43: =0 | D43: =D6*(1-'04_Mode_Params'!$D$8) | E43: =E6*(1-'04_Mode_Params'!$D$8) | F43: =F6*(1-'04_Mode_Params'!$D$8) | G43: =G6*(1-'04_Mode_Params'!$D$8) | H43: =H6*(1-'04_Mode_Params'!$D$8) | I43: =I6*(1-'04_Mode_Params'!$D$8) | J43: =J6*(1-'04_Mode_Params'!$D$8) | K43: =K6*(1-'04_Mode_Params'!$D$8) | ... M43: =M6*(1-'04_Mode_Params'!$D$8)
A44: LaaS/AI订阅｜服务商 | B44: 服务商承担电费成本（正数，扣减） | C44: =0 | D44: =D43*'04_Mode_Params'!$D$10 | E44: =E43*'04_Mode_Params'!$D$10 | F44: =F43*'04_Mode_Params'!$D$10 | G44: =G43*'04_Mode_Params'!$D$10 | H44: =H43*'04_Mode_Params'!$D$10 | I44: =I43*'04_Mode_Params'!$D$10 | J44: =J43*'04_Mode_Params'!$D$10 | K44: =K43*'04_Mode_Params'!$D$10 | ... M44: =M43*'04_Mode_Params'!$D$10
...

Sheet 06_Sensitivity
A1: 敏感性分析｜年费、节电率与服务商回报要求
A2: 用于判断“100万元/年”是否足够，以及Laas节电率提升能否覆盖更高CAPEX和平台/升级成本。
A4: 模式 | B4: 10年现金回本所需年费 | C4: NPV=0所需年费 | D4: 当前年费 | E4: 当前年费缺口/富余 | F4: 解释
A5: 能源托管/EMC | B5: =('04_Mode_Params'!C5+'02_Inputs'!$D$5*('04_Mode_Params'!C17-'04_Mode_Params'!C7))/'02_Inputs'!$D$5 | C5: ='04_Mode_Params'!C5/(IF('02_Inputs'!$D$13=0,'02_Inputs'!$D$5,(1-(1+'02_Inputs'!$D$13)^-'02_Inputs'!$D$5)/'02_Inputs'!$D$13))+'04_Mode_Params'!C17-'04_Mode_Params'!C7 | D5: ='04_Mode_Params'!C6 | E5: =D5-C5 | F5: 若为负，说明当前年费低于达到折现率要求的年费。
A6: LaaS/AI订阅 | B6: =('04_Mode_Params'!D5+'02_Inputs'!$D$5*('04_Mode_Params'!D17-'04_Mode_Params'!D7))/'02_Inputs'!$D$5 | C6: ='04_Mode_Params'!D5/(IF('02_Inputs'!$D$13=0,'02_Inputs'!$D$5,(1-(1+'02_Inputs'!$D$13)^-'02_Inputs'!$D$5)/'02_Inputs'!$D$13))+'04_Mode_Params'!D17-'04_Mode_Params'!D7 | D6: ='04_Mode_Params'!D6 | E6: =D6-C6 | F6: 若Laas CAPEX和平台升级成本更高，所需年费通常高于普通托管。
A9: 年费敏感性 | B9: 80万 | C9: 90万 | D9: 100万 | E9: 110万 | F9: 120万 | G9: 140万 | H9: 160万
A10: 能源托管/EMC 10年ROI | B10: =((800000+'04_Mode_Params'!$C$7-'04_Mode_Params'!$C$17)*'02_Inputs'!$D$5-'04_Mode_Params'!$C$5)/'04_Mode_Params'!$C$5 | C10: =((900000+'04_Mode_Params'!$C$7-'04_Mode_Params'!$C$17)*'02_Inputs'!$D$5-'04_Mode_Params'!$C$5)/'04_Mode_Params'!$C$5 | D10: =((1000000+'04_Mode_Params'!$C$7-'04_Mode_Params'!$C$17)*'02_Inputs'!$D$5-'04_Mode_Params'!$C$5)/'04_Mode_Params'!$C$5 | E10: =((1100000+'04_Mode_Params'!$C$7-'04_Mode_Params'!$C$17)*'02_Inputs'!$D$5-'04_Mode_Params'!$C$5)/'04_Mode_Params'!$C$5 | F10: =((1200000+'04_Mode_Params'!$C$7-'04_Mode_Params'!$C$17)*'02_Inputs'!$D$5-'04_Mode_Params'!$C$5)/'04_Mode_Params'!$C$5 | G10: =((1400000+'04_Mode_Params'!$C$7-'04_Mode_Params'!$C$17)*'02_Inputs'!$D$5-'04_Mode_Params'!$C$5)/'04_Mode_Params'!$C$5 | H10: =((1600000+'04_Mode_Params'!$C$7-'04_Mode_Params'!$C$17)*'02_Inputs'!$D$5-'04_Mode_Params'!$C$5)/'04_Mode_Params'!$C$5
A11: 能源托管/EMC 年度净经营现金流 | B11: =800000+'04_Mode_Params'!$C$7-'04_Mode_Params'!$C$17 | C11: =900000+'04_Mode_Params'!$C$7-'04_Mode_Params'!$C$17 | D11: =1000000+'04_Mode_Params'!$C$7-'04_Mode_Params'!$C$17 | E11: =1100000+'04_Mode_Params'!$C$7-'04_Mode_Params'!$C$17 | F11: =1200000+'04_Mode_Params'!$C$7-'04_Mode_Params'!$C$17 | G11: =1400000+'04_Mode_Params'!$C$7-'04_Mode_Params'!$C$17 | H11: =1600000+'04_Mode_Params'!$C$7-'04_Mode_Params'!$C$17
A12: LaaS/AI订阅 10年ROI | B12: =((800000+'04_Mode_Params'!$D$7-'04_Mode_Params'!$D$17)*'02_Inputs'!$D$5-'04_Mode_Params'!$D$5)/'04_Mode_Params'!$D$5 | C12: =((900000+'04_Mode_Params'!$D$7-'04_Mode_Params'!$D$17)*'02_Inputs'!$D$5-'04_Mode_Params'!$D$5)/'04_Mode_Params'!$D$5 | D12: =((1000000+'04_Mode_Params'!$D$7-'04_Mode_Params'!$D$17)*'02_Inputs'!$D$5-'04_Mode_Params'!$D$5)/'04_Mode_Params'!$D$5 | E12: =((1100000+'04_Mode_Params'!$D$7-'04_Mode_Params'!$D$17)*'02_Inputs'!$D$5-'04_Mode_Params'!$D$5)/'04_Mode_Params'!$D$5 | F12: =((1200000+'04_Mode_Params'!$D$7-'04_Mode_Params'!$D$17)*'02_Inputs'!$D$5-'04_Mode_Params'!$D$5)/'04_Mode_Params'!$D$5 | G12: =((1400000+'04_Mode_Params'!$D$7-'04_Mode_Params'!$D$17)*'02_Inputs'!$D$5-'04_Mode_Params'!$D$5)/'04_Mode_Params'!$D$5 | H12: =((1600000+'04_Mode_Params'!$D$7-'04_Mode_Params'!$D$17)*'02_Inputs'!$D$5-'04_Mode_Params'!$D$5)/'04_Mode_Params'!$D$5
A13: LaaS/AI订阅 年度净经营现金流 | B13: =800000+'04_Mode_Params'!$D$7-'04_Mode_Params'!$D$17 | C13: =900000+'04_Mode_Params'!$D$7-'04_Mode_Params'!$D$17 | D13: =1000000+'04_Mode_Params'!$D$7-'04_Mode_Params'!$D$17 | E13: =1100000+'04_Mode_Params'!$D$7-'04_Mode_Params'!$D$17 | F13: =1200000+'04_Mode_Params'!$D$7-'04_Mode_Params'!$D$17 | G13: =1400000+'04_Mode_Params'!$D$7-'04_Mode_Params'!$D$17 | H13: =1600000+'04_Mode_Params'!$D$7-'04_Mode_Params'!$D$17
A16: 节电率敏感性 | B16: 40% | C16: 45% | D16: 50% | E16: 55% | F16: 60% | G16: 65% | H16: 70%
A17: 能源托管/EMC 业主年净节省 | B17: ='03_Baseline'!$D$15-('03_Baseline'!$D$12*(1-0.4)*(1-'04_Mode_Params'!$C$10)+'04_Mode_Params'!$C$6+'02_Inputs'!$D$17) | C17: ='03_Baseline'!$D$15-('03_Baseline'!$D$12*(1-0.45)*(1-'04_Mode_Params'!$C$10)+'04_Mode_Params'!$C$6+'02_Inputs'!$D$17) | D17: ='03_Baseline'!$D$15-('03_Baseline'!$D$12*(1-0.5)*(1-'04_Mode_Params'!$C$10)+'04_Mode_Params'!$C$6+'02_Inputs'!$D$17) | E17: ='03_Baseline'!$D$15-('03_Baseline'!$D$12*(1-0.55)*(1-'04_Mode_Params'!$C$10)+'04_Mode_Params'!$C$6+'02_Inputs'!$D$17) | F17: ='03_Baseline'!$D$15-('03_Baseline'!$D$12*(1-0.6)*(1-'04_Mode_Params'!$C$10)+'04_Mode_Params'!$C$6+'02_Inputs'!$D$17) | G17: ='03_Baseline'!$D$15-('03_Baseline'!$D$12*(1-0.65)*(1-'04_Mode_Params'!$C$10)+'04_Mode_Params'!$C$6+'02_Inputs'!$D$17) | H17: ='03_Baseline'!$D$15-('03_Baseline'!$D$12*(1-0.7)*(1-'04_Mode_Params'!$C$10)+'04_Mode_Params'!$C$6+'02_Inputs'!$D$17)
A18: 能源托管/EMC 业主节省率 | B18: =B17/'03_Baseline'!$D$15 | C18: =C17/'03_Baseline'!$D$15 | D18: =D17/'03_Baseline'!$D$15 | E18: =E17/'03_Baseline'!$D$15 | F18: =F17/'03_Baseline'!$D$15 | G18: =G17/'03_Baseline'!$D$15 | H18: =H17/'03_Baseline'!$D$15
A19: LaaS/AI订阅 业主年净节省 | B19: ='03_Baseline'!$D$15-('03_Baseline'!$D$12*(1-0.4)*(1-'04_Mode_Params'!$D$10)+'04_Mode_Params'!$D$6+'02_Inputs'!$D$17) -> -741781.4 | C19: ='03_Baseline'!$D$15-('03_Baseline'!$D$12*(1-0.45)*(1-'04_Mode_Params'!$D$10)+'04_Mode_Params'!$D$6+'02_Inputs'!$D$17) -> -635753.7 | D19: ='03_Baseline'!$D$15-('03_Baseline'!$D$12*(1-0.5)*(1-'04_Mode_Params'!$D$10)+'04_Mode_Params'!$D$6+'02_Inputs'!$D$17) -> -497452 | E19: ='03_Baseline'!$D$15-('03_Baseline'!$D$12*(1-0.55)*(1-'04_Mode_Params'!$D$10)+'04_Mode_Params'!$D$6+'02_Inputs'!$D$17) -> -423698.3 | F19: ='03_Baseline'!$D$15-('03_Baseline'!$D$12*(1-0.6)*(1-'04_Mode_Params'!$D$10)+'04_Mode_Params'!$D$6+'02_Inputs'!$D$17) -> -317670.6 | G19: ='03_Baseline'!$D$15-('03_Baseline'!$D$12*(1-0.65)*(1-'04_Mode_Params'!$D$10)+'04_Mode_Params'!$D$6+'02_Inputs'!$D$17) -> -211642.9 | H19: ='03_Baseline'!$D$15-('03_Baseline'!$D$12*(1-0.7)*(1-'04_Mode_Params'!$D$10)+'04_Mode_Params'!$D$6+'02_Inputs'!$D$17) -> -105615.2
A20: LaaS/AI订阅 业主节省率 | B20: =B19/'03_Baseline'!$D$15 | C20: =C19/'03_Baseline'!$D$15 | D20: =D19/'03_Baseline'!$D$15 | E20: =E19/'03_Baseline'!$D$15 | F20: =F19/'03_Baseline'!$D$15 | G20: =G19/'03_Baseline'!$D$15 | H20: =H19/'03_Baseline'!$D$15

Sheet 07_Model_Checks
A1: 模型逻辑复核｜关键公式与常识校验
A2: 本页用于排查常见错误：成本是否被当作收入、业主支出是否双算、服务商其他收入是否误加给业主、电费承担方是否拆分正确。
A4: 校验项 | B4: 检查公式 | C4: 能源托管结果 | D4: LaaS结果 | E4: 状态 | F4: 错误含义 | G4: 修正方法
A5: Y1服务商净现金流=收入−成本 | B5: Y1净现金流应等于年度总收入−年度总现金成本 | C5: =ABS('05_Annual_Model'!D23-('05_Annual_Model'!D21-'05_Annual_Model'!D22))<1 | D5: =ABS('05_Annual_Model'!D50-('05_Annual_Model'!D48-'05_Annual_Model'!D49))<1 | E5: =IF(AND(C5=TRUE,D5=TRUE),"OK","ERROR") | F5: 若不等，说明成本符号或公式引用错误 | G5: 检查Annual_Model服务商现金流区
A6: Y0服务商净现金流=-初始CAPEX | B6: Y0净现金流应等于0−Y0总现金成本 | C6: =ABS('05_Annual_Model'!C23+( '05_Annual_Model'!C12))<1 | D6: =ABS('05_Annual_Model'!C50+('05_Annual_Model'!C39))<1 | E6: =IF(AND(C6=TRUE,D6=TRUE),"OK","ERROR") | F6: 若不等，说明CAPEX没有在Y0扣减 | G6: 检查Annual_Model Y0列
A7: 成本行均为正数 | B7: CAPEX/运维/平台/备件/电费成本应≥0 | C7: =MIN('05_Annual_Model'!C12:M12,'05_Annual_Model'!C17:M20)>=0 | D7: =MIN('05_Annual_Model'!C39:M39,'05_Annual_Model'!C44:M47)>=0 | E7: =IF(AND(C7=TRUE,D7=TRUE),"OK","ERROR") | F7: 若为负，说明又回到了“负成本相加”的口径 | G7: 把成本作为正数并在净现金流中扣减
A8: 业主支出不含服务商第三方收入 | B8: 业主年度总支出=业主电费+服务费+保留管理成本 | C8: =ABS('05_Annual_Model'!D34-('05_Annual_Model'!D31+'05_Annual_Model'!D32+'05_Annual_Model'!D33))<1 | D8: =ABS('05_Annual_Model'!D61-('05_Annual_Model'!D58+'05_Annual_Model'!D59+'05_Annual_Model'!D60))<1 | E8: =IF(AND(C8=TRUE,D8=TRUE),"OK","ERROR") | F8: 若不等，说明把服务商其他收入误算成业主支出 | G8: 第三方收入只进服务商收入，不进业主支出
A9: 电费承担方拆分正确 | B9: 服务商电费成本+业主支付电费=节电后电费总额 | C9: =ABS(('05_Annual_Model'!D17+'05_Annual_Model'!D31)-'05_Annual_Model'!D16)<1 | D9: =ABS(('05_Annual_Model'!D44+'05_Annual_Model'!D58)-'05_Annual_Model'!D43)<1 | E9: =IF(AND(C9=TRUE,D9=TRUE),"OK","ERROR") | F9: 若不等，说明电费被重复计入或漏计 | G9: 检查服务商是否承担电费开关
A10: 累计现金流连贯 | B10: Y2累计=Y1累计+Y2净现金流 | C10: =ABS('05_Annual_Model'!E24-('05_Annual_Model'!D24+'05_Annual_Model'!E23))<1 | D10: =ABS('05_Annual_Model'!E51-('05_Annual_Model'!D51+'05_Annual_Model'!E50))<1 | E10: =IF(AND(C10=TRUE,D10=TRUE),"OK","ERROR") | F10: 若不等，说明累计现金流断链 | G10: 检查累计现金流公式
A11: 业主净节省口径正确 | B11: 业主净节省=不改造总成本−业主总支出 | C11: =ABS('05_Annual_Model'!D35-('05_Annual_Model'!D8-'05_Annual_Model'!D34))<1 | D11: =ABS('05_Annual_Model'!D62-('05_Annual_Model'!D8-'05_Annual_Model'!D61))<1 | E11: =IF(AND(C11=TRUE,D11=TRUE),"OK","ERROR") | F11: 若不等，说明节省额口径错误 | G11: 检查业主侧公式
A12: 静态回收期不能早于累计现金流转正 | B12: 若M累计现金流<0，回收期必须显示未回收 | C12: =IF('05_Annual_Model'!M24<0,'05_Annual_Model'!C28="未回收",TRUE) | D12: =IF('05_Annual_Model'!M51<0,'05_Annual_Model'!C55="未回收",TRUE) | E12: =IF(AND(C12=TRUE,D12=TRUE),"OK","ERROR") | F12: 若错误，说明回收期引用了错误行 | G12: 检查回收期公式引用累计现金流行

Sheet 08_Calc_Logic
A1: 计算逻辑说明｜修正版
A2: 重点：将“业主视角”和“服务商视角”分开；将“收入、成本、节省”分开；不把成本写成负数再与收入相加。
A4: 模块 | B4: 公式 | C4: 解释 | D4: 对应工作表 | E4: 常见错误 | F4: 可调整项
A5: 现状年用电量 | B5: 灯具数量×单灯功率÷1000×每日亮灯小时×年运行天数 | C5: 将每盏灯功率转换为kW后乘以全年运行小时。 | D5: 03_Baseline | E5: 只用灯数但漏掉功率/时长，会导致电费无意义。 | F5: 灯具数量、功率、亮灯小时
A6: 基准年电费 | B6: 现状年用电量×电价 | C6: 不改造情形的电费基准。 | D6: 03_Baseline | E6: 把节电后的电费用作基准，会高估节省。 | F6: 电价
A7: 基准年运维费 | B7: 灯具数量×现状运维单价 | C7: 不改造情形的运维基准。 | D7: 03_Baseline | E7: 把服务商运维成本和业主现状运维费混用。 | F7: 现状运维单价
A8: 节电后电费总额 | B8: 基准电费×(1−综合节电率) | C8: 先计算物理电费，再按承担方开关分配。 | D8: 04_Mode_Params / 05_Annual_Model | E8: 没有区分“电费由谁付”，会导致业主/服务商双算或漏算。 | F8: 节电率、承担电费开关
A9: 服务商年度收入 | B9: 服务费/订阅费+其他/第三方收入+资产转让收入 | C9: 服务商收入项。默认第三方收入不计入业主支出。 | D9: 05_Annual_Model | E9: 把第三方收入也算成业主支出，导致业主侧多算。 | F9: 年费、其他收入、资产转让
A10: 服务商年度现金成本 | B10: CAPEX+服务商电费成本+运维成本+平台成本+备件储备 | C10: 所有成本均按正数列示，净现金流公式中扣减。 | D10: 05_Annual_Model | E10: 成本用负数列示又在净现金流中扣减，会双重扣减。 | F10: CAPEX、运维、平台、备件
A11: 服务商年度净现金流 | B11: 年度总收入−年度总现金成本 | C11: Y0通常为−CAPEX，Y1-Y10为经营现金流。 | D11: 05_Annual_Model | E11: 写成服务收入+运维成本+平台成本。 | F11: 所有收入成本项
A12: 业主年度总支出 | B12: 业主支付电费+服务费/订阅费+业主保留管理成本 | C12: 服务费是业主支出，不是业主收益。 | D12: 05_Annual_Model | E12: 把服务商收入当成业主节省，或把服务商成本加给业主。 | F12: 年费、电费承担方、保留管理成本
A13: 业主净节省 | B13: 不改造基准总成本−业主年度总支出 | C13: 判断业主是否有采用模式的经济理由。 | D13: 04_Mode_Params / 05_Annual_Model | E13: 只看节电金额，不扣服务费，会高估业主收益。 | F13: 节电率、年费
A14: NPV | B14: NPV(折现率,Y1:Y10现金流)+Y0现金流 | C14: 判断服务商是否达到资金成本要求。 | D14: 05_Annual_Model | E14: 只看静态回收而忽略资金时间价值。 | F14: 折现率、合同期
A15: IRR | B15: IRR(Y0:Y10现金流) | C15: 判断服务商项目内部收益率。 | D15: 05_Annual_Model | E15: 现金流长期为负时，IRR没有经营决策意义。 | F15: 年费、CAPEX、成本
A16: NPV=0所需年费 | B16: CAPEX年金化+年度现金成本−其他收入 | C16: 反推服务商达到折现率要求的最低年费。 | D16: 06_Sensitivity | E16: 把这个数当作业主可接受价格；它只是服务商底线。 | F16: CAPEX、折现率、成本、其他收入

Sheet 09_Glossary
A1: 术语与口径说明
A3: 术语 | B3: 中文解释 | C3: 模型口径 | D3: 容易混淆点 | E3: 建议使用场景
A4: 能源托管/EMC | B4: 服务商或第三方通过节能改造与管理获得服务费或节能收益。 | C4: 本模型以固定服务费为主，可叠加第三方收入、资产转让收入。 | D4: 节电收益不一定归服务商，必须看电费承担方和合同分配。 | E4: 政府/业主关注节能指标、费用不增加时。
A5: LaaS/AI订阅 | B5: Lighting as a Service，强调照明能力、平台、升级、运维的一体化订阅。 | C5: 本模型以订阅费为主，CAPEX和平台升级成本通常高于普通托管。 | D5: 不是传统租赁，不只是设备使用权，还包含持续升级和服务。 | E5: 需要打包功能迭代、AI调光、数字运维时。
A6: 业主年度服务费预算 | B6: 业主每年愿意/能够支付给服务商的预算。 | C6: 在模型中是业主支出、服务商收入。 | D6: 不能把它同时当作业主投资收益。 | E6: 看项目付费能力。
A7: CAPEX | B7: 资本性支出，项目初始建设投入。 | C7: 按每盏灯CAPEX×灯具数量计算，在Y0扣减。 | D7: 不要把CAPEX摊销当现金流；现金流看真实资金流出。 | E7: 测算服务商投资压力。
A8: 年度净经营现金流 | B8: 不含初始CAPEX的年度经营净流入。 | C8: 年度收入−年度现金成本。 | D8: 如果成本行是正数，公式必须是减法。 | E8: 看每年经营是否赚钱。
A9: 年度净现金流 | B9: 某一年全部现金流入减全部现金流出。 | C9: Y0通常为−CAPEX，Y1-Y10为经营现金流。 | D9: 不要把成本当收入相加。 | E9: 看累计回收和IRR/NPV。
A10: 业主净节省 | B10: 业主采用模式后相对不改造省下的钱。 | C10: 基准总成本−改造后业主总支出。 | D10: 只看节电金额不扣服务费，会高估业主收益。 | E10: 判断政府/业主是否接受。
A11: NPV | B11: 净现值。 | C11: 未来现金流按折现率折回后加总。 | D11: NPV为正才说明达到折现率要求。 | E11: 服务商投资决策。
A12: IRR | B12: 内部收益率。 | C12: 使项目NPV为0的收益率。 | D12: 现金流未回正时解释力有限。 | E12: 服务商投资回报比较。
A13: 静态回收期 | B13: 累计现金流转正所需年份。 | C13: 累计现金流首次≥0的年份。 | D13: 不考虑资金时间价值。 | E13: 对外沟通直观，但不能替代NPV。
