Workbook

Sheet Owner_NPV_Comparison
A1: Question B：哪种模式让甲方付得更少？（甲方NPV(总支出) 最低）
A3: 折现率（甲方，年） | B3: =假设!B36 | D3: Mode | E3: =假设!B34
A4: Baseline（市电含电缆）年成本 | B4: ='假设'!$B$29 | D4: Baseline NPV(cost) | E4: =NPV($B$3,$B$11:$K$11)
A5: 说明 | B5: 本页按各模式表中的“甲方实际流出（Mode_B公式）”计算NPV(cost)。ΔNPV>0 表示相对基线省钱。
A7: 模式 | B7: Y1 | C7: Y2 | D7: Y3 | E7: Y4 | F7: … | G7: NPV(cost) and Delta vs baseline
A8: EMC | B8: ='EMC模式'!F6 | C8: ='EMC模式'!F7 | D8: ='EMC模式'!F8 | E8: ='EMC模式'!F9 | F8: … | G8: =NPV($B$3,'EMC模式'!F6:F15)&" | Delta="&($E$4-NPV($B$3,'EMC模式'!F6:F15))
A9: 能源托管 | B9: ='能源托管模式'!F6 | C9: ='能源托管模式'!F7 | D9: ='能源托管模式'!F8 | E9: ='能源托管模式'!F9 | F9: … | G9: =NPV($B$3,'能源托管模式'!F6:F15)&" | Delta="&($E$4-NPV($B$3,'能源托管模式'!F6:F15))
A10: LaaS | B10: ='LaaS模式'!F6 | C10: ='LaaS模式'!F7 | D10: ='LaaS模式'!F8 | E10: ='LaaS模式'!F9 | F10: … | G10: =NPV($B$3,'LaaS模式'!F6:F15)&" | Delta="&($E$4-NPV($B$3,'LaaS模式'!F6:F15))
A11: 租赁 | B11: ='租赁模式'!F6 | C11: ='租赁模式'!F7 | D11: ='租赁模式'!F8 | E11: ='租赁模式'!F9 | F11: … | G11: =NPV($B$3,'租赁模式'!F6:F15)&" | Delta="&($E$4-NPV($B$3,'租赁模式'!F6:F15)) | H11: ='假设'!$B$29 | I11: ='假设'!$B$29 | J11: ='假设'!$B$29 | K11: ='假设'!$B$29

Sheet 假设
A1: 路灯项目四种模式对照实验（业主年投入恒定）
A3: 口径：10年期；同一项目规模、同一节能效果、同一CAPEX与融资比例，并将“业主年总投入”固定为同一数值，仅比较不同合同结构如何分配收益。
A5: 全局假设 | B5: 数值 | D5: 模式 | E5: 业主年总投入（恒定） | F5: 业主自付电费 | G5: 业主自付运维 | H5: 支付给核心服务方的费用 | I5: 核心服务方第10年残值 | J5: 甲方第10年终值
A6: 分析期（年） | B6: 10 | D6: EMC | E6: =$B$16 | F6: =$B$11 | G6: =$B$12 | H6: =E6-F6-G6 | I6: 0 | J6: =B21
A7: 资产经济寿命（年） | B7: 12 | D7: 能源托管 | E7: =$B$16 | F7: =0 | G7: =0 | H7: =E7-F7-G7 | I7: 0 | J7: =B21
A8: 改造CAPEX | B8: 15000000 | D8: LaaS | E8: =$B$16 | F8: =$B$11 | G8: =0 | H8: =E8-F8-G8 | I8: =B21 | J8: 0
A9: 改造前年电费 | B9: 12000000 | D9: 租赁 | E9: =$B$16 | F9: =$B$11 | G9: =$B$12 | H9: =E9-F9-G9 | I9: 0 | J9: =B21
A10: 改造前年运维费 | B10: 3000000
A11: 改造后年电费 | B11: 7200000
A12: 改造后年运维费 | B12: 2400000 | D12: 如何理解本工作簿
A13: 平台/软件年成本 | B13: 400000 | D13: 业主年总投入恒定 | E13: 四种模式的“甲方实际流出”统一锁定为同一个年金额，默认值见B16，可直接改。
A14: EMC服务运营年成本 | B14: 700000 | D14: 谁的利润会变化 | E14: 在同一业主支付额下，变化最大的是核心服务方净现金；甲方差异主要来自终值/资产归属。
A15: 租赁服务管理年成本 | B15: 200000 | D15: 何时会出现不可行 | E15: 如果B16过低，会导致某些模式下“支付给核心服务方的费用”为负数，说明该模式在该支付约束下不可成立。
A16: 业主年总投入（恒定，可调） | B16: 13100000
A17: 债务比例 | B17: 0.7
A18: 贷款利率 | B18: 0.06
A19: 资金方资金成本 | B19: 0.035
A20: 设备收入占CAPEX比例 | B20: 0.8
A21: 设备毛利率 | B21: 0.225
A22: EPC收入占CAPEX比例 | B22: 0.2
A23: EPC毛利率 | B23: 0.2
A24: 第10年终值（资产残值） | B24: 2500000
A25: 债务金额 | B25: =B8*B17
A26: 股权投入 | B26: =B8-B25
A27: 年债务偿付额 | B27: =-PMT(B18,B6,B25)
A28: 累计债务偿付额 | B28: =B27*B6
A29: 甲方基线年总成本 | B29: =B9+B10
A30: 甲方基线10年总成本 | B30: =B29*B6
A32: Mode_B（Question B）：业主支付不锁定，比较“甲方NPV(总支出)”谁最低
A33: 开关 | B33: OwnerSpendMode | C33: Fixed / ModelBased | D33: 说明 | E33: 选择 ModelBased 才会回答 Question B
A34: OwnerSpendMode（Fixed / ModelBased） | B34: ModelBased | D34: Fixed=沿用B16锁定；ModelBased=按各模式计费结构算业主支出
A36: 折现率（甲方，年） | B36: 0.12 | D36: 用于 Owner_NPV_Comparison
A37: 合约期（年） | B37: =B6
A39: Mode_B 关键参数（让四模式在甲方侧自然拉开差异）
A40: EMC：甲方保留节省比例（OwnerRetainShare） | B40: 0.5 | D40: 例：50%表示节省的一半归甲方；另一半用于支付服务方
A41: EMC：固定服务费（年，可选） | B41: 0
A42: 托管：托管费（年，覆盖电费+运维） | B42: =B16 | D42: 默认等于B16；你可改为报价/指数化费用
A43: LaaS：订阅费（年） | B43: =B16
A44: LaaS：SLA罚则（年，默认0） | B44: 0
A45: 租赁：隐含利率（年，用于算租金PMT） | B45: =B18
...

Sheet 融资摊还
A1: 统一融资假设下的贷款摊还表
A3: 口径：四种模式统一采用相同的CAPEX、债务比例与利率；由于本次只固定业主支付额，因此融资侧结果保持一致。
A5: 年份 | B5: 期初余额 | C5: 年偿付额 | D5: 利息 | E5: 本金 | F5: 期末余额 | G5: 资金成本 | H5: 净息差
A6: 1 | B6: ='假设'!$B$25 | C6: ='假设'!$B$27 | D6: =B6*'假设'!$B$18 | E6: =C6-D6 | F6: =MAX(B6-E6,0) | G6: =B6*'假设'!$B$19 | H6: =D6-G6
A7: 2 | B7: =F6 | C7: ='假设'!$B$27 | D7: =B7*'假设'!$B$18 | E7: =C7-D7 | F7: =MAX(B7-E7,0) | G7: =B7*'假设'!$B$19 | H7: =D7-G7
A8: 3 | B8: =F7 | C8: ='假设'!$B$27 | D8: =B8*'假设'!$B$18 | E8: =C8-D8 | F8: =MAX(B8-E8,0) | G8: =B8*'假设'!$B$19 | H8: =D8-G8
A9: 4 | B9: =F8 | C9: ='假设'!$B$27 | D9: =B9*'假设'!$B$18 | E9: =C9-D9 | F9: =MAX(B9-E9,0) | G9: =B9*'假设'!$B$19 | H9: =D9-G9
A10: 5 | B10: =F9 | C10: ='假设'!$B$27 | D10: =B10*'假设'!$B$18 | E10: =C10-D10 | F10: =MAX(B10-E10,0) | G10: =B10*'假设'!$B$19 | H10: =D10-G10
A11: 6 | B11: =F10 | C11: ='假设'!$B$27 | D11: =B11*'假设'!$B$18 | E11: =C11-D11 | F11: =MAX(B11-E11,0) | G11: =B11*'假设'!$B$19 | H11: =D11-G11
A12: 7 | B12: =F11 | C12: ='假设'!$B$27 | D12: =B12*'假设'!$B$18 | E12: =C12-D12 | F12: =MAX(B12-E12,0) | G12: =B12*'假设'!$B$19 | H12: =D12-G12
A13: 8 | B13: =F12 | C13: ='假设'!$B$27 | D13: =B13*'假设'!$B$18 | E13: =C13-D13 | F13: =MAX(B13-E13,0) | G13: =B13*'假设'!$B$19 | H13: =D13-G13
A14: 9 | B14: =F13 | C14: ='假设'!$B$27 | D14: =B14*'假设'!$B$18 | E14: =C14-D14 | F14: =MAX(B14-E14,0) | G14: =B14*'假设'!$B$19 | H14: =D14-G14
A15: 10 | B15: =F14 | C15: ='假设'!$B$27 | D15: =B15*'假设'!$B$18 | E15: =C15-D15 | F15: =MAX(B15-E15,0) | G15: =B15*'假设'!$B$19 | H15: =D15-G15
A16: 合计 | C16: =SUM(C6:C15) | D16: =SUM(D6:D15) | E16: =SUM(E6:E15) | G16: =SUM(G6:G15) | H16: =SUM(H6:H15)

Sheet 汇总对比
A1: 四种模式最终各方收益对比（业主年投入恒定）
A3: 核心看法：在“业主年总投入固定”为同一个数字时，甲方差异主要体现在终值归属，真正被拉开的是核心服务方的收益分配。默认固定值见“假设”表B16。
A5: 参与方 | B5: EMC | C5: 能源托管 | D5: LaaS | E5: 租赁 | F5: 口径说明 | H5: 指标 | I5: EMC | J5: 能源托管 | K5: LaaS | L5: 租赁
A6: 甲方净收益 | B6: ='EMC模式'!$B$7 | C6: ='能源托管模式'!$B$7 | D6: ='LaaS模式'!$B$7 | E6: ='租赁模式'!$B$7 | F6: 10年相对基线的节约额 + 若终值归甲方则加上终值 | H6: 甲方净收益 | I6: =B6 | J6: =C6 | K6: =D6 | L6: =E6
A7: 核心服务方净现金 | B7: ='EMC模式'!$B$8 | C7: ='能源托管模式'!$B$8 | D7: ='LaaS模式'!$B$8 | E7: ='租赁模式'!$B$8 | F7: 收入 + 残值归服务方 – 直接运营成本 – 累计债务偿付 – 初始股权投入 | H7: 核心服务方净现金 | I7: =B7 | J7: =C7 | K7: =D7 | L7: =E7
A8: 设备商利润 | B8: ='EMC模式'!$B$11 | C8: ='能源托管模式'!$B$11 | D8: ='LaaS模式'!$B$11 | E8: ='租赁模式'!$B$11 | F8: 固定同一CAPEX拆分，用于隔离模式差异 | H8: 资金方净息差 | I8: =B10 | J8: =C10 | K8: =D10 | L8: =E10
A9: EPC利润 | B9: ='EMC模式'!$B$12 | C9: ='能源托管模式'!$B$12 | D9: ='LaaS模式'!$B$12 | E9: ='租赁模式'!$B$12 | F9: 固定同一CAPEX拆分，用于隔离模式差异
A10: 资金方净息差 | B10: ='EMC模式'!$B$14 | C10: ='能源托管模式'!$B$14 | D10: ='LaaS模式'!$B$14 | E10: ='租赁模式'!$B$14 | F10: 统一债务条件下的净利差收益
A13: 快速结论 | B13: 最佳模式 | C13: 指标 | D13: 数值
A14: 甲方 | B14: =INDEX(B$5:E$5,1, MATCH(MAX(B6:E6), B6:E6, 0)) | C14: 甲方净收益最高 | D14: =MAX(B6:E6)
A15: 核心服务方 | B15: =INDEX(B$5:E$5,1, MATCH(MAX(B7:E7), B7:E7, 0)) | C15: 核心服务方净现金最高 | D15: =MAX(B7:E7)
A16: 提醒 | B16: LaaS若要成立 | C16: 需确保残值归服务方，或提高订阅费
A18: 新增阅读指引 | B18: 先看“逐年利润对比”了解每年谁更赚，再看“年度差异来源”定位差额到底来自服务费、电费/运维承担还是残值归属。

Sheet EMC模式
A1: EMC：业主年投入恒定下的参与方收益拆解
A3: 说明：业主每年总投入固定为同一金额；EMC下甲方仍自付电费与运维，剩余部分支付给ESCO。第10年终值归甲方。
A5: 指标 | B5: 数值 | D5: 年份 | E5: 基线成本 | F5: 甲方实际流出 | G5: 归甲方终值 | H5: 甲方增量收益 | J5: 年份 | K5: 收入 | L5: 直接运营成本 | M5: 债务偿付 | N5: 残值归服务方 | O5: 股权现金流
A6: 业主年总投入（恒定） | B6: ='假设'!$B$16 | D6: 1 | E6: ='假设'!$B$29 | F6: =IF(假设!B34="Fixed",'假设'!$B$16,(('假设'!$B$11+'假设'!$B$12)+假设!B41+假设!B40*(('假设'!$B$9+'假设'!$B$10)-('假设'!$B$11+'假设'!$B$12)))) | G6: =0 | H6: =E6-F6+G6 | J6: 0 | K6: =0 | L6: =0 | M6: =0 | N6: =0 | O6: =-'假设'!$B$26
A7: 甲方10年净收益 | B7: ='假设'!$B$30-B6*'假设'!$B$6+='假设'!$B$24 | D7: 2 | E7: ='假设'!$B$29 | F7: =IF(假设!B34="Fixed",'假设'!$B$16,(('假设'!$B$11+'假设'!$B$12)+假设!B41+假设!B40*(('假设'!$B$9+'假设'!$B$10)-('假设'!$B$11+'假设'!$B$12)))) | G7: =0 | H7: =E7-F7+G7 | J7: 1 | K7: ='假设'!$H$6 | L7: ='假设'!$B$14 | M7: ='假设'!$B$27 | N7: =0 | O7: =K7-L7-M7+N7
A8: 核心服务方10年净现金 | B8: =SUM(O6:O16) | D8: 3 | E8: ='假设'!$B$29 | F8: =IF(假设!B34="Fixed",'假设'!$B$16,(('假设'!$B$11+'假设'!$B$12)+假设!B41+假设!B40*(('假设'!$B$9+'假设'!$B$10)-('假设'!$B$11+'假设'!$B$12)))) | G8: =0 | H8: =E8-F8+G8 | J8: 2 | K8: ='假设'!$H$6 | L8: ='假设'!$B$14 | M8: ='假设'!$B$27 | N8: =0 | O8: =K8-L8-M8+N8
A9: 核心服务方10年收入 | B9: =SUM(K6:K16)+SUM(N6:N16) | D9: 4 | E9: ='假设'!$B$29 | F9: =IF(假设!B34="Fixed",'假设'!$B$16,(('假设'!$B$11+'假设'!$B$12)+假设!B41+假设!B40*(('假设'!$B$9+'假设'!$B$10)-('假设'!$B$11+'假设'!$B$12)))) | G9: =0 | H9: =E9-F9+G9 | J9: 3 | K9: ='假设'!$H$6 | L9: ='假设'!$B$14 | M9: ='假设'!$B$27 | N9: =0 | O9: =K9-L9-M9+N9
A10: 核心服务方10年直接运营成本 | B10: =SUM(L6:L16) | D10: 5 | E10: ='假设'!$B$29 | F10: =IF(假设!B34="Fixed",'假设'!$B$16,(('假设'!$B$11+'假设'!$B$12)+假设!B41+假设!B40*(('假设'!$B$9+'假设'!$B$10)-('假设'!$B$11+'假设'!$B$12)))) | G10: =0 | H10: =E10-F10+G10 | J10: 4 | K10: ='假设'!$H$6 | L10: ='假设'!$B$14 | M10: ='假设'!$B$27 | N10: =0 | O10: =K10-L10-M10+N10
A11: 设备商利润 | B11: ='假设'!$B$8*'假设'!$B$20*'假设'!$B$21 | D11: 6 | E11: ='假设'!$B$29 | F11: =IF(假设!B34="Fixed",'假设'!$B$16,(('假设'!$B$11+'假设'!$B$12)+假设!B41+假设!B40*(('假设'!$B$9+'假设'!$B$10)-('假设'!$B$11+'假设'!$B$12)))) | G11: =0 | H11: =E11-F11+G11 | J11: 5 | K11: ='假设'!$H$6 | L11: ='假设'!$B$14 | M11: ='假设'!$B$27 | N11: =0 | O11: =K11-L11-M11+N11
A12: EPC利润 | B12: ='假设'!$B$8*'假设'!$B$22*'假设'!$B$23 | D12: 7 | E12: ='假设'!$B$29 | F12: =IF(假设!B34="Fixed",'假设'!$B$16,(('假设'!$B$11+'假设'!$B$12)+假设!B41+假设!B40*(('假设'!$B$9+'假设'!$B$10)-('假设'!$B$11+'假设'!$B$12)))) | G12: =0 | H12: =E12-F12+G12 | J12: 6 | K12: ='假设'!$H$6 | L12: ='假设'!$B$14 | M12: ='假设'!$B$27 | N12: =0 | O12: =K12-L12-M12+N12
A13: 资金方总利息 | B13: ='融资摊还'!$D$16 | D13: 8 | E13: ='假设'!$B$29 | F13: =IF(假设!B34="Fixed",'假设'!$B$16,(('假设'!$B$11+'假设'!$B$12)+假设!B41+假设!B40*(('假设'!$B$9+'假设'!$B$10)-('假设'!$B$11+'假设'!$B$12)))) | G13: =0 | H13: =E13-F13+G13 | J13: 7 | K13: ='假设'!$H$6 | L13: ='假设'!$B$14 | M13: ='假设'!$B$27 | N13: =0 | O13: =K13-L13-M13+N13
A14: 资金方净息差 | B14: ='融资摊还'!$H$16 | D14: 9 | E14: ='假设'!$B$29 | F14: =IF(假设!B34="Fixed",'假设'!$B$16,(('假设'!$B$11+'假设'!$B$12)+假设!B41+假设!B40*(('假设'!$B$9+'假设'!$B$10)-('假设'!$B$11+'假设'!$B$12)))) | G14: =0 | H14: =E14-F14+G14 | J14: 8 | K14: ='假设'!$H$6 | L14: ='假设'!$B$14 | M14: ='假设'!$B$27 | N14: =0 | O14: =K14-L14-M14+N14
D15: 10 | E15: ='假设'!$B$29 | F15: =IF(假设!B34="Fixed",'假设'!$B$16,(('假设'!$B$11+'假设'!$B$12)+假设!B41+假设!B40*(('假设'!$B$9+'假设'!$B$10)-('假设'!$B$11+'假设'!$B$12)))) | G15: ='假设'!$B$24 | H15: =E15-F15+G15 | J15: 9 | K15: ='假设'!$H$6 | L15: ='假设'!$B$14 | M15: ='假设'!$B$27 | N15: =0 | O15: =K15-L15-M15+N15
D16: 合计 | E16: =SUM(E6:E15) | F16: =SUM(F6:F15) | G16: =SUM(G6:G15) | H16: =SUM(H6:H15) | J16: 10 | K16: ='假设'!$H$6 | L16: ='假设'!$B$14 | M16: ='假设'!$B$27 | N16: =0 | O16: =K16-L16-M16+N16
J17: 合计 | K17: =SUM(K6:K16) | L17: =SUM(L6:L16) | M17: =SUM(M6:M16) | N17: =SUM(N6:N16) | O17: =SUM(O6:O16)

Sheet 能源托管模式
A1: 能源托管：业主年投入恒定下的参与方收益拆解
A3: 说明：业主每年总投入固定为同一金额；能源托管下甲方不再单独支付电费与运维，全部体现在托管费中。第10年终值归甲方。
A5: 指标 | B5: 数值 | D5: 年份 | E5: 基线成本 | F5: 甲方实际流出 | G5: 归甲方终值 | H5: 甲方增量收益 | J5: 年份 | K5: 收入 | L5: 直接运营成本 | M5: 债务偿付 | N5: 残值归服务方 | O5: 股权现金流
A6: 业主年总投入（恒定） | B6: ='假设'!$B$16 | D6: 1 | E6: ='假设'!$B$29 | F6: =IF(假设!B34="Fixed",'假设'!$B$16,(假设!B42)) | G6: =0 | H6: =E6-F6+G6 | J6: 0 | K6: =0 | L6: =0 | M6: =0 | N6: =0 | O6: =-'假设'!$B$26
A7: 甲方10年净收益 | B7: ='假设'!$B$30-B6*'假设'!$B$6+='假设'!$B$24 | D7: 2 | E7: ='假设'!$B$29 | F7: =IF(假设!B34="Fixed",'假设'!$B$16,(假设!B42)) | G7: =0 | H7: =E7-F7+G7 | J7: 1 | K7: ='假设'!$H$7 | L7: ='假设'!$B$11+'假设'!$B$12+'假设'!$B$13 | M7: ='假设'!$B$27 | N7: =0 | O7: =K7-L7-M7+N7
A8: 核心服务方10年净现金 | B8: =SUM(O6:O16) | D8: 3 | E8: ='假设'!$B$29 | F8: =IF(假设!B34="Fixed",'假设'!$B$16,(假设!B42)) | G8: =0 | H8: =E8-F8+G8 | J8: 2 | K8: ='假设'!$H$7 | L8: ='假设'!$B$11+'假设'!$B$12+'假设'!$B$13 | M8: ='假设'!$B$27 | N8: =0 | O8: =K8-L8-M8+N8
A9: 核心服务方10年收入 | B9: =SUM(K6:K16)+SUM(N6:N16) | D9: 4 | E9: ='假设'!$B$29 | F9: =IF(假设!B34="Fixed",'假设'!$B$16,(假设!B42)) | G9: =0 | H9: =E9-F9+G9 | J9: 3 | K9: ='假设'!$H$7 | L9: ='假设'!$B$11+'假设'!$B$12+'假设'!$B$13 | M9: ='假设'!$B$27 | N9: =0 | O9: =K9-L9-M9+N9
A10: 核心服务方10年直接运营成本 | B10: =SUM(L6:L16) | D10: 5 | E10: ='假设'!$B$29 | F10: =IF(假设!B34="Fixed",'假设'!$B$16,(假设!B42)) | G10: =0 | H10: =E10-F10+G10 | J10: 4 | K10: ='假设'!$H$7 | L10: ='假设'!$B$11+'假设'!$B$12+'假设'!$B$13 | M10: ='假设'!$B$27 | N10: =0 | O10: =K10-L10-M10+N10
A11: 设备商利润 | B11: ='假设'!$B$8*'假设'!$B$20*'假设'!$B$21 | D11: 6 | E11: ='假设'!$B$29 | F11: =IF(假设!B34="Fixed",'假设'!$B$16,(假设!B42)) | G11: =0 | H11: =E11-F11+G11 | J11: 5 | K11: ='假设'!$H$7 | L11: ='假设'!$B$11+'假设'!$B$12+'假设'!$B$13 | M11: ='假设'!$B$27 | N11: =0 | O11: =K11-L11-M11+N11
A12: EPC利润 | B12: ='假设'!$B$8*'假设'!$B$22*'假设'!$B$23 | D12: 7 | E12: ='假设'!$B$29 | F12: =IF(假设!B34="Fixed",'假设'!$B$16,(假设!B42)) | G12: =0 | H12: =E12-F12+G12 | J12: 6 | K12: ='假设'!$H$7 | L12: ='假设'!$B$11+'假设'!$B$12+'假设'!$B$13 | M12: ='假设'!$B$27 | N12: =0 | O12: =K12-L12-M12+N12
A13: 资金方总利息 | B13: ='融资摊还'!$D$16 | D13: 8 | E13: ='假设'!$B$29 | F13: =IF(假设!B34="Fixed",'假设'!$B$16,(假设!B42)) | G13: =0 | H13: =E13-F13+G13 | J13: 7 | K13: ='假设'!$H$7 | L13: ='假设'!$B$11+'假设'!$B$12+'假设'!$B$13 | M13: ='假设'!$B$27 | N13: =0 | O13: =K13-L13-M13+N13
A14: 资金方净息差 | B14: ='融资摊还'!$H$16 | D14: 9 | E14: ='假设'!$B$29 | F14: =IF(假设!B34="Fixed",'假设'!$B$16,(假设!B42)) | G14: =0 | H14: =E14-F14+G14 | J14: 8 | K14: ='假设'!$H$7 | L14: ='假设'!$B$11+'假设'!$B$12+'假设'!$B$13 | M14: ='假设'!$B$27 | N14: =0 | O14: =K14-L14-M14+N14
D15: 10 | E15: ='假设'!$B$29 | F15: =IF(假设!B34="Fixed",'假设'!$B$16,(假设!B42)) | G15: ='假设'!$B$24 | H15: =E15-F15+G15 | J15: 9 | K15: ='假设'!$H$7 | L15: ='假设'!$B$11+'假设'!$B$12+'假设'!$B$13 | M15: ='假设'!$B$27 | N15: =0 | O15: =K15-L15-M15+N15
D16: 合计 | E16: =SUM(E6:E15) | F16: =SUM(F6:F15) | G16: =SUM(G6:G15) | H16: =SUM(H6:H15) | J16: 10 | K16: ='假设'!$H$7 | L16: ='假设'!$B$11+'假设'!$B$12+'假设'!$B$13 | M16: ='假设'!$B$27 | N16: =0 | O16: =K16-L16-M16+N16
J17: 合计 | K17: =SUM(K6:K16) | L17: =SUM(L6:L16) | M17: =SUM(M6:M16) | N17: =SUM(N6:N16) | O17: =SUM(O6:O16)

Sheet LaaS模式
A1: LaaS：业主年投入恒定下的参与方收益拆解
A3: 说明：业主每年总投入固定为同一金额；LaaS下甲方仍自付电费，服务商承担运维与平台成本。第10年残值默认归服务商。
A5: 指标 | B5: 数值 | D5: 年份 | E5: 基线成本 | F5: 甲方实际流出 | G5: 归甲方终值 | H5: 甲方增量收益 | J5: 年份 | K5: 收入 | L5: 直接运营成本 | M5: 债务偿付 | N5: 残值归服务方 | O5: 股权现金流
A6: 业主年总投入（恒定） | B6: ='假设'!$B$16 | D6: 1 | E6: ='假设'!$B$29 | F6: =IF(假设!B34="Fixed",'假设'!$B$16,(假设!B43+假设!B44)) | G6: =0 | H6: =E6-F6+G6 | J6: 0 | K6: =0 | L6: =0 | M6: =0 | N6: =0 | O6: =-'假设'!$B$26
A7: 甲方10年净收益 | B7: ='假设'!$B$30-B6*'假设'!$B$6+0 | D7: 2 | E7: ='假设'!$B$29 | F7: =IF(假设!B34="Fixed",'假设'!$B$16,(假设!B43+假设!B44)) | G7: =0 | H7: =E7-F7+G7 | J7: 1 | K7: ='假设'!$H$8 | L7: ='假设'!$B$12+'假设'!$B$13 | M7: ='假设'!$B$27 | N7: =0 | O7: =K7-L7-M7+N7
A8: 核心服务方10年净现金 | B8: =SUM(O6:O16) | D8: 3 | E8: ='假设'!$B$29 | F8: =IF(假设!B34="Fixed",'假设'!$B$16,(假设!B43+假设!B44)) | G8: =0 | H8: =E8-F8+G8 | J8: 2 | K8: ='假设'!$H$8 | L8: ='假设'!$B$12+'假设'!$B$13 | M8: ='假设'!$B$27 | N8: =0 | O8: =K8-L8-M8+N8
A9: 核心服务方10年收入 | B9: =SUM(K6:K16)+SUM(N6:N16) | D9: 4 | E9: ='假设'!$B$29 | F9: =IF(假设!B34="Fixed",'假设'!$B$16,(假设!B43+假设!B44)) | G9: =0 | H9: =E9-F9+G9 | J9: 3 | K9: ='假设'!$H$8 | L9: ='假设'!$B$12+'假设'!$B$13 | M9: ='假设'!$B$27 | N9: =0 | O9: =K9-L9-M9+N9
A10: 核心服务方10年直接运营成本 | B10: =SUM(L6:L16) | D10: 5 | E10: ='假设'!$B$29 | F10: =IF(假设!B34="Fixed",'假设'!$B$16,(假设!B43+假设!B44)) | G10: =0 | H10: =E10-F10+G10 | J10: 4 | K10: ='假设'!$H$8 | L10: ='假设'!$B$12+'假设'!$B$13 | M10: ='假设'!$B$27 | N10: =0 | O10: =K10-L10-M10+N10
A11: 设备商利润 | B11: ='假设'!$B$8*'假设'!$B$20*'假设'!$B$21 | D11: 6 | E11: ='假设'!$B$29 | F11: =IF(假设!B34="Fixed",'假设'!$B$16,(假设!B43+假设!B44)) | G11: =0 | H11: =E11-F11+G11 | J11: 5 | K11: ='假设'!$H$8 | L11: ='假设'!$B$12+'假设'!$B$13 | M11: ='假设'!$B$27 | N11: =0 | O11: =K11-L11-M11+N11
A12: EPC利润 | B12: ='假设'!$B$8*'假设'!$B$22*'假设'!$B$23 | D12: 7 | E12: ='假设'!$B$29 | F12: =IF(假设!B34="Fixed",'假设'!$B$16,(假设!B43+假设!B44)) | G12: =0 | H12: =E12-F12+G12 | J12: 6 | K12: ='假设'!$H$8 | L12: ='假设'!$B$12+'假设'!$B$13 | M12: ='假设'!$B$27 | N12: =0 | O12: =K12-L12-M12+N12
A13: 资金方总利息 | B13: ='融资摊还'!$D$16 | D13: 8 | E13: ='假设'!$B$29 | F13: =IF(假设!B34="Fixed",'假设'!$B$16,(假设!B43+假设!B44)) | G13: =0 | H13: =E13-F13+G13 | J13: 7 | K13: ='假设'!$H$8 | L13: ='假设'!$B$12+'假设'!$B$13 | M13: ='假设'!$B$27 | N13: =0 | O13: =K13-L13-M13+N13
A14: 资金方净息差 | B14: ='融资摊还'!$H$16 | D14: 9 | E14: ='假设'!$B$29 | F14: =IF(假设!B34="Fixed",'假设'!$B$16,(假设!B43+假设!B44)) | G14: =0 | H14: =E14-F14+G14 | J14: 8 | K14: ='假设'!$H$8 | L14: ='假设'!$B$12+'假设'!$B$13 | M14: ='假设'!$B$27 | N14: =0 | O14: =K14-L14-M14+N14
D15: 10 | E15: ='假设'!$B$29 | F15: =IF(假设!B34="Fixed",'假设'!$B$16,(假设!B43+假设!B44)) | G15: =0 | H15: =E15-F15+G15 | J15: 9 | K15: ='假设'!$H$8 | L15: ='假设'!$B$12+'假设'!$B$13 | M15: ='假设'!$B$27 | N15: =0 | O15: =K15-L15-M15+N15
D16: 合计 | E16: =SUM(E6:E15) | F16: =SUM(F6:F15) | G16: =SUM(G6:G15) | H16: =SUM(H6:H15) | J16: 10 | K16: ='假设'!$H$8 | L16: ='假设'!$B$12+'假设'!$B$13 | M16: ='假设'!$B$27 | N16: ='假设'!$B$24 | O16: =K16-L16-M16+N16
J17: 合计 | K17: =SUM(K6:K16) | L17: =SUM(L6:L16) | M17: =SUM(M6:M16) | N17: =SUM(N6:N16) | O17: =SUM(O6:O16)

Sheet 租赁模式
A1: 租赁：业主年投入恒定下的参与方收益拆解
A3: 说明：业主每年总投入固定为同一金额；租赁下甲方自付电费与运维，租金由剩余空间决定。第10年终值归甲方。
A5: 指标 | B5: 数值 | D5: 年份 | E5: 基线成本 | F5: 甲方实际流出 | G5: 归甲方终值 | H5: 甲方增量收益 | J5: 年份 | K5: 收入 | L5: 直接运营成本 | M5: 债务偿付 | N5: 残值归服务方 | O5: 股权现金流
A6: 业主年总投入（恒定） | B6: ='假设'!$B$16 | D6: 1 | E6: ='假设'!$B$29 | F6: =IF(假设!B34="Fixed",'假设'!$B$16,(假设!B46+'假设'!$B$11+'假设'!$B$12)) | G6: =0 | H6: =E6-F6+G6 | J6: 0 | K6: =0 | L6: =0 | M6: =0 | N6: =0 | O6: =-'假设'!$B$26
A7: 甲方10年净收益 | B7: ='假设'!$B$30-B6*'假设'!$B$6+='假设'!$B$24 | D7: 2 | E7: ='假设'!$B$29 | F7: =IF(假设!B34="Fixed",'假设'!$B$16,(假设!B46+'假设'!$B$11+'假设'!$B$12)) | G7: =0 | H7: =E7-F7+G7 | J7: 1 | K7: ='假设'!$H$9 | L7: ='假设'!$B$15 | M7: ='假设'!$B$27 | N7: =0 | O7: =K7-L7-M7+N7
A8: 核心服务方10年净现金 | B8: =SUM(O6:O16) | D8: 3 | E8: ='假设'!$B$29 | F8: =IF(假设!B34="Fixed",'假设'!$B$16,(假设!B46+'假设'!$B$11+'假设'!$B$12)) | G8: =0 | H8: =E8-F8+G8 | J8: 2 | K8: ='假设'!$H$9 | L8: ='假设'!$B$15 | M8: ='假设'!$B$27 | N8: =0 | O8: =K8-L8-M8+N8
A9: 核心服务方10年收入 | B9: =SUM(K6:K16)+SUM(N6:N16) | D9: 4 | E9: ='假设'!$B$29 | F9: =IF(假设!B34="Fixed",'假设'!$B$16,(假设!B46+'假设'!$B$11+'假设'!$B$12)) | G9: =0 | H9: =E9-F9+G9 | J9: 3 | K9: ='假设'!$H$9 | L9: ='假设'!$B$15 | M9: ='假设'!$B$27 | N9: =0 | O9: =K9-L9-M9+N9
A10: 核心服务方10年直接运营成本 | B10: =SUM(L6:L16) | D10: 5 | E10: ='假设'!$B$29 | F10: =IF(假设!B34="Fixed",'假设'!$B$16,(假设!B46+'假设'!$B$11+'假设'!$B$12)) | G10: =0 | H10: =E10-F10+G10 | J10: 4 | K10: ='假设'!$H$9 | L10: ='假设'!$B$15 | M10: ='假设'!$B$27 | N10: =0 | O10: =K10-L10-M10+N10
A11: 设备商利润 | B11: ='假设'!$B$8*'假设'!$B$20*'假设'!$B$21 | D11: 6 | E11: ='假设'!$B$29 | F11: =IF(假设!B34="Fixed",'假设'!$B$16,(假设!B46+'假设'!$B$11+'假设'!$B$12)) | G11: =0 | H11: =E11-F11+G11 | J11: 5 | K11: ='假设'!$H$9 | L11: ='假设'!$B$15 | M11: ='假设'!$B$27 | N11: =0 | O11: =K11-L11-M11+N11
A12: EPC利润 | B12: ='假设'!$B$8*'假设'!$B$22*'假设'!$B$23 | D12: 7 | E12: ='假设'!$B$29 | F12: =IF(假设!B34="Fixed",'假设'!$B$16,(假设!B46+'假设'!$B$11+'假设'!$B$12)) | G12: =0 | H12: =E12-F12+G12 | J12: 6 | K12: ='假设'!$H$9 | L12: ='假设'!$B$15 | M12: ='假设'!$B$27 | N12: =0 | O12: =K12-L12-M12+N12
A13: 资金方总利息 | B13: ='融资摊还'!$D$16 | D13: 8 | E13: ='假设'!$B$29 | F13: =IF(假设!B34="Fixed",'假设'!$B$16,(假设!B46+'假设'!$B$11+'假设'!$B$12)) | G13: =0 | H13: =E13-F13+G13 | J13: 7 | K13: ='假设'!$H$9 | L13: ='假设'!$B$15 | M13: ='假设'!$B$27 | N13: =0 | O13: =K13-L13-M13+N13
A14: 资金方净息差 | B14: ='融资摊还'!$H$16 | D14: 9 | E14: ='假设'!$B$29 | F14: =IF(假设!B34="Fixed",'假设'!$B$16,(假设!B46+'假设'!$B$11+'假设'!$B$12)) | G14: =0 | H14: =E14-F14+G14 | J14: 8 | K14: ='假设'!$H$9 | L14: ='假设'!$B$15 | M14: ='假设'!$B$27 | N14: =0 | O14: =K14-L14-M14+N14
D15: 10 | E15: ='假设'!$B$29 | F15: =IF(假设!B34="Fixed",'假设'!$B$16,(假设!B46+'假设'!$B$11+'假设'!$B$12)) | G15: ='假设'!$B$24 | H15: =E15-F15+G15 | J15: 9 | K15: ='假设'!$H$9 | L15: ='假设'!$B$15 | M15: ='假设'!$B$27 | N15: =0 | O15: =K15-L15-M15+N15
D16: 合计 | E16: =SUM(E6:E15) | F16: =SUM(F6:F15) | G16: =SUM(G6:G15) | H16: =SUM(H6:H15) | J16: 10 | K16: ='假设'!$H$9 | L16: ='假设'!$B$15 | M16: ='假设'!$B$27 | N16: =0 | O16: =K16-L16-M16+N16
J17: 合计 | K17: =SUM(K6:K16) | L17: =SUM(L6:L16) | M17: =SUM(M6:M16) | N17: =SUM(N6:N16) | O17: =SUM(O6:O16)

Sheet 来源
A1: 来源与说明
A3: 本工作簿的模式定义与利润逻辑沿用此前公开资料；本次修订仅改变建模约束：将“业主年总投入”设为恒定值。
A5: 主题 | B5: URL | C5: 用途
A6: EMC定义 / 回款逻辑 | B6: https://www.ndrc.gov.cn/fggz/fzzlgh/gjfzgh/202112/t20211224_1309459.html | C6: 用于确认EMC通过节能收益或服务费回款
A7: GB/T 24915 合同类型 | B7: https://www.cnis.ac.cn/bydt/bzyjzq/gbyjzq/201901/P020190223345417615159.pdf | C7: 用于确认分享型、保证型、能源托管型、融资租赁型等合同结构
A8: 公共机构能源费用托管 | B8: https://www.nhc.gov.cn/guihuaxxs/c100133/202210/64426e407ed944129269f1a9987d11fa/files/1733226470216_70623.pdf | C8: 用于确认服务采购、5–10年期限、资产移交与预算口径
A9: 路灯能源托管招标案例 | B9: https://ggzyjyzx.tl.gov.cn/jyxx/003002/003002002/20251204/b2640348-e1ba-48ad-90d4-e621d6dca0a2.html | C9: 用于确认路灯托管通常包含改造、电费与维护
A10: LaaS 官方说明 | B10: https://www.signify.com/global/signify-services/managed-services/light-as-a-service | C10: 用于确认“买光服务，不是买系统”的逻辑
A11: LaaS 资产归属 / 残值 | B11: https://www.ellenmacarthurfoundation.org/circular-examples/light-as-a-service | C11: 用于确认服务商持有资产与终值/再部署逻辑
A12: 路灯 lease-to-own | B12: https://ppp.worldbank.org/print/pdf/node/3718 | C12: 用于确认路灯租赁/期满移交的交付结构

Sheet 逐年利润对比
A1: 逐年利润对比（从项目建成第1年开始）
A2: 口径说明：业主年总投入固定；下表只看建成后第1年至第10年的年度差异。设备商、EPC和核心服务方初始股权投入属于建设期一次性项目，不在年度运营差异中拉开模式差距。
A4: 一、甲方逐年增量收益对比（相对改造前基线）
A5: 年份 | B5: EMC | C5: 能源托管 | D5: LaaS | E5: 租赁 | F5: 年度最高 | G5: 年度最低 | H5: 差额 | I5: 年度差异说明
A6: 1 | B6: ='EMC模式'!H6 | C6: ='能源托管模式'!H6 | D6: ='LaaS模式'!H6 | E6: ='租赁模式'!H6 | F6: =MAX(B6:E6) | G6: =MIN(B6:E6) | H6: =F6-G6 | I6: 前9年甲方收益一致，差异主要不在甲方侧而在服务方分配
A7: 2 | B7: ='EMC模式'!H7 | C7: ='能源托管模式'!H7 | D7: ='LaaS模式'!H7 | E7: ='租赁模式'!H7 | F7: =MAX(B7:E7) | G7: =MIN(B7:E7) | H7: =F7-G7 | I7: 前9年甲方收益一致，差异主要不在甲方侧而在服务方分配
A8: 3 | B8: ='EMC模式'!H8 | C8: ='能源托管模式'!H8 | D8: ='LaaS模式'!H8 | E8: ='租赁模式'!H8 | F8: =MAX(B8:E8) | G8: =MIN(B8:E8) | H8: =F8-G8 | I8: 前9年甲方收益一致，差异主要不在甲方侧而在服务方分配
A9: 4 | B9: ='EMC模式'!H9 | C9: ='能源托管模式'!H9 | D9: ='LaaS模式'!H9 | E9: ='租赁模式'!H9 | F9: =MAX(B9:E9) | G9: =MIN(B9:E9) | H9: =F9-G9 | I9: 前9年甲方收益一致，差异主要不在甲方侧而在服务方分配
A10: 5 | B10: ='EMC模式'!H10 | C10: ='能源托管模式'!H10 | D10: ='LaaS模式'!H10 | E10: ='租赁模式'!H10 | F10: =MAX(B10:E10) | G10: =MIN(B10:E10) | H10: =F10-G10 | I10: 前9年甲方收益一致，差异主要不在甲方侧而在服务方分配
A11: 6 | B11: ='EMC模式'!H11 | C11: ='能源托管模式'!H11 | D11: ='LaaS模式'!H11 | E11: ='租赁模式'!H11 | F11: =MAX(B11:E11) | G11: =MIN(B11:E11) | H11: =F11-G11 | I11: 前9年甲方收益一致，差异主要不在甲方侧而在服务方分配
A12: 7 | B12: ='EMC模式'!H12 | C12: ='能源托管模式'!H12 | D12: ='LaaS模式'!H12 | E12: ='租赁模式'!H12 | F12: =MAX(B12:E12) | G12: =MIN(B12:E12) | H12: =F12-G12 | I12: 前9年甲方收益一致，差异主要不在甲方侧而在服务方分配
A13: 8 | B13: ='EMC模式'!H13 | C13: ='能源托管模式'!H13 | D13: ='LaaS模式'!H13 | E13: ='租赁模式'!H13 | F13: =MAX(B13:E13) | G13: =MIN(B13:E13) | H13: =F13-G13 | I13: 前9年甲方收益一致，差异主要不在甲方侧而在服务方分配
A14: 9 | B14: ='EMC模式'!H14 | C14: ='能源托管模式'!H14 | D14: ='LaaS模式'!H14 | E14: ='租赁模式'!H14 | F14: =MAX(B14:E14) | G14: =MIN(B14:E14) | H14: =F14-G14 | I14: 前9年甲方收益一致，差异主要不在甲方侧而在服务方分配
A15: 10 | B15: ='EMC模式'!H15 | C15: ='能源托管模式'!H15 | D15: ='LaaS模式'!H15 | E15: ='租赁模式'!H15 | F15: =MAX(B15:E15) | G15: =MIN(B15:E15) | H15: =F15-G15 | I15: 第10年开始出现终值归属差异；LaaS默认终值不归甲方
A16: 合计 | B16: =SUM(B6:B15) | C16: =SUM(C6:C15) | D16: =SUM(D6:D15) | E16: =SUM(E6:E15) | F16: =SUM(F6:F15) | G16: =SUM(G6:G15) | H16: =SUM(H6:H15) | I16: 10年累计差异
A19: 二、核心服务方逐年净经营现金对比（未扣建设期初始股权投入）
A20: 年份 | B20: EMC | C20: 能源托管 | D20: LaaS | E20: 租赁 | F20: 年度最高 | G20: 年度最低 | H20: 差额 | I20: 年度差异说明
A21: 1 | B21: ='EMC模式'!K7-'EMC模式'!L7-'EMC模式'!M7+'EMC模式'!N7 | C21: ='能源托管模式'!K7-'能源托管模式'!L7-'能源托管模式'!M7+'能源托管模式'!N7 | D21: ='LaaS模式'!K7-'LaaS模式'!L7-'LaaS模式'!M7+'LaaS模式'!N7 | E21: ='租赁模式'!K7-'租赁模式'!L7-'租赁模式'!M7+'租赁模式'!N7 | F21: =MAX(B21:E21) | G21: =MIN(B21:E21) | H21: =F21-G21 | I21: 年度差异主要来自：服务费口径不同 + 谁承担运维成本；债务条件相同
A22: 2 | B22: ='EMC模式'!K8-'EMC模式'!L8-'EMC模式'!M8+'EMC模式'!N8 | C22: ='能源托管模式'!K8-'能源托管模式'!L8-'能源托管模式'!M8+'能源托管模式'!N8 | D22: ='LaaS模式'!K8-'LaaS模式'!L8-'LaaS模式'!M8+'LaaS模式'!N8 | E22: ='租赁模式'!K8-'租赁模式'!L8-'租赁模式'!M8+'租赁模式'!N8 | F22: =MAX(B22:E22) | G22: =MIN(B22:E22) | H22: =F22-G22 | I22: 年度差异主要来自：服务费口径不同 + 谁承担运维成本；债务条件相同
A23: 3 | B23: ='EMC模式'!K9-'EMC模式'!L9-'EMC模式'!M9+'EMC模式'!N9 | C23: ='能源托管模式'!K9-'能源托管模式'!L9-'能源托管模式'!M9+'能源托管模式'!N9 | D23: ='LaaS模式'!K9-'LaaS模式'!L9-'LaaS模式'!M9+'LaaS模式'!N9 | E23: ='租赁模式'!K9-'租赁模式'!L9-'租赁模式'!M9+'租赁模式'!N9 | F23: =MAX(B23:E23) | G23: =MIN(B23:E23) | H23: =F23-G23 | I23: 年度差异主要来自：服务费口径不同 + 谁承担运维成本；债务条件相同
A24: 4 | B24: ='EMC模式'!K10-'EMC模式'!L10-'EMC模式'!M10+'EMC模式'!N10 | C24: ='能源托管模式'!K10-'能源托管模式'!L10-'能源托管模式'!M10+'能源托管模式'!N10 | D24: ='LaaS模式'!K10-'LaaS模式'!L10-'LaaS模式'!M10+'LaaS模式'!N10 | E24: ='租赁模式'!K10-'租赁模式'!L10-'租赁模式'!M10+'租赁模式'!N10 | F24: =MAX(B24:E24) | G24: =MIN(B24:E24) | H24: =F24-G24 | I24: 年度差异主要来自：服务费口径不同 + 谁承担运维成本；债务条件相同
A25: 5 | B25: ='EMC模式'!K11-'EMC模式'!L11-'EMC模式'!M11+'EMC模式'!N11 | C25: ='能源托管模式'!K11-'能源托管模式'!L11-'能源托管模式'!M11+'能源托管模式'!N11 | D25: ='LaaS模式'!K11-'LaaS模式'!L11-'LaaS模式'!M11+'LaaS模式'!N11 | E25: ='租赁模式'!K11-'租赁模式'!L11-'租赁模式'!M11+'租赁模式'!N11 | F25: =MAX(B25:E25) | G25: =MIN(B25:E25) | H25: =F25-G25 | I25: 年度差异主要来自：服务费口径不同 + 谁承担运维成本；债务条件相同
A26: 6 | B26: ='EMC模式'!K12-'EMC模式'!L12-'EMC模式'!M12+'EMC模式'!N12 | C26: ='能源托管模式'!K12-'能源托管模式'!L12-'能源托管模式'!M12+'能源托管模式'!N12 | D26: ='LaaS模式'!K12-'LaaS模式'!L12-'LaaS模式'!M12+'LaaS模式'!N12 | E26: ='租赁模式'!K12-'租赁模式'!L12-'租赁模式'!M12+'租赁模式'!N12 | F26: =MAX(B26:E26) | G26: =MIN(B26:E26) | H26: =F26-G26 | I26: 年度差异主要来自：服务费口径不同 + 谁承担运维成本；债务条件相同
A27: 7 | B27: ='EMC模式'!K13-'EMC模式'!L13-'EMC模式'!M13+'EMC模式'!N13 | C27: ='能源托管模式'!K13-'能源托管模式'!L13-'能源托管模式'!M13+'能源托管模式'!N13 | D27: ='LaaS模式'!K13-'LaaS模式'!L13-'LaaS模式'!M13+'LaaS模式'!N13 | E27: ='租赁模式'!K13-'租赁模式'!L13-'租赁模式'!M13+'租赁模式'!N13 | F27: =MAX(B27:E27) | G27: =MIN(B27:E27) | H27: =F27-G27 | I27: 年度差异主要来自：服务费口径不同 + 谁承担运维成本；债务条件相同
A28: 8 | B28: ='EMC模式'!K14-'EMC模式'!L14-'EMC模式'!M14+'EMC模式'!N14 | C28: ='能源托管模式'!K14-'能源托管模式'!L14-'能源托管模式'!M14+'能源托管模式'!N14 | D28: ='LaaS模式'!K14-'LaaS模式'!L14-'LaaS模式'!M14+'LaaS模式'!N14 | E28: ='租赁模式'!K14-'租赁模式'!L14-'租赁模式'!M14+'租赁模式'!N14 | F28: =MAX(B28:E28) | G28: =MIN(B28:E28) | H28: =F28-G28 | I28: 年度差异主要来自：服务费口径不同 + 谁承担运维成本；债务条件相同
A29: 9 | B29: ='EMC模式'!K15-'EMC模式'!L15-'EMC模式'!M15+'EMC模式'!N15 | C29: ='能源托管模式'!K15-'能源托管模式'!L15-'能源托管模式'!M15+'能源托管模式'!N15 | D29: ='LaaS模式'!K15-'LaaS模式'!L15-'LaaS模式'!M15+'LaaS模式'!N15 | E29: ='租赁模式'!K15-'租赁模式'!L15-'租赁模式'!M15+'租赁模式'!N15 | F29: =MAX(B29:E29) | G29: =MIN(B29:E29) | H29: =F29-G29 | I29: 年度差异主要来自：服务费口径不同 + 谁承担运维成本；债务条件相同
A30: 10 | B30: ='EMC模式'!K16-'EMC模式'!L16-'EMC模式'!M16+'EMC模式'!N16 | C30: ='能源托管模式'!K16-'能源托管模式'!L16-'能源托管模式'!M16+'能源托管模式'!N16 | D30: ='LaaS模式'!K16-'LaaS模式'!L16-'LaaS模式'!M16+'LaaS模式'!N16 | E30: ='租赁模式'!K16-'租赁模式'!L16-'租赁模式'!M16+'租赁模式'!N16 | F30: =MAX(B30:E30) | G30: =MIN(B30:E30) | H30: =F30-G30 | I30: 第10年差异再叠加残值/终值归属；LaaS默认残值归服务方
A31: 合计 | B31: =SUM(B21:B30) | C31: =SUM(C21:C30) | D31: =SUM(D21:D30) | E31: =SUM(E21:E30) | F31: =SUM(F21:F30) | G31: =SUM(G21:G30) | H31: =SUM(H21:H30) | I31: 10年经营期累计
A34: 三、建设期/不拉开年度模式差异的项目
A35: 项目 | B35: 发生时点 | C35: 金额/口径 | D35: 四模式差异 | E35: 说明
A36: 设备商利润 | B36: 建设期 | C36: ='汇总对比'!B8 | D36: 无 | E36: 同一CAPEX口径下，设备商利润在建设期确认，四模式相同
A37: EPC利润 | B37: 建设期 | C37: ='汇总对比'!B9 | D37: 无 | E37: 同一CAPEX口径下，EPC利润在建设期确认，四模式相同
A38: 核心服务方初始股权投入 | B38: 建设期 | C38: ='假设'!B8*(1-'假设'!B17) | D38: 无 | E38: 四模式均按同一资本金比例投入；它影响最终净收益，但不影响第1-10年的年度经营差异
A39: 资金方净息差 | B39: 第1-10年 | C39: ='汇总对比'!B10 | D39: 无 | E39: 融资比例、利率、资金成本相同，因此资金方收益基本不拉开模式差距

Sheet 年度差异来源
A1: 年度差异来源拆解（逐年看利润差在哪里）
A2: 阅读方法：先看甲方侧的D~H列，再看核心服务方侧的I~Q列。与EMC相比，差额到底来自“收入更多”“运维成本更高/更低”还是“第10年残值归属”，都在同一行直接展开。
A4: 模式 | B4: 年份 | C4: 业主年总投入 | D4: 业主自付电费 | E4: 业主自付运维 | F4: 支付给核心服务方 | G4: 甲方增量收益 | H4: 甲方较EMC差额 | I4: 核心服务方收入 | J4: 直接运营成本 | K4: 债务偿付 | L4: 残值归服务方 | M4: 核心服务方净经营现金 | N4: 收入较EMC差额 | O4: 运营成本较EMC差额 | P4: 残值较EMC差额 | Q4: 净现金较EMC差额 | R4: 差异主要来自
A6: EMC | B6: 1 | C6: ='假设'!E6 | D6: ='假设'!F6 | E6: ='假设'!G6 | F6: ='假设'!H6 | G6: ='EMC模式'!H6 | H6: =G6-'EMC模式'!H6 | I6: ='EMC模式'!K7 | J6: ='EMC模式'!L7 | K6: ='EMC模式'!M7 | L6: ='EMC模式'!N7 | M6: =I6-J6-K6+L6 | N6: =I6-'EMC模式'!K7 | O6: =J6-'EMC模式'!L7 | P6: =L6-'EMC模式'!N7 | Q6: =M6-('EMC模式'!K7-'EMC模式'!L7-'EMC模式'!M7+'EMC模式'!N7) | R6: EMC作为基准模式：业主自付电费+运维，服务方主要赚节能服务费
A7: EMC | B7: 2 | C7: ='假设'!E6 | D7: ='假设'!F6 | E7: ='假设'!G6 | F7: ='假设'!H6 | G7: ='EMC模式'!H7 | H7: =G7-'EMC模式'!H7 | I7: ='EMC模式'!K8 | J7: ='EMC模式'!L8 | K7: ='EMC模式'!M8 | L7: ='EMC模式'!N8 | M7: =I7-J7-K7+L7 | N7: =I7-'EMC模式'!K8 | O7: =J7-'EMC模式'!L8 | P7: =L7-'EMC模式'!N8 | Q7: =M7-('EMC模式'!K8-'EMC模式'!L8-'EMC模式'!M8+'EMC模式'!N8) | R7: EMC作为基准模式：业主自付电费+运维，服务方主要赚节能服务费
A8: EMC | B8: 3 | C8: ='假设'!E6 | D8: ='假设'!F6 | E8: ='假设'!G6 | F8: ='假设'!H6 | G8: ='EMC模式'!H8 | H8: =G8-'EMC模式'!H8 | I8: ='EMC模式'!K9 | J8: ='EMC模式'!L9 | K8: ='EMC模式'!M9 | L8: ='EMC模式'!N9 | M8: =I8-J8-K8+L8 | N8: =I8-'EMC模式'!K9 | O8: =J8-'EMC模式'!L9 | P8: =L8-'EMC模式'!N9 | Q8: =M8-('EMC模式'!K9-'EMC模式'!L9-'EMC模式'!M9+'EMC模式'!N9) | R8: EMC作为基准模式：业主自付电费+运维，服务方主要赚节能服务费
A9: EMC | B9: 4 | C9: ='假设'!E6 | D9: ='假设'!F6 | E9: ='假设'!G6 | F9: ='假设'!H6 | G9: ='EMC模式'!H9 | H9: =G9-'EMC模式'!H9 | I9: ='EMC模式'!K10 | J9: ='EMC模式'!L10 | K9: ='EMC模式'!M10 | L9: ='EMC模式'!N10 | M9: =I9-J9-K9+L9 | N9: =I9-'EMC模式'!K10 | O9: =J9-'EMC模式'!L10 | P9: =L9-'EMC模式'!N10 | Q9: =M9-('EMC模式'!K10-'EMC模式'!L10-'EMC模式'!M10+'EMC模式'!N10) | R9: EMC作为基准模式：业主自付电费+运维，服务方主要赚节能服务费
A10: EMC | B10: 5 | C10: ='假设'!E6 | D10: ='假设'!F6 | E10: ='假设'!G6 | F10: ='假设'!H6 | G10: ='EMC模式'!H10 | H10: =G10-'EMC模式'!H10 | I10: ='EMC模式'!K11 | J10: ='EMC模式'!L11 | K10: ='EMC模式'!M11 | L10: ='EMC模式'!N11 | M10: =I10-J10-K10+L10 | N10: =I10-'EMC模式'!K11 | O10: =J10-'EMC模式'!L11 | P10: =L10-'EMC模式'!N11 | Q10: =M10-('EMC模式'!K11-'EMC模式'!L11-'EMC模式'!M11+'EMC模式'!N11) | R10: EMC作为基准模式：业主自付电费+运维，服务方主要赚节能服务费
A11: EMC | B11: 6 | C11: ='假设'!E6 | D11: ='假设'!F6 | E11: ='假设'!G6 | F11: ='假设'!H6 | G11: ='EMC模式'!H11 | H11: =G11-'EMC模式'!H11 | I11: ='EMC模式'!K12 | J11: ='EMC模式'!L12 | K11: ='EMC模式'!M12 | L11: ='EMC模式'!N12 | M11: =I11-J11-K11+L11 | N11: =I11-'EMC模式'!K12 | O11: =J11-'EMC模式'!L12 | P11: =L11-'EMC模式'!N12 | Q11: =M11-('EMC模式'!K12-'EMC模式'!L12-'EMC模式'!M12+'EMC模式'!N12) | R11: EMC作为基准模式：业主自付电费+运维，服务方主要赚节能服务费
A12: EMC | B12: 7 | C12: ='假设'!E6 | D12: ='假设'!F6 | E12: ='假设'!G6 | F12: ='假设'!H6 | G12: ='EMC模式'!H12 | H12: =G12-'EMC模式'!H12 | I12: ='EMC模式'!K13 | J12: ='EMC模式'!L13 | K12: ='EMC模式'!M13 | L12: ='EMC模式'!N13 | M12: =I12-J12-K12+L12 | N12: =I12-'EMC模式'!K13 | O12: =J12-'EMC模式'!L13 | P12: =L12-'EMC模式'!N13 | Q12: =M12-('EMC模式'!K13-'EMC模式'!L13-'EMC模式'!M13+'EMC模式'!N13) | R12: EMC作为基准模式：业主自付电费+运维，服务方主要赚节能服务费
A13: EMC | B13: 8 | C13: ='假设'!E6 | D13: ='假设'!F6 | E13: ='假设'!G6 | F13: ='假设'!H6 | G13: ='EMC模式'!H13 | H13: =G13-'EMC模式'!H13 | I13: ='EMC模式'!K14 | J13: ='EMC模式'!L14 | K13: ='EMC模式'!M14 | L13: ='EMC模式'!N14 | M13: =I13-J13-K13+L13 | N13: =I13-'EMC模式'!K14 | O13: =J13-'EMC模式'!L14 | P13: =L13-'EMC模式'!N14 | Q13: =M13-('EMC模式'!K14-'EMC模式'!L14-'EMC模式'!M14+'EMC模式'!N14) | R13: EMC作为基准模式：业主自付电费+运维，服务方主要赚节能服务费
A14: EMC | B14: 9 | C14: ='假设'!E6 | D14: ='假设'!F6 | E14: ='假设'!G6 | F14: ='假设'!H6 | G14: ='EMC模式'!H14 | H14: =G14-'EMC模式'!H14 | I14: ='EMC模式'!K15 | J14: ='EMC模式'!L15 | K14: ='EMC模式'!M15 | L14: ='EMC模式'!N15 | M14: =I14-J14-K14+L14 | N14: =I14-'EMC模式'!K15 | O14: =J14-'EMC模式'!L15 | P14: =L14-'EMC模式'!N15 | Q14: =M14-('EMC模式'!K15-'EMC模式'!L15-'EMC模式'!M15+'EMC模式'!N15) | R14: EMC作为基准模式：业主自付电费+运维，服务方主要赚节能服务费
A15: EMC | B15: 10 | C15: ='假设'!E6 | D15: ='假设'!F6 | E15: ='假设'!G6 | F15: ='假设'!H6 | G15: ='EMC模式'!H15 | H15: =G15-'EMC模式'!H15 | I15: ='EMC模式'!K16 | J15: ='EMC模式'!L16 | K15: ='EMC模式'!M16 | L15: ='EMC模式'!N16 | M15: =I15-J15-K15+L15 | N15: =I15-'EMC模式'!K16 | O15: =J15-'EMC模式'!L16 | P15: =L15-'EMC模式'!N16 | Q15: =M15-('EMC模式'!K16-'EMC模式'!L16-'EMC模式'!M16+'EMC模式'!N16) | R15: 第10年含终值/残值归属；本模式下终值归甲方，因此甲方收益高于LaaS
A16: 能源托管 | B16: 1 | C16: ='假设'!E7 | D16: ='假设'!F7 | E16: ='假设'!G7 | F16: ='假设'!H7 | G16: ='能源托管模式'!H6 | H16: =G16-'EMC模式'!H6 | I16: ='能源托管模式'!K7 | J16: ='能源托管模式'!L7 | K16: ='能源托管模式'!M7 | L16: ='能源托管模式'!N7 | M16: =I16-J16-K16+L16 | N16: =I16-'EMC模式'!K7 | O16: =J16-'EMC模式'!L7 | P16: =L16-'EMC模式'!N7 | Q16: =M16-('EMC模式'!K7-'EMC模式'!L7-'EMC模式'!M7+'EMC模式'!N7) | R16: 业主不再单列电费和运维，全部并入托管费；服务方收入更高，但同时承担电费与运维
A17: 能源托管 | B17: 2 | C17: ='假设'!E7 | D17: ='假设'!F7 | E17: ='假设'!G7 | F17: ='假设'!H7 | G17: ='能源托管模式'!H7 | H17: =G17-'EMC模式'!H7 | I17: ='能源托管模式'!K8 | J17: ='能源托管模式'!L8 | K17: ='能源托管模式'!M8 | L17: ='能源托管模式'!N8 | M17: =I17-J17-K17+L17 | N17: =I17-'EMC模式'!K8 | O17: =J17-'EMC模式'!L8 | P17: =L17-'EMC模式'!N8 | Q17: =M17-('EMC模式'!K8-'EMC模式'!L8-'EMC模式'!M8+'EMC模式'!N8) | R17: 业主不再单列电费和运维，全部并入托管费；服务方收入更高，但同时承担电费与运维
A18: 能源托管 | B18: 3 | C18: ='假设'!E7 | D18: ='假设'!F7 | E18: ='假设'!G7 | F18: ='假设'!H7 | G18: ='能源托管模式'!H8 | H18: =G18-'EMC模式'!H8 | I18: ='能源托管模式'!K9 | J18: ='能源托管模式'!L9 | K18: ='能源托管模式'!M9 | L18: ='能源托管模式'!N9 | M18: =I18-J18-K18+L18 | N18: =I18-'EMC模式'!K9 | O18: =J18-'EMC模式'!L9 | P18: =L18-'EMC模式'!N9 | Q18: =M18-('EMC模式'!K9-'EMC模式'!L9-'EMC模式'!M9+'EMC模式'!N9) | R18: 业主不再单列电费和运维，全部并入托管费；服务方收入更高，但同时承担电费与运维
A19: 能源托管 | B19: 4 | C19: ='假设'!E7 | D19: ='假设'!F7 | E19: ='假设'!G7 | F19: ='假设'!H7 | G19: ='能源托管模式'!H9 | H19: =G19-'EMC模式'!H9 | I19: ='能源托管模式'!K10 | J19: ='能源托管模式'!L10 | K19: ='能源托管模式'!M10 | L19: ='能源托管模式'!N10 | M19: =I19-J19-K19+L19 | N19: =I19-'EMC模式'!K10 | O19: =J19-'EMC模式'!L10 | P19: =L19-'EMC模式'!N10 | Q19: =M19-('EMC模式'!K10-'EMC模式'!L10-'EMC模式'!M10+'EMC模式'!N10) | R19: 业主不再单列电费和运维，全部并入托管费；服务方收入更高，但同时承担电费与运维
A20: 能源托管 | B20: 5 | C20: ='假设'!E7 | D20: ='假设'!F7 | E20: ='假设'!G7 | F20: ='假设'!H7 | G20: ='能源托管模式'!H10 | H20: =G20-'EMC模式'!H10 | I20: ='能源托管模式'!K11 | J20: ='能源托管模式'!L11 | K20: ='能源托管模式'!M11 | L20: ='能源托管模式'!N11 | M20: =I20-J20-K20+L20 | N20: =I20-'EMC模式'!K11 | O20: =J20-'EMC模式'!L11 | P20: =L20-'EMC模式'!N11 | Q20: =M20-('EMC模式'!K11-'EMC模式'!L11-'EMC模式'!M11+'EMC模式'!N11) | R20: 业主不再单列电费和运维，全部并入托管费；服务方收入更高，但同时承担电费与运维
A21: 能源托管 | B21: 6 | C21: ='假设'!E7 | D21: ='假设'!F7 | E21: ='假设'!G7 | F21: ='假设'!H7 | G21: ='能源托管模式'!H11 | H21: =G21-'EMC模式'!H11 | I21: ='能源托管模式'!K12 | J21: ='能源托管模式'!L12 | K21: ='能源托管模式'!M12 | L21: ='能源托管模式'!N12 | M21: =I21-J21-K21+L21 | N21: =I21-'EMC模式'!K12 | O21: =J21-'EMC模式'!L12 | P21: =L21-'EMC模式'!N12 | Q21: =M21-('EMC模式'!K12-'EMC模式'!L12-'EMC模式'!M12+'EMC模式'!N12) | R21: 业主不再单列电费和运维，全部并入托管费；服务方收入更高，但同时承担电费与运维
A22: 能源托管 | B22: 7 | C22: ='假设'!E7 | D22: ='假设'!F7 | E22: ='假设'!G7 | F22: ='假设'!H7 | G22: ='能源托管模式'!H12 | H22: =G22-'EMC模式'!H12 | I22: ='能源托管模式'!K13 | J22: ='能源托管模式'!L13 | K22: ='能源托管模式'!M13 | L22: ='能源托管模式'!N13 | M22: =I22-J22-K22+L22 | N22: =I22-'EMC模式'!K13 | O22: =J22-'EMC模式'!L13 | P22: =L22-'EMC模式'!N13 | Q22: =M22-('EMC模式'!K13-'EMC模式'!L13-'EMC模式'!M13+'EMC模式'!N13) | R22: 业主不再单列电费和运维，全部并入托管费；服务方收入更高，但同时承担电费与运维
A23: 能源托管 | B23: 8 | C23: ='假设'!E7 | D23: ='假设'!F7 | E23: ='假设'!G7 | F23: ='假设'!H7 | G23: ='能源托管模式'!H13 | H23: =G23-'EMC模式'!H13 | I23: ='能源托管模式'!K14 | J23: ='能源托管模式'!L14 | K23: ='能源托管模式'!M14 | L23: ='能源托管模式'!N14 | M23: =I23-J23-K23+L23 | N23: =I23-'EMC模式'!K14 | O23: =J23-'EMC模式'!L14 | P23: =L23-'EMC模式'!N14 | Q23: =M23-('EMC模式'!K14-'EMC模式'!L14-'EMC模式'!M14+'EMC模式'!N14) | R23: 业主不再单列电费和运维，全部并入托管费；服务方收入更高，但同时承担电费与运维
A24: 能源托管 | B24: 9 | C24: ='假设'!E7 | D24: ='假设'!F7 | E24: ='假设'!G7 | F24: ='假设'!H7 | G24: ='能源托管模式'!H14 | H24: =G24-'EMC模式'!H14 | I24: ='能源托管模式'!K15 | J24: ='能源托管模式'!L15 | K24: ='能源托管模式'!M15 | L24: ='能源托管模式'!N15 | M24: =I24-J24-K24+L24 | N24: =I24-'EMC模式'!K15 | O24: =J24-'EMC模式'!L15 | P24: =L24-'EMC模式'!N15 | Q24: =M24-('EMC模式'!K15-'EMC模式'!L15-'EMC模式'!M15+'EMC模式'!N15) | R24: 业主不再单列电费和运维，全部并入托管费；服务方收入更高，但同时承担电费与运维
A25: 能源托管 | B25: 10 | C25: ='假设'!E7 | D25: ='假设'!F7 | E25: ='假设'!G7 | F25: ='假设'!H7 | G25: ='能源托管模式'!H15 | H25: =G25-'EMC模式'!H15 | I25: ='能源托管模式'!K16 | J25: ='能源托管模式'!L16 | K25: ='能源托管模式'!M16 | L25: ='能源托管模式'!N16 | M25: =I25-J25-K25+L25 | N25: =I25-'EMC模式'!K16 | O25: =J25-'EMC模式'!L16 | P25: =L25-'EMC模式'!N16 | Q25: =M25-('EMC模式'!K16-'EMC模式'!L16-'EMC模式'!M16+'EMC模式'!N16) | R25: 第10年含终值/残值归属；本模式下终值归甲方，因此甲方收益高于LaaS
A26: LaaS | B26: 1 | C26: ='假设'!E8 | D26: ='假设'!F8 | E26: ='假设'!G8 | F26: ='假设'!H8 | G26: ='LaaS模式'!H6 | H26: =G26-'EMC模式'!H6 | I26: ='LaaS模式'!K7 | J26: ='LaaS模式'!L7 | K26: ='LaaS模式'!M7 | L26: ='LaaS模式'!N7 | M26: =I26-J26-K26+L26 | N26: =I26-'EMC模式'!K7 | O26: =J26-'EMC模式'!L7 | P26: =L26-'EMC模式'!N7 | Q26: =M26-('EMC模式'!K7-'EMC模式'!L7-'EMC模式'!M7+'EMC模式'!N7) | R26: 前9年差异主要来自订阅费更高且服务方承担运维；第10年再叠加残值归服务方、甲方无终值
A27: LaaS | B27: 2 | C27: ='假设'!E8 | D27: ='假设'!F8 | E27: ='假设'!G8 | F27: ='假设'!H8 | G27: ='LaaS模式'!H7 | H27: =G27-'EMC模式'!H7 | I27: ='LaaS模式'!K8 | J27: ='LaaS模式'!L8 | K27: ='LaaS模式'!M8 | L27: ='LaaS模式'!N8 | M27: =I27-J27-K27+L27 | N27: =I27-'EMC模式'!K8 | O27: =J27-'EMC模式'!L8 | P27: =L27-'EMC模式'!N8 | Q27: =M27-('EMC模式'!K8-'EMC模式'!L8-'EMC模式'!M8+'EMC模式'!N8) | R27: 前9年差异主要来自订阅费更高且服务方承担运维；第10年再叠加残值归服务方、甲方无终值
A28: LaaS | B28: 3 | C28: ='假设'!E8 | D28: ='假设'!F8 | E28: ='假设'!G8 | F28: ='假设'!H8 | G28: ='LaaS模式'!H8 | H28: =G28-'EMC模式'!H8 | I28: ='LaaS模式'!K9 | J28: ='LaaS模式'!L9 | K28: ='LaaS模式'!M9 | L28: ='LaaS模式'!N9 | M28: =I28-J28-K28+L28 | N28: =I28-'EMC模式'!K9 | O28: =J28-'EMC模式'!L9 | P28: =L28-'EMC模式'!N9 | Q28: =M28-('EMC模式'!K9-'EMC模式'!L9-'EMC模式'!M9+'EMC模式'!N9) | R28: 前9年差异主要来自订阅费更高且服务方承担运维；第10年再叠加残值归服务方、甲方无终值
A29: LaaS | B29: 4 | C29: ='假设'!E8 | D29: ='假设'!F8 | E29: ='假设'!G8 | F29: ='假设'!H8 | G29: ='LaaS模式'!H9 | H29: =G29-'EMC模式'!H9 | I29: ='LaaS模式'!K10 | J29: ='LaaS模式'!L10 | K29: ='LaaS模式'!M10 | L29: ='LaaS模式'!N10 | M29: =I29-J29-K29+L29 | N29: =I29-'EMC模式'!K10 | O29: =J29-'EMC模式'!L10 | P29: =L29-'EMC模式'!N10 | Q29: =M29-('EMC模式'!K10-'EMC模式'!L10-'EMC模式'!M10+'EMC模式'!N10) | R29: 前9年差异主要来自订阅费更高且服务方承担运维；第10年再叠加残值归服务方、甲方无终值
A30: LaaS | B30: 5 | C30: ='假设'!E8 | D30: ='假设'!F8 | E30: ='假设'!G8 | F30: ='假设'!H8 | G30: ='LaaS模式'!H10 | H30: =G30-'EMC模式'!H10 | I30: ='LaaS模式'!K11 | J30: ='LaaS模式'!L11 | K30: ='LaaS模式'!M11 | L30: ='LaaS模式'!N11 | M30: =I30-J30-K30+L30 | N30: =I30-'EMC模式'!K11 | O30: =J30-'EMC模式'!L11 | P30: =L30-'EMC模式'!N11 | Q30: =M30-('EMC模式'!K11-'EMC模式'!L11-'EMC模式'!M11+'EMC模式'!N11) | R30: 前9年差异主要来自订阅费更高且服务方承担运维；第10年再叠加残值归服务方、甲方无终值
A31: LaaS | B31: 6 | C31: ='假设'!E8 | D31: ='假设'!F8 | E31: ='假设'!G8 | F31: ='假设'!H8 | G31: ='LaaS模式'!H11 | H31: =G31-'EMC模式'!H11 | I31: ='LaaS模式'!K12 | J31: ='LaaS模式'!L12 | K31: ='LaaS模式'!M12 | L31: ='LaaS模式'!N12 | M31: =I31-J31-K31+L31 | N31: =I31-'EMC模式'!K12 | O31: =J31-'EMC模式'!L12 | P31: =L31-'EMC模式'!N12 | Q31: =M31-('EMC模式'!K12-'EMC模式'!L12-'EMC模式'!M12+'EMC模式'!N12) | R31: 前9年差异主要来自订阅费更高且服务方承担运维；第10年再叠加残值归服务方、甲方无终值
A32: LaaS | B32: 7 | C32: ='假设'!E8 | D32: ='假设'!F8 | E32: ='假设'!G8 | F32: ='假设'!H8 | G32: ='LaaS模式'!H12 | H32: =G32-'EMC模式'!H12 | I32: ='LaaS模式'!K13 | J32: ='LaaS模式'!L13 | K32: ='LaaS模式'!M13 | L32: ='LaaS模式'!N13 | M32: =I32-J32-K32+L32 | N32: =I32-'EMC模式'!K13 | O32: =J32-'EMC模式'!L13 | P32: =L32-'EMC模式'!N13 | Q32: =M32-('EMC模式'!K13-'EMC模式'!L13-'EMC模式'!M13+'EMC模式'!N13) | R32: 前9年差异主要来自订阅费更高且服务方承担运维；第10年再叠加残值归服务方、甲方无终值
A33: LaaS | B33: 8 | C33: ='假设'!E8 | D33: ='假设'!F8 | E33: ='假设'!G8 | F33: ='假设'!H8 | G33: ='LaaS模式'!H13 | H33: =G33-'EMC模式'!H13 | I33: ='LaaS模式'!K14 | J33: ='LaaS模式'!L14 | K33: ='LaaS模式'!M14 | L33: ='LaaS模式'!N14 | M33: =I33-J33-K33+L33 | N33: =I33-'EMC模式'!K14 | O33: =J33-'EMC模式'!L14 | P33: =L33-'EMC模式'!N14 | Q33: =M33-('EMC模式'!K14-'EMC模式'!L14-'EMC模式'!M14+'EMC模式'!N14) | R33: 前9年差异主要来自订阅费更高且服务方承担运维；第10年再叠加残值归服务方、甲方无终值
A34: LaaS | B34: 9 | C34: ='假设'!E8 | D34: ='假设'!F8 | E34: ='假设'!G8 | F34: ='假设'!H8 | G34: ='LaaS模式'!H14 | H34: =G34-'EMC模式'!H14 | I34: ='LaaS模式'!K15 | J34: ='LaaS模式'!L15 | K34: ='LaaS模式'!M15 | L34: ='LaaS模式'!N15 | M34: =I34-J34-K34+L34 | N34: =I34-'EMC模式'!K15 | O34: =J34-'EMC模式'!L15 | P34: =L34-'EMC模式'!N15 | Q34: =M34-('EMC模式'!K15-'EMC模式'!L15-'EMC模式'!M15+'EMC模式'!N15) | R34: 前9年差异主要来自订阅费更高且服务方承担运维；第10年再叠加残值归服务方、甲方无终值
A35: LaaS | B35: 10 | C35: ='假设'!E8 | D35: ='假设'!F8 | E35: ='假设'!G8 | F35: ='假设'!H8 | G35: ='LaaS模式'!H15 | H35: =G35-'EMC模式'!H15 | I35: ='LaaS模式'!K16 | J35: ='LaaS模式'!L16 | K35: ='LaaS模式'!M16 | L35: ='LaaS模式'!N16 | M35: =I35-J35-K35+L35 | N35: =I35-'EMC模式'!K16 | O35: =J35-'EMC模式'!L16 | P35: =L35-'EMC模式'!N16 | Q35: =M35-('EMC模式'!K16-'EMC模式'!L16-'EMC模式'!M16+'EMC模式'!N16) | R35: 第10年差异最大：LaaS多出服务方残值，同时甲方少了终值，因此服务方与甲方差异同时拉开
A36: 租赁 | B36: 1 | C36: ='假设'!E9 | D36: ='假设'!F9 | E36: ='假设'!G9 | F36: ='假设'!H9 | G36: ='租赁模式'!H6 | H36: =G36-'EMC模式'!H6 | I36: ='租赁模式'!K7 | J36: ='租赁模式'!L7 | K36: ='租赁模式'!M7 | L36: ='租赁模式'!N7 | M36: =I36-J36-K36+L36 | N36: =I36-'EMC模式'!K7 | O36: =J36-'EMC模式'!L7 | P36: =L36-'EMC模式'!N7 | Q36: =M36-('EMC模式'!K7-'EMC模式'!L7-'EMC模式'!M7+'EMC模式'!N7) | R36: 业主仍自付电费和运维；服务方收入与EMC接近，但运维管理成本更低
A37: 租赁 | B37: 2 | C37: ='假设'!E9 | D37: ='假设'!F9 | E37: ='假设'!G9 | F37: ='假设'!H9 | G37: ='租赁模式'!H7 | H37: =G37-'EMC模式'!H7 | I37: ='租赁模式'!K8 | J37: ='租赁模式'!L8 | K37: ='租赁模式'!M8 | L37: ='租赁模式'!N8 | M37: =I37-J37-K37+L37 | N37: =I37-'EMC模式'!K8 | O37: =J37-'EMC模式'!L8 | P37: =L37-'EMC模式'!N8 | Q37: =M37-('EMC模式'!K8-'EMC模式'!L8-'EMC模式'!M8+'EMC模式'!N8) | R37: 业主仍自付电费和运维；服务方收入与EMC接近，但运维管理成本更低
A38: 租赁 | B38: 3 | C38: ='假设'!E9 | D38: ='假设'!F9 | E38: ='假设'!G9 | F38: ='假设'!H9 | G38: ='租赁模式'!H8 | H38: =G38-'EMC模式'!H8 | I38: ='租赁模式'!K9 | J38: ='租赁模式'!L9 | K38: ='租赁模式'!M9 | L38: ='租赁模式'!N9 | M38: =I38-J38-K38+L38 | N38: =I38-'EMC模式'!K9 | O38: =J38-'EMC模式'!L9 | P38: =L38-'EMC模式'!N9 | Q38: =M38-('EMC模式'!K9-'EMC模式'!L9-'EMC模式'!M9+'EMC模式'!N9) | R38: 业主仍自付电费和运维；服务方收入与EMC接近，但运维管理成本更低
A39: 租赁 | B39: 4 | C39: ='假设'!E9 | D39: ='假设'!F9 | E39: ='假设'!G9 | F39: ='假设'!H9 | G39: ='租赁模式'!H9 | H39: =G39-'EMC模式'!H9 | I39: ='租赁模式'!K10 | J39: ='租赁模式'!L10 | K39: ='租赁模式'!M10 | L39: ='租赁模式'!N10 | M39: =I39-J39-K39+L39 | N39: =I39-'EMC模式'!K10 | O39: =J39-'EMC模式'!L10 | P39: =L39-'EMC模式'!N10 | Q39: =M39-('EMC模式'!K10-'EMC模式'!L10-'EMC模式'!M10+'EMC模式'!N10) | R39: 业主仍自付电费和运维；服务方收入与EMC接近，但运维管理成本更低
A40: 租赁 | B40: 5 | C40: ='假设'!E9 | D40: ='假设'!F9 | E40: ='假设'!G9 | F40: ='假设'!H9 | G40: ='租赁模式'!H10 | H40: =G40-'EMC模式'!H10 | I40: ='租赁模式'!K11 | J40: ='租赁模式'!L11 | K40: ='租赁模式'!M11 | L40: ='租赁模式'!N11 | M40: =I40-J40-K40+L40 | N40: =I40-'EMC模式'!K11 | O40: =J40-'EMC模式'!L11 | P40: =L40-'EMC模式'!N11 | Q40: =M40-('EMC模式'!K11-'EMC模式'!L11-'EMC模式'!M11+'EMC模式'!N11) | R40: 业主仍自付电费和运维；服务方收入与EMC接近，但运维管理成本更低
A41: 租赁 | B41: 6 | C41: ='假设'!E9 | D41: ='假设'!F9 | E41: ='假设'!G9 | F41: ='假设'!H9 | G41: ='租赁模式'!H11 | H41: =G41-'EMC模式'!H11 | I41: ='租赁模式'!K12 | J41: ='租赁模式'!L12 | K41: ='租赁模式'!M12 | L41: ='租赁模式'!N12 | M41: =I41-J41-K41+L41 | N41: =I41-'EMC模式'!K12 | O41: =J41-'EMC模式'!L12 | P41: =L41-'EMC模式'!N12 | Q41: =M41-('EMC模式'!K12-'EMC模式'!L12-'EMC模式'!M12+'EMC模式'!N12) | R41: 业主仍自付电费和运维；服务方收入与EMC接近，但运维管理成本更低
A42: 租赁 | B42: 7 | C42: ='假设'!E9 | D42: ='假设'!F9 | E42: ='假设'!G9 | F42: ='假设'!H9 | G42: ='租赁模式'!H12 | H42: =G42-'EMC模式'!H12 | I42: ='租赁模式'!K13 | J42: ='租赁模式'!L13 | K42: ='租赁模式'!M13 | L42: ='租赁模式'!N13 | M42: =I42-J42-K42+L42 | N42: =I42-'EMC模式'!K13 | O42: =J42-'EMC模式'!L13 | P42: =L42-'EMC模式'!N13 | Q42: =M42-('EMC模式'!K13-'EMC模式'!L13-'EMC模式'!M13+'EMC模式'!N13) | R42: 业主仍自付电费和运维；服务方收入与EMC接近，但运维管理成本更低
...
