Workbook

Sheet 00_Value_Drivers
A1: Under equal conditions: where does LaaS value come from?
A2: Decompose incremental value drivers and payback pressure.
A4: Snapshot
A6: Baseline electricity (Y1) | B6: ='Inputs_Data'!C6
A7: Owner annual budget | B7: ='Inputs_Data'!B6
A8: Initial CAPEX | B8: ='Inputs_Data'!H5

Sheet Inputs_Data
A1: Inputs (from /data)
A2: All values are RMB/year unless noted.
A4: Year | B4: Trust_fee | C4: Elec_OPEX | D4: Staff+Other_OPEX | E4: Cash_OPEX | F4: Depreciation | G4: Debt_service | H4: CAPEX_y0
A5: 0 | B5: 0 | C5: 0 | D5: 0 | E5: 0 | F5: 0 | G5: 0 | H5: 3539400
A6: 1 | B6: 2342300 | C6: 1028000 | D6: 610000 | E6: 1638000 | F6: 407780 | G6: 867700 | H6: 0
A7: 2 | B7: 2342300 | C7: 1028000 | D7: 610000 | E7: 1638000 | F7: 407780 | G7: 840400 | H7: 0
A8: 3 | B8: 2342300 | C8: 1028000 | D8: 610000 | E8: 1638000 | F8: 407780 | G8: 813100 | H8: 0
A9: 4 | B9: 2342300 | C9: 1028000 | D9: 610000 | E9: 1638000 | F9: 407780 | G9: 785800 | H9: 0
A10: 5 | B10: 2342300 | C10: 1028000 | D10: 610000 | E10: 1638000 | F10: 407780 | G10: 758500 | H10: 0
A11: 6 | B11: 2342300 | C11: 1028000 | D11: 610000 | E11: 1638000 | F11: 407780 | G11: 731200 | H11: 0
A12: 7 | B12: 2342300 | C12: 1028000 | D12: 610000 | E12: 1638000 | F12: 407780 | G12: 103900 | H12: 0
A13: 8 | B13: 2342300 | C13: 1028000 | D13: 610000 | E13: 1638000 | F13: 407780 | G13: 600600 | H13: 0
A14: 9 | B14: 2342300 | C14: 1028000 | D14: 610000 | E14: 1638000 | F14: 407780 | G14: 0 | H14: 0
A15: 10 | B15: 2342300 | C15: 1028000 | D15: 610000 | E15: 1638000 | F15: 407780 | G15: 0 | H15: 0

Sheet Assumptions
A1: Assumptions (editable)
A2: Highlighted cells drive all outputs via formulas.
A4: OPEX reduction factors (by line item)
A5: Item | B5: Value | C5: Notes | D5: Ref
A6: Electricity OPEX reduction % | B6: 0.4 | C6: Used in electricity_only_pct tier (conservative vs case studies). | D6: Story_and_Sources
A7: Staff OPEX reduction % | B7: 0.35 | C7: Remote monitoring + optimized dispatch; applied to non-electric OPEX. | D7: Story_and_Sources
A8: Vehicles OPEX reduction % | B8: 0.3 | C8: Truck-roll reduction; applied to non-electric OPEX. | D8: Story_and_Sources
A9: Materials OPEX reduction % | B9: 0.15 | C9: Predictive grouping reduces waste; applied to non-electric OPEX. | D9: Story_and_Sources
A10: Management OPEX reduction % | B10: 0.1 | C10: Automation reduces overhead; applied to non-electric OPEX. | D10: Story_and_Sources
A11: Max AI OPEX reduction cap % | B11: 0.85 | C11: Model guardrail: avoid unrealistic improvements; requires evidence for >85%. | D11: Story_and_Sources

Sheet Scenarios_10
A1: 10 win-win tiers
A2: Each tier uses a distinct mechanism; all outputs are formula-driven.
A4: Tier | B4: Term_y | C4: OPEX_mode | D4: Base_fee_RMB | E4: Upfront_RMB | F4: TailDisc_RMB | G4: AI_red_pct | H4: Story
A5: Tier1_UniformAI_20 | B5: 10 | C5: uniform_pct | D5: ='Inputs_Data'!B6*0.95 | E5: 0 | F5: 0 | G5: 0.2 | H5: AI dispatch + predictive maintenance reduces non-electric OPEX
A6: Tier2_UniformAI_35 | B6: 10 | C6: uniform_pct | D6: ='Inputs_Data'!B6*0.97 | E6: 0 | F6: 0 | G6: 0.35 | H6: Higher AI ops maturity; still within cited ranges
A7: Tier3_ElecOnly_40 | B7: 10 | C7: electricity_only_pct | D7: ='Inputs_Data'!B6*0.96 | E7: 0 | F7: 0 | G7: 0.4 | H7: Adaptive dimming/controls reduce electricity cost
A8: Tier4_ElecOnly_60 | B8: 10 | C8: electricity_only_pct | D8: ='Inputs_Data'!B6*0.98 | E8: 0 | F8: 0 | G8: 0.6 | H8: Aggressive controls (case-like), needs stronger acceptance
A9: Tier5_AISolar | B9: 10 | C9: ai_plus_solar | D9: ='Inputs_Data'!B6*1.05 | E9: 0 | F9: 0 | G9: 0 | H9: AI+Solar: electricity OPEX to 0 (engineering/contract assumption)
A10: Tier6_Upfront_Prepay | B10: 10 | C10: uniform_pct | D10: ='Inputs_Data'!B6*1.00 | E10: 1000000 | F10: 0 | G10: 0.25 | H10: Upfront as prepayment reduces annual fee; improves payback
A11: Tier7_TailDiscount | B11: 10 | C11: uniform_pct | D11: ='Inputs_Data'!B6*1.02 | E11: 0 | F11: 250000 | G11: 0.25 | H11: SLA-style tail discount in last 4 years
A12: Tier8_HigherFee_StrongerSLA | B12: 10 | C12: uniform_pct | D12: ='Inputs_Data'!B6*1.08 | E12: 0 | F12: 350000 | G12: 0.3 | H12: Higher fee but more SLA credit; keep client whole
A13: Tier9_MidTerm_8y | B13: 8 | C13: uniform_pct | D13: ='Inputs_Data'!B6*1.00 | E13: 500000 | F13: 0 | G13: 0.3 | H13: Shorter term with upfront to keep 36m payback
A14: Tier10_Conservative | B14: 10 | C14: uniform_pct | D14: ='Inputs_Data'!B6*0.92 | E14: 0 | F14: 0 | G14: 0.1 | H14: Low fee + modest AI improvements (very conservative)

Sheet Model_Calc
A1: Model (formula-driven)
A2: Each scenario computed via formulas from Inputs_Data + Assumptions.
A4: Scenario summary metrics (computed)
A5: Tier | B5: ClientPay_Y1 | C5: BaselinePay_Y1 | D5: ClientSavings_Y1 | E5: LaaS_CashOPEX_Y1 | F5: Baseline_CashOPEX_Y1 | G5: ProviderGP_Uplift_Y1 | H5: Payback_months(approx) | I5: WinWin?
A6: ='Scenarios_10'!A5 | B6: =MAX(0,'Scenarios_10'!D5-'Scenarios_10'!E5/'Scenarios_10'!B5) | C6: ='Inputs_Data'!B6 | D6: =('Inputs_Data'!B6-(MAX(0,'Scenarios_10'!D5-'Scenarios_10'!E5/'Scenarios_10'!B5))) | E6: =IF('Scenarios_10'!C5="uniform_pct",'Inputs_Data'!E6*(1-MIN('Scenarios_10'!G5,'Assumptions'!B10)),IF('Scenarios_10'!C5="electricity_only_pct",('Inputs_Data'!C6*(1-MIN('Scenarios_10'!G5,'Assumptions'!B10)))+'Inputs_Data'!D6,0+('Inputs_Data'!D6*(1-AVERAGE('Assumptions'!B6,'Assumptions'!B7,'Assumptions'!B8,'Assumptions'!B9))))) | F6: ='Inputs_Data'!E6 | G6: =((MAX(0,'Scenarios_10'!D5-'Scenarios_10'!E5/'Scenarios_10'!B5)-(IF('Scenarios_10'!C5="uniform_pct",'Inputs_Data'!E6*(1-MIN('Scenarios_10'!G5,'Assumptions'!B10)),IF('Scenarios_10'!C5="electricity_only_pct",('Inputs_Data'!C6*(1-MIN('Scenarios_10'!G5,'Assumptions'!B10)))+'Inputs_Data'!D6,0+('Inputs_Data'!D6*(1-AVERAGE('Assumptions'!B6,'Assumptions'!B7,'Assumptions'!B8,'Assumptions'!B9)))))+'Inputs_Data'!F6))-('Inputs_Data'!B6-('Inputs_Data'!E6+'Inputs_Data'!F6))) | H6: =IF((MAX(0,'Scenarios_10'!D5-'Scenarios_10'!E5/'Scenarios_10'!B5)-(IF('Scenarios_10'!C5="uniform_pct",'Inputs_Data'!E6*(1-MIN('Scenarios_10'!G5,'Assumptions'!B10)),IF('Scenarios_10'!C5="electricity_only_pct",('Inputs_Data'!C6*(1-MIN('Scenarios_10'!G5,'Assumptions'!B10)))+'Inputs_Data'!D6,0+('Inputs_Data'!D6*(1-AVERAGE('Assumptions'!B6,'Assumptions'!B7,'Assumptions'!B8,'Assumptions'!B9)))))))<=0,999,ROUNDUP('Inputs_Data'!H5/((MAX(0,'Scenarios_10'!D5-'Scenarios_10'!E5/'Scenarios_10'!B5)-(IF('Scenarios_10'!C5="uniform_pct",'Inputs_Data'!E6*(1-MIN('Scenarios_10'!G5,'Assumptions'!B10)),IF('Scenarios_10'!C5="electricity_only_pct",('Inputs_Data'!C6*(1-MIN('Scenarios_10'!G5,'Assumptions'!B10)))+'Inputs_Data'!D6,0+('Inputs_Data'!D6*(1-AVERAGE('Assumptions'!B6,'Assumptions'!B7,'Assumptions'!B8,'Assumptions'!B9)))))))/12),0)) | I6: =AND(MAX(0,'Scenarios_10'!D5-'Scenarios_10'!E5/'Scenarios_10'!B5)<='Inputs_Data'!B6,((MAX(0,'Scenarios_10'!D5-'Scenarios_10'!E5/'Scenarios_10'!B5)-(IF('Scenarios_10'!C5="uniform_pct",'Inputs_Data'!E6*(1-MIN('Scenarios_10'!G5,'Assumptions'!B10)),IF('Scenarios_10'!C5="electricity_only_pct",('Inputs_Data'!C6*(1-MIN('Scenarios_10'!G5,'Assumptions'!B10)))+'Inputs_Data'!D6,0+('Inputs_Data'!D6*(1-AVERAGE('Assumptions'!B6,'Assumptions'!B7,'Assumptions'!B8,'Assumptions'!B9)))))+'Inputs_Data'!F6))-('Inputs_Data'!B6-('Inputs_Data'!E6+'Inputs_Data'!F6)))>=0,IF((MAX(0,'Scenarios_10'!D5-'Scenarios_10'!E5/'Scenarios_10'!B5)-(IF('Scenarios_10'!C5="uniform_pct",'Inputs_Data'!E6*(1-MIN('Scenarios_10'!G5,'Assumptions'!B10)),IF('Scenarios_10'!C5="electricity_only_pct",('Inputs_Data'!C6*(1-MIN('Scenarios_10'!G5,'Assumptions'!B10)))+'Inputs_Data'!D6,0+('Inputs_Data'!D6*(1-AVERAGE('Assumptions'!B6,'Assumptions'!B7,'Assumptions'!B8,'Assumptions'!B9)))))))<=0,999,ROUNDUP('Inputs_Data'!H5/((MAX(0,'Scenarios_10'!D5-'Scenarios_10'!E5/'Scenarios_10'!B5)-(IF('Scenarios_10'!C5="uniform_pct",'Inputs_Data'!E6*(1-MIN('Scenarios_10'!G5,'Assumptions'!B10)),IF('Scenarios_10'!C5="electricity_only_pct",('Inputs_Data'!C6*(1-MIN('Scenarios_10'!G5,'Assumptions'!B10)))+'Inputs_Data'!D6,0+('Inputs_Data'!D6*(1-AVERAGE('Assumptions'!B6,'Assumptions'!B7,'Assumptions'!B8,'Assumptions'!B9)))))))/12),0))<=36)
A7: ='Scenarios_10'!A6 | B7: =MAX(0,'Scenarios_10'!D6-'Scenarios_10'!E6/'Scenarios_10'!B6) | C7: ='Inputs_Data'!B6 | D7: =('Inputs_Data'!B6-(MAX(0,'Scenarios_10'!D6-'Scenarios_10'!E6/'Scenarios_10'!B6))) | E7: =IF('Scenarios_10'!C6="uniform_pct",'Inputs_Data'!E6*(1-MIN('Scenarios_10'!G6,'Assumptions'!B10)),IF('Scenarios_10'!C6="electricity_only_pct",('Inputs_Data'!C6*(1-MIN('Scenarios_10'!G6,'Assumptions'!B10)))+'Inputs_Data'!D6,0+('Inputs_Data'!D6*(1-AVERAGE('Assumptions'!B6,'Assumptions'!B7,'Assumptions'!B8,'Assumptions'!B9))))) | F7: ='Inputs_Data'!E6 | G7: =((MAX(0,'Scenarios_10'!D6-'Scenarios_10'!E6/'Scenarios_10'!B6)-(IF('Scenarios_10'!C6="uniform_pct",'Inputs_Data'!E6*(1-MIN('Scenarios_10'!G6,'Assumptions'!B10)),IF('Scenarios_10'!C6="electricity_only_pct",('Inputs_Data'!C6*(1-MIN('Scenarios_10'!G6,'Assumptions'!B10)))+'Inputs_Data'!D6,0+('Inputs_Data'!D6*(1-AVERAGE('Assumptions'!B6,'Assumptions'!B7,'Assumptions'!B8,'Assumptions'!B9)))))+'Inputs_Data'!F6))-('Inputs_Data'!B6-('Inputs_Data'!E6+'Inputs_Data'!F6))) | H7: =IF((MAX(0,'Scenarios_10'!D6-'Scenarios_10'!E6/'Scenarios_10'!B6)-(IF('Scenarios_10'!C6="uniform_pct",'Inputs_Data'!E6*(1-MIN('Scenarios_10'!G6,'Assumptions'!B10)),IF('Scenarios_10'!C6="electricity_only_pct",('Inputs_Data'!C6*(1-MIN('Scenarios_10'!G6,'Assumptions'!B10)))+'Inputs_Data'!D6,0+('Inputs_Data'!D6*(1-AVERAGE('Assumptions'!B6,'Assumptions'!B7,'Assumptions'!B8,'Assumptions'!B9)))))))<=0,999,ROUNDUP('Inputs_Data'!H5/((MAX(0,'Scenarios_10'!D6-'Scenarios_10'!E6/'Scenarios_10'!B6)-(IF('Scenarios_10'!C6="uniform_pct",'Inputs_Data'!E6*(1-MIN('Scenarios_10'!G6,'Assumptions'!B10)),IF('Scenarios_10'!C6="electricity_only_pct",('Inputs_Data'!C6*(1-MIN('Scenarios_10'!G6,'Assumptions'!B10)))+'Inputs_Data'!D6,0+('Inputs_Data'!D6*(1-AVERAGE('Assumptions'!B6,'Assumptions'!B7,'Assumptions'!B8,'Assumptions'!B9)))))))/12),0)) | I7: =AND(MAX(0,'Scenarios_10'!D6-'Scenarios_10'!E6/'Scenarios_10'!B6)<='Inputs_Data'!B6,((MAX(0,'Scenarios_10'!D6-'Scenarios_10'!E6/'Scenarios_10'!B6)-(IF('Scenarios_10'!C6="uniform_pct",'Inputs_Data'!E6*(1-MIN('Scenarios_10'!G6,'Assumptions'!B10)),IF('Scenarios_10'!C6="electricity_only_pct",('Inputs_Data'!C6*(1-MIN('Scenarios_10'!G6,'Assumptions'!B10)))+'Inputs_Data'!D6,0+('Inputs_Data'!D6*(1-AVERAGE('Assumptions'!B6,'Assumptions'!B7,'Assumptions'!B8,'Assumptions'!B9)))))+'Inputs_Data'!F6))-('Inputs_Data'!B6-('Inputs_Data'!E6+'Inputs_Data'!F6)))>=0,IF((MAX(0,'Scenarios_10'!D6-'Scenarios_10'!E6/'Scenarios_10'!B6)-(IF('Scenarios_10'!C6="uniform_pct",'Inputs_Data'!E6*(1-MIN('Scenarios_10'!G6,'Assumptions'!B10)),IF('Scenarios_10'!C6="electricity_only_pct",('Inputs_Data'!C6*(1-MIN('Scenarios_10'!G6,'Assumptions'!B10)))+'Inputs_Data'!D6,0+('Inputs_Data'!D6*(1-AVERAGE('Assumptions'!B6,'Assumptions'!B7,'Assumptions'!B8,'Assumptions'!B9)))))))<=0,999,ROUNDUP('Inputs_Data'!H5/((MAX(0,'Scenarios_10'!D6-'Scenarios_10'!E6/'Scenarios_10'!B6)-(IF('Scenarios_10'!C6="uniform_pct",'Inputs_Data'!E6*(1-MIN('Scenarios_10'!G6,'Assumptions'!B10)),IF('Scenarios_10'!C6="electricity_only_pct",('Inputs_Data'!C6*(1-MIN('Scenarios_10'!G6,'Assumptions'!B10)))+'Inputs_Data'!D6,0+('Inputs_Data'!D6*(1-AVERAGE('Assumptions'!B6,'Assumptions'!B7,'Assumptions'!B8,'Assumptions'!B9)))))))/12),0))<=36)
A8: ='Scenarios_10'!A7 | B8: =MAX(0,'Scenarios_10'!D7-'Scenarios_10'!E7/'Scenarios_10'!B7) | C8: ='Inputs_Data'!B6 | D8: =('Inputs_Data'!B6-(MAX(0,'Scenarios_10'!D7-'Scenarios_10'!E7/'Scenarios_10'!B7))) | E8: =IF('Scenarios_10'!C7="uniform_pct",'Inputs_Data'!E6*(1-MIN('Scenarios_10'!G7,'Assumptions'!B10)),IF('Scenarios_10'!C7="electricity_only_pct",('Inputs_Data'!C6*(1-MIN('Scenarios_10'!G7,'Assumptions'!B10)))+'Inputs_Data'!D6,0+('Inputs_Data'!D6*(1-AVERAGE('Assumptions'!B6,'Assumptions'!B7,'Assumptions'!B8,'Assumptions'!B9))))) | F8: ='Inputs_Data'!E6 | G8: =((MAX(0,'Scenarios_10'!D7-'Scenarios_10'!E7/'Scenarios_10'!B7)-(IF('Scenarios_10'!C7="uniform_pct",'Inputs_Data'!E6*(1-MIN('Scenarios_10'!G7,'Assumptions'!B10)),IF('Scenarios_10'!C7="electricity_only_pct",('Inputs_Data'!C6*(1-MIN('Scenarios_10'!G7,'Assumptions'!B10)))+'Inputs_Data'!D6,0+('Inputs_Data'!D6*(1-AVERAGE('Assumptions'!B6,'Assumptions'!B7,'Assumptions'!B8,'Assumptions'!B9)))))+'Inputs_Data'!F6))-('Inputs_Data'!B6-('Inputs_Data'!E6+'Inputs_Data'!F6))) | H8: =IF((MAX(0,'Scenarios_10'!D7-'Scenarios_10'!E7/'Scenarios_10'!B7)-(IF('Scenarios_10'!C7="uniform_pct",'Inputs_Data'!E6*(1-MIN('Scenarios_10'!G7,'Assumptions'!B10)),IF('Scenarios_10'!C7="electricity_only_pct",('Inputs_Data'!C6*(1-MIN('Scenarios_10'!G7,'Assumptions'!B10)))+'Inputs_Data'!D6,0+('Inputs_Data'!D6*(1-AVERAGE('Assumptions'!B6,'Assumptions'!B7,'Assumptions'!B8,'Assumptions'!B9)))))))<=0,999,ROUNDUP('Inputs_Data'!H5/((MAX(0,'Scenarios_10'!D7-'Scenarios_10'!E7/'Scenarios_10'!B7)-(IF('Scenarios_10'!C7="uniform_pct",'Inputs_Data'!E6*(1-MIN('Scenarios_10'!G7,'Assumptions'!B10)),IF('Scenarios_10'!C7="electricity_only_pct",('Inputs_Data'!C6*(1-MIN('Scenarios_10'!G7,'Assumptions'!B10)))+'Inputs_Data'!D6,0+('Inputs_Data'!D6*(1-AVERAGE('Assumptions'!B6,'Assumptions'!B7,'Assumptions'!B8,'Assumptions'!B9)))))))/12),0)) | I8: =AND(MAX(0,'Scenarios_10'!D7-'Scenarios_10'!E7/'Scenarios_10'!B7)<='Inputs_Data'!B6,((MAX(0,'Scenarios_10'!D7-'Scenarios_10'!E7/'Scenarios_10'!B7)-(IF('Scenarios_10'!C7="uniform_pct",'Inputs_Data'!E6*(1-MIN('Scenarios_10'!G7,'Assumptions'!B10)),IF('Scenarios_10'!C7="electricity_only_pct",('Inputs_Data'!C6*(1-MIN('Scenarios_10'!G7,'Assumptions'!B10)))+'Inputs_Data'!D6,0+('Inputs_Data'!D6*(1-AVERAGE('Assumptions'!B6,'Assumptions'!B7,'Assumptions'!B8,'Assumptions'!B9)))))+'Inputs_Data'!F6))-('Inputs_Data'!B6-('Inputs_Data'!E6+'Inputs_Data'!F6)))>=0,IF((MAX(0,'Scenarios_10'!D7-'Scenarios_10'!E7/'Scenarios_10'!B7)-(IF('Scenarios_10'!C7="uniform_pct",'Inputs_Data'!E6*(1-MIN('Scenarios_10'!G7,'Assumptions'!B10)),IF('Scenarios_10'!C7="electricity_only_pct",('Inputs_Data'!C6*(1-MIN('Scenarios_10'!G7,'Assumptions'!B10)))+'Inputs_Data'!D6,0+('Inputs_Data'!D6*(1-AVERAGE('Assumptions'!B6,'Assumptions'!B7,'Assumptions'!B8,'Assumptions'!B9)))))))<=0,999,ROUNDUP('Inputs_Data'!H5/((MAX(0,'Scenarios_10'!D7-'Scenarios_10'!E7/'Scenarios_10'!B7)-(IF('Scenarios_10'!C7="uniform_pct",'Inputs_Data'!E6*(1-MIN('Scenarios_10'!G7,'Assumptions'!B10)),IF('Scenarios_10'!C7="electricity_only_pct",('Inputs_Data'!C6*(1-MIN('Scenarios_10'!G7,'Assumptions'!B10)))+'Inputs_Data'!D6,0+('Inputs_Data'!D6*(1-AVERAGE('Assumptions'!B6,'Assumptions'!B7,'Assumptions'!B8,'Assumptions'!B9)))))))/12),0))<=36)
A9: ='Scenarios_10'!A8 | B9: =MAX(0,'Scenarios_10'!D8-'Scenarios_10'!E8/'Scenarios_10'!B8) | C9: ='Inputs_Data'!B6 | D9: =('Inputs_Data'!B6-(MAX(0,'Scenarios_10'!D8-'Scenarios_10'!E8/'Scenarios_10'!B8))) | E9: =IF('Scenarios_10'!C8="uniform_pct",'Inputs_Data'!E6*(1-MIN('Scenarios_10'!G8,'Assumptions'!B10)),IF('Scenarios_10'!C8="electricity_only_pct",('Inputs_Data'!C6*(1-MIN('Scenarios_10'!G8,'Assumptions'!B10)))+'Inputs_Data'!D6,0+('Inputs_Data'!D6*(1-AVERAGE('Assumptions'!B6,'Assumptions'!B7,'Assumptions'!B8,'Assumptions'!B9))))) | F9: ='Inputs_Data'!E6 | G9: =((MAX(0,'Scenarios_10'!D8-'Scenarios_10'!E8/'Scenarios_10'!B8)-(IF('Scenarios_10'!C8="uniform_pct",'Inputs_Data'!E6*(1-MIN('Scenarios_10'!G8,'Assumptions'!B10)),IF('Scenarios_10'!C8="electricity_only_pct",('Inputs_Data'!C6*(1-MIN('Scenarios_10'!G8,'Assumptions'!B10)))+'Inputs_Data'!D6,0+('Inputs_Data'!D6*(1-AVERAGE('Assumptions'!B6,'Assumptions'!B7,'Assumptions'!B8,'Assumptions'!B9)))))+'Inputs_Data'!F6))-('Inputs_Data'!B6-('Inputs_Data'!E6+'Inputs_Data'!F6))) | H9: =IF((MAX(0,'Scenarios_10'!D8-'Scenarios_10'!E8/'Scenarios_10'!B8)-(IF('Scenarios_10'!C8="uniform_pct",'Inputs_Data'!E6*(1-MIN('Scenarios_10'!G8,'Assumptions'!B10)),IF('Scenarios_10'!C8="electricity_only_pct",('Inputs_Data'!C6*(1-MIN('Scenarios_10'!G8,'Assumptions'!B10)))+'Inputs_Data'!D6,0+('Inputs_Data'!D6*(1-AVERAGE('Assumptions'!B6,'Assumptions'!B7,'Assumptions'!B8,'Assumptions'!B9)))))))<=0,999,ROUNDUP('Inputs_Data'!H5/((MAX(0,'Scenarios_10'!D8-'Scenarios_10'!E8/'Scenarios_10'!B8)-(IF('Scenarios_10'!C8="uniform_pct",'Inputs_Data'!E6*(1-MIN('Scenarios_10'!G8,'Assumptions'!B10)),IF('Scenarios_10'!C8="electricity_only_pct",('Inputs_Data'!C6*(1-MIN('Scenarios_10'!G8,'Assumptions'!B10)))+'Inputs_Data'!D6,0+('Inputs_Data'!D6*(1-AVERAGE('Assumptions'!B6,'Assumptions'!B7,'Assumptions'!B8,'Assumptions'!B9)))))))/12),0)) | I9: =AND(MAX(0,'Scenarios_10'!D8-'Scenarios_10'!E8/'Scenarios_10'!B8)<='Inputs_Data'!B6,((MAX(0,'Scenarios_10'!D8-'Scenarios_10'!E8/'Scenarios_10'!B8)-(IF('Scenarios_10'!C8="uniform_pct",'Inputs_Data'!E6*(1-MIN('Scenarios_10'!G8,'Assumptions'!B10)),IF('Scenarios_10'!C8="electricity_only_pct",('Inputs_Data'!C6*(1-MIN('Scenarios_10'!G8,'Assumptions'!B10)))+'Inputs_Data'!D6,0+('Inputs_Data'!D6*(1-AVERAGE('Assumptions'!B6,'Assumptions'!B7,'Assumptions'!B8,'Assumptions'!B9)))))+'Inputs_Data'!F6))-('Inputs_Data'!B6-('Inputs_Data'!E6+'Inputs_Data'!F6)))>=0,IF((MAX(0,'Scenarios_10'!D8-'Scenarios_10'!E8/'Scenarios_10'!B8)-(IF('Scenarios_10'!C8="uniform_pct",'Inputs_Data'!E6*(1-MIN('Scenarios_10'!G8,'Assumptions'!B10)),IF('Scenarios_10'!C8="electricity_only_pct",('Inputs_Data'!C6*(1-MIN('Scenarios_10'!G8,'Assumptions'!B10)))+'Inputs_Data'!D6,0+('Inputs_Data'!D6*(1-AVERAGE('Assumptions'!B6,'Assumptions'!B7,'Assumptions'!B8,'Assumptions'!B9)))))))<=0,999,ROUNDUP('Inputs_Data'!H5/((MAX(0,'Scenarios_10'!D8-'Scenarios_10'!E8/'Scenarios_10'!B8)-(IF('Scenarios_10'!C8="uniform_pct",'Inputs_Data'!E6*(1-MIN('Scenarios_10'!G8,'Assumptions'!B10)),IF('Scenarios_10'!C8="electricity_only_pct",('Inputs_Data'!C6*(1-MIN('Scenarios_10'!G8,'Assumptions'!B10)))+'Inputs_Data'!D6,0+('Inputs_Data'!D6*(1-AVERAGE('Assumptions'!B6,'Assumptions'!B7,'Assumptions'!B8,'Assumptions'!B9)))))))/12),0))<=36)
A10: ='Scenarios_10'!A9 | B10: =MAX(0,'Scenarios_10'!D9-'Scenarios_10'!E9/'Scenarios_10'!B9) | C10: ='Inputs_Data'!B6 | D10: =('Inputs_Data'!B6-(MAX(0,'Scenarios_10'!D9-'Scenarios_10'!E9/'Scenarios_10'!B9))) | E10: =IF('Scenarios_10'!C9="uniform_pct",'Inputs_Data'!E6*(1-MIN('Scenarios_10'!G9,'Assumptions'!B10)),IF('Scenarios_10'!C9="electricity_only_pct",('Inputs_Data'!C6*(1-MIN('Scenarios_10'!G9,'Assumptions'!B10)))+'Inputs_Data'!D6,0+('Inputs_Data'!D6*(1-AVERAGE('Assumptions'!B6,'Assumptions'!B7,'Assumptions'!B8,'Assumptions'!B9))))) | F10: ='Inputs_Data'!E6 | G10: =((MAX(0,'Scenarios_10'!D9-'Scenarios_10'!E9/'Scenarios_10'!B9)-(IF('Scenarios_10'!C9="uniform_pct",'Inputs_Data'!E6*(1-MIN('Scenarios_10'!G9,'Assumptions'!B10)),IF('Scenarios_10'!C9="electricity_only_pct",('Inputs_Data'!C6*(1-MIN('Scenarios_10'!G9,'Assumptions'!B10)))+'Inputs_Data'!D6,0+('Inputs_Data'!D6*(1-AVERAGE('Assumptions'!B6,'Assumptions'!B7,'Assumptions'!B8,'Assumptions'!B9)))))+'Inputs_Data'!F6))-('Inputs_Data'!B6-('Inputs_Data'!E6+'Inputs_Data'!F6))) | H10: =IF((MAX(0,'Scenarios_10'!D9-'Scenarios_10'!E9/'Scenarios_10'!B9)-(IF('Scenarios_10'!C9="uniform_pct",'Inputs_Data'!E6*(1-MIN('Scenarios_10'!G9,'Assumptions'!B10)),IF('Scenarios_10'!C9="electricity_only_pct",('Inputs_Data'!C6*(1-MIN('Scenarios_10'!G9,'Assumptions'!B10)))+'Inputs_Data'!D6,0+('Inputs_Data'!D6*(1-AVERAGE('Assumptions'!B6,'Assumptions'!B7,'Assumptions'!B8,'Assumptions'!B9)))))))<=0,999,ROUNDUP('Inputs_Data'!H5/((MAX(0,'Scenarios_10'!D9-'Scenarios_10'!E9/'Scenarios_10'!B9)-(IF('Scenarios_10'!C9="uniform_pct",'Inputs_Data'!E6*(1-MIN('Scenarios_10'!G9,'Assumptions'!B10)),IF('Scenarios_10'!C9="electricity_only_pct",('Inputs_Data'!C6*(1-MIN('Scenarios_10'!G9,'Assumptions'!B10)))+'Inputs_Data'!D6,0+('Inputs_Data'!D6*(1-AVERAGE('Assumptions'!B6,'Assumptions'!B7,'Assumptions'!B8,'Assumptions'!B9)))))))/12),0)) | I10: =AND(MAX(0,'Scenarios_10'!D9-'Scenarios_10'!E9/'Scenarios_10'!B9)<='Inputs_Data'!B6,((MAX(0,'Scenarios_10'!D9-'Scenarios_10'!E9/'Scenarios_10'!B9)-(IF('Scenarios_10'!C9="uniform_pct",'Inputs_Data'!E6*(1-MIN('Scenarios_10'!G9,'Assumptions'!B10)),IF('Scenarios_10'!C9="electricity_only_pct",('Inputs_Data'!C6*(1-MIN('Scenarios_10'!G9,'Assumptions'!B10)))+'Inputs_Data'!D6,0+('Inputs_Data'!D6*(1-AVERAGE('Assumptions'!B6,'Assumptions'!B7,'Assumptions'!B8,'Assumptions'!B9)))))+'Inputs_Data'!F6))-('Inputs_Data'!B6-('Inputs_Data'!E6+'Inputs_Data'!F6)))>=0,IF((MAX(0,'Scenarios_10'!D9-'Scenarios_10'!E9/'Scenarios_10'!B9)-(IF('Scenarios_10'!C9="uniform_pct",'Inputs_Data'!E6*(1-MIN('Scenarios_10'!G9,'Assumptions'!B10)),IF('Scenarios_10'!C9="electricity_only_pct",('Inputs_Data'!C6*(1-MIN('Scenarios_10'!G9,'Assumptions'!B10)))+'Inputs_Data'!D6,0+('Inputs_Data'!D6*(1-AVERAGE('Assumptions'!B6,'Assumptions'!B7,'Assumptions'!B8,'Assumptions'!B9)))))))<=0,999,ROUNDUP('Inputs_Data'!H5/((MAX(0,'Scenarios_10'!D9-'Scenarios_10'!E9/'Scenarios_10'!B9)-(IF('Scenarios_10'!C9="uniform_pct",'Inputs_Data'!E6*(1-MIN('Scenarios_10'!G9,'Assumptions'!B10)),IF('Scenarios_10'!C9="electricity_only_pct",('Inputs_Data'!C6*(1-MIN('Scenarios_10'!G9,'Assumptions'!B10)))+'Inputs_Data'!D6,0+('Inputs_Data'!D6*(1-AVERAGE('Assumptions'!B6,'Assumptions'!B7,'Assumptions'!B8,'Assumptions'!B9)))))))/12),0))<=36)
A11: ='Scenarios_10'!A10 | B11: =MAX(0,'Scenarios_10'!D10-'Scenarios_10'!E10/'Scenarios_10'!B10) | C11: ='Inputs_Data'!B6 | D11: =('Inputs_Data'!B6-(MAX(0,'Scenarios_10'!D10-'Scenarios_10'!E10/'Scenarios_10'!B10))) | E11: =IF('Scenarios_10'!C10="uniform_pct",'Inputs_Data'!E6*(1-MIN('Scenarios_10'!G10,'Assumptions'!B10)),IF('Scenarios_10'!C10="electricity_only_pct",('Inputs_Data'!C6*(1-MIN('Scenarios_10'!G10,'Assumptions'!B10)))+'Inputs_Data'!D6,0+('Inputs_Data'!D6*(1-AVERAGE('Assumptions'!B6,'Assumptions'!B7,'Assumptions'!B8,'Assumptions'!B9))))) | F11: ='Inputs_Data'!E6 | G11: =((MAX(0,'Scenarios_10'!D10-'Scenarios_10'!E10/'Scenarios_10'!B10)-(IF('Scenarios_10'!C10="uniform_pct",'Inputs_Data'!E6*(1-MIN('Scenarios_10'!G10,'Assumptions'!B10)),IF('Scenarios_10'!C10="electricity_only_pct",('Inputs_Data'!C6*(1-MIN('Scenarios_10'!G10,'Assumptions'!B10)))+'Inputs_Data'!D6,0+('Inputs_Data'!D6*(1-AVERAGE('Assumptions'!B6,'Assumptions'!B7,'Assumptions'!B8,'Assumptions'!B9)))))+'Inputs_Data'!F6))-('Inputs_Data'!B6-('Inputs_Data'!E6+'Inputs_Data'!F6))) | H11: =IF((MAX(0,'Scenarios_10'!D10-'Scenarios_10'!E10/'Scenarios_10'!B10)-(IF('Scenarios_10'!C10="uniform_pct",'Inputs_Data'!E6*(1-MIN('Scenarios_10'!G10,'Assumptions'!B10)),IF('Scenarios_10'!C10="electricity_only_pct",('Inputs_Data'!C6*(1-MIN('Scenarios_10'!G10,'Assumptions'!B10)))+'Inputs_Data'!D6,0+('Inputs_Data'!D6*(1-AVERAGE('Assumptions'!B6,'Assumptions'!B7,'Assumptions'!B8,'Assumptions'!B9)))))))<=0,999,ROUNDUP('Inputs_Data'!H5/((MAX(0,'Scenarios_10'!D10-'Scenarios_10'!E10/'Scenarios_10'!B10)-(IF('Scenarios_10'!C10="uniform_pct",'Inputs_Data'!E6*(1-MIN('Scenarios_10'!G10,'Assumptions'!B10)),IF('Scenarios_10'!C10="electricity_only_pct",('Inputs_Data'!C6*(1-MIN('Scenarios_10'!G10,'Assumptions'!B10)))+'Inputs_Data'!D6,0+('Inputs_Data'!D6*(1-AVERAGE('Assumptions'!B6,'Assumptions'!B7,'Assumptions'!B8,'Assumptions'!B9)))))))/12),0)) | I11: =AND(MAX(0,'Scenarios_10'!D10-'Scenarios_10'!E10/'Scenarios_10'!B10)<='Inputs_Data'!B6,((MAX(0,'Scenarios_10'!D10-'Scenarios_10'!E10/'Scenarios_10'!B10)-(IF('Scenarios_10'!C10="uniform_pct",'Inputs_Data'!E6*(1-MIN('Scenarios_10'!G10,'Assumptions'!B10)),IF('Scenarios_10'!C10="electricity_only_pct",('Inputs_Data'!C6*(1-MIN('Scenarios_10'!G10,'Assumptions'!B10)))+'Inputs_Data'!D6,0+('Inputs_Data'!D6*(1-AVERAGE('Assumptions'!B6,'Assumptions'!B7,'Assumptions'!B8,'Assumptions'!B9)))))+'Inputs_Data'!F6))-('Inputs_Data'!B6-('Inputs_Data'!E6+'Inputs_Data'!F6)))>=0,IF((MAX(0,'Scenarios_10'!D10-'Scenarios_10'!E10/'Scenarios_10'!B10)-(IF('Scenarios_10'!C10="uniform_pct",'Inputs_Data'!E6*(1-MIN('Scenarios_10'!G10,'Assumptions'!B10)),IF('Scenarios_10'!C10="electricity_only_pct",('Inputs_Data'!C6*(1-MIN('Scenarios_10'!G10,'Assumptions'!B10)))+'Inputs_Data'!D6,0+('Inputs_Data'!D6*(1-AVERAGE('Assumptions'!B6,'Assumptions'!B7,'Assumptions'!B8,'Assumptions'!B9)))))))<=0,999,ROUNDUP('Inputs_Data'!H5/((MAX(0,'Scenarios_10'!D10-'Scenarios_10'!E10/'Scenarios_10'!B10)-(IF('Scenarios_10'!C10="uniform_pct",'Inputs_Data'!E6*(1-MIN('Scenarios_10'!G10,'Assumptions'!B10)),IF('Scenarios_10'!C10="electricity_only_pct",('Inputs_Data'!C6*(1-MIN('Scenarios_10'!G10,'Assumptions'!B10)))+'Inputs_Data'!D6,0+('Inputs_Data'!D6*(1-AVERAGE('Assumptions'!B6,'Assumptions'!B7,'Assumptions'!B8,'Assumptions'!B9)))))))/12),0))<=36)
A12: ='Scenarios_10'!A11 | B12: =MAX(0,'Scenarios_10'!D11-'Scenarios_10'!E11/'Scenarios_10'!B11) | C12: ='Inputs_Data'!B6 | D12: =('Inputs_Data'!B6-(MAX(0,'Scenarios_10'!D11-'Scenarios_10'!E11/'Scenarios_10'!B11))) | E12: =IF('Scenarios_10'!C11="uniform_pct",'Inputs_Data'!E6*(1-MIN('Scenarios_10'!G11,'Assumptions'!B10)),IF('Scenarios_10'!C11="electricity_only_pct",('Inputs_Data'!C6*(1-MIN('Scenarios_10'!G11,'Assumptions'!B10)))+'Inputs_Data'!D6,0+('Inputs_Data'!D6*(1-AVERAGE('Assumptions'!B6,'Assumptions'!B7,'Assumptions'!B8,'Assumptions'!B9))))) | F12: ='Inputs_Data'!E6 | G12: =((MAX(0,'Scenarios_10'!D11-'Scenarios_10'!E11/'Scenarios_10'!B11)-(IF('Scenarios_10'!C11="uniform_pct",'Inputs_Data'!E6*(1-MIN('Scenarios_10'!G11,'Assumptions'!B10)),IF('Scenarios_10'!C11="electricity_only_pct",('Inputs_Data'!C6*(1-MIN('Scenarios_10'!G11,'Assumptions'!B10)))+'Inputs_Data'!D6,0+('Inputs_Data'!D6*(1-AVERAGE('Assumptions'!B6,'Assumptions'!B7,'Assumptions'!B8,'Assumptions'!B9)))))+'Inputs_Data'!F6))-('Inputs_Data'!B6-('Inputs_Data'!E6+'Inputs_Data'!F6))) | H12: =IF((MAX(0,'Scenarios_10'!D11-'Scenarios_10'!E11/'Scenarios_10'!B11)-(IF('Scenarios_10'!C11="uniform_pct",'Inputs_Data'!E6*(1-MIN('Scenarios_10'!G11,'Assumptions'!B10)),IF('Scenarios_10'!C11="electricity_only_pct",('Inputs_Data'!C6*(1-MIN('Scenarios_10'!G11,'Assumptions'!B10)))+'Inputs_Data'!D6,0+('Inputs_Data'!D6*(1-AVERAGE('Assumptions'!B6,'Assumptions'!B7,'Assumptions'!B8,'Assumptions'!B9)))))))<=0,999,ROUNDUP('Inputs_Data'!H5/((MAX(0,'Scenarios_10'!D11-'Scenarios_10'!E11/'Scenarios_10'!B11)-(IF('Scenarios_10'!C11="uniform_pct",'Inputs_Data'!E6*(1-MIN('Scenarios_10'!G11,'Assumptions'!B10)),IF('Scenarios_10'!C11="electricity_only_pct",('Inputs_Data'!C6*(1-MIN('Scenarios_10'!G11,'Assumptions'!B10)))+'Inputs_Data'!D6,0+('Inputs_Data'!D6*(1-AVERAGE('Assumptions'!B6,'Assumptions'!B7,'Assumptions'!B8,'Assumptions'!B9)))))))/12),0)) | I12: =AND(MAX(0,'Scenarios_10'!D11-'Scenarios_10'!E11/'Scenarios_10'!B11)<='Inputs_Data'!B6,((MAX(0,'Scenarios_10'!D11-'Scenarios_10'!E11/'Scenarios_10'!B11)-(IF('Scenarios_10'!C11="uniform_pct",'Inputs_Data'!E6*(1-MIN('Scenarios_10'!G11,'Assumptions'!B10)),IF('Scenarios_10'!C11="electricity_only_pct",('Inputs_Data'!C6*(1-MIN('Scenarios_10'!G11,'Assumptions'!B10)))+'Inputs_Data'!D6,0+('Inputs_Data'!D6*(1-AVERAGE('Assumptions'!B6,'Assumptions'!B7,'Assumptions'!B8,'Assumptions'!B9)))))+'Inputs_Data'!F6))-('Inputs_Data'!B6-('Inputs_Data'!E6+'Inputs_Data'!F6)))>=0,IF((MAX(0,'Scenarios_10'!D11-'Scenarios_10'!E11/'Scenarios_10'!B11)-(IF('Scenarios_10'!C11="uniform_pct",'Inputs_Data'!E6*(1-MIN('Scenarios_10'!G11,'Assumptions'!B10)),IF('Scenarios_10'!C11="electricity_only_pct",('Inputs_Data'!C6*(1-MIN('Scenarios_10'!G11,'Assumptions'!B10)))+'Inputs_Data'!D6,0+('Inputs_Data'!D6*(1-AVERAGE('Assumptions'!B6,'Assumptions'!B7,'Assumptions'!B8,'Assumptions'!B9)))))))<=0,999,ROUNDUP('Inputs_Data'!H5/((MAX(0,'Scenarios_10'!D11-'Scenarios_10'!E11/'Scenarios_10'!B11)-(IF('Scenarios_10'!C11="uniform_pct",'Inputs_Data'!E6*(1-MIN('Scenarios_10'!G11,'Assumptions'!B10)),IF('Scenarios_10'!C11="electricity_only_pct",('Inputs_Data'!C6*(1-MIN('Scenarios_10'!G11,'Assumptions'!B10)))+'Inputs_Data'!D6,0+('Inputs_Data'!D6*(1-AVERAGE('Assumptions'!B6,'Assumptions'!B7,'Assumptions'!B8,'Assumptions'!B9)))))))/12),0))<=36)
A13: ='Scenarios_10'!A12 | B13: =MAX(0,'Scenarios_10'!D12-'Scenarios_10'!E12/'Scenarios_10'!B12) | C13: ='Inputs_Data'!B6 | D13: =('Inputs_Data'!B6-(MAX(0,'Scenarios_10'!D12-'Scenarios_10'!E12/'Scenarios_10'!B12))) | E13: =IF('Scenarios_10'!C12="uniform_pct",'Inputs_Data'!E6*(1-MIN('Scenarios_10'!G12,'Assumptions'!B10)),IF('Scenarios_10'!C12="electricity_only_pct",('Inputs_Data'!C6*(1-MIN('Scenarios_10'!G12,'Assumptions'!B10)))+'Inputs_Data'!D6,0+('Inputs_Data'!D6*(1-AVERAGE('Assumptions'!B6,'Assumptions'!B7,'Assumptions'!B8,'Assumptions'!B9))))) | F13: ='Inputs_Data'!E6 | G13: =((MAX(0,'Scenarios_10'!D12-'Scenarios_10'!E12/'Scenarios_10'!B12)-(IF('Scenarios_10'!C12="uniform_pct",'Inputs_Data'!E6*(1-MIN('Scenarios_10'!G12,'Assumptions'!B10)),IF('Scenarios_10'!C12="electricity_only_pct",('Inputs_Data'!C6*(1-MIN('Scenarios_10'!G12,'Assumptions'!B10)))+'Inputs_Data'!D6,0+('Inputs_Data'!D6*(1-AVERAGE('Assumptions'!B6,'Assumptions'!B7,'Assumptions'!B8,'Assumptions'!B9)))))+'Inputs_Data'!F6))-('Inputs_Data'!B6-('Inputs_Data'!E6+'Inputs_Data'!F6))) | H13: =IF((MAX(0,'Scenarios_10'!D12-'Scenarios_10'!E12/'Scenarios_10'!B12)-(IF('Scenarios_10'!C12="uniform_pct",'Inputs_Data'!E6*(1-MIN('Scenarios_10'!G12,'Assumptions'!B10)),IF('Scenarios_10'!C12="electricity_only_pct",('Inputs_Data'!C6*(1-MIN('Scenarios_10'!G12,'Assumptions'!B10)))+'Inputs_Data'!D6,0+('Inputs_Data'!D6*(1-AVERAGE('Assumptions'!B6,'Assumptions'!B7,'Assumptions'!B8,'Assumptions'!B9)))))))<=0,999,ROUNDUP('Inputs_Data'!H5/((MAX(0,'Scenarios_10'!D12-'Scenarios_10'!E12/'Scenarios_10'!B12)-(IF('Scenarios_10'!C12="uniform_pct",'Inputs_Data'!E6*(1-MIN('Scenarios_10'!G12,'Assumptions'!B10)),IF('Scenarios_10'!C12="electricity_only_pct",('Inputs_Data'!C6*(1-MIN('Scenarios_10'!G12,'Assumptions'!B10)))+'Inputs_Data'!D6,0+('Inputs_Data'!D6*(1-AVERAGE('Assumptions'!B6,'Assumptions'!B7,'Assumptions'!B8,'Assumptions'!B9)))))))/12),0)) | I13: =AND(MAX(0,'Scenarios_10'!D12-'Scenarios_10'!E12/'Scenarios_10'!B12)<='Inputs_Data'!B6,((MAX(0,'Scenarios_10'!D12-'Scenarios_10'!E12/'Scenarios_10'!B12)-(IF('Scenarios_10'!C12="uniform_pct",'Inputs_Data'!E6*(1-MIN('Scenarios_10'!G12,'Assumptions'!B10)),IF('Scenarios_10'!C12="electricity_only_pct",('Inputs_Data'!C6*(1-MIN('Scenarios_10'!G12,'Assumptions'!B10)))+'Inputs_Data'!D6,0+('Inputs_Data'!D6*(1-AVERAGE('Assumptions'!B6,'Assumptions'!B7,'Assumptions'!B8,'Assumptions'!B9)))))+'Inputs_Data'!F6))-('Inputs_Data'!B6-('Inputs_Data'!E6+'Inputs_Data'!F6)))>=0,IF((MAX(0,'Scenarios_10'!D12-'Scenarios_10'!E12/'Scenarios_10'!B12)-(IF('Scenarios_10'!C12="uniform_pct",'Inputs_Data'!E6*(1-MIN('Scenarios_10'!G12,'Assumptions'!B10)),IF('Scenarios_10'!C12="electricity_only_pct",('Inputs_Data'!C6*(1-MIN('Scenarios_10'!G12,'Assumptions'!B10)))+'Inputs_Data'!D6,0+('Inputs_Data'!D6*(1-AVERAGE('Assumptions'!B6,'Assumptions'!B7,'Assumptions'!B8,'Assumptions'!B9)))))))<=0,999,ROUNDUP('Inputs_Data'!H5/((MAX(0,'Scenarios_10'!D12-'Scenarios_10'!E12/'Scenarios_10'!B12)-(IF('Scenarios_10'!C12="uniform_pct",'Inputs_Data'!E6*(1-MIN('Scenarios_10'!G12,'Assumptions'!B10)),IF('Scenarios_10'!C12="electricity_only_pct",('Inputs_Data'!C6*(1-MIN('Scenarios_10'!G12,'Assumptions'!B10)))+'Inputs_Data'!D6,0+('Inputs_Data'!D6*(1-AVERAGE('Assumptions'!B6,'Assumptions'!B7,'Assumptions'!B8,'Assumptions'!B9)))))))/12),0))<=36)
A14: ='Scenarios_10'!A13 | B14: =MAX(0,'Scenarios_10'!D13-'Scenarios_10'!E13/'Scenarios_10'!B13) | C14: ='Inputs_Data'!B6 | D14: =('Inputs_Data'!B6-(MAX(0,'Scenarios_10'!D13-'Scenarios_10'!E13/'Scenarios_10'!B13))) | E14: =IF('Scenarios_10'!C13="uniform_pct",'Inputs_Data'!E6*(1-MIN('Scenarios_10'!G13,'Assumptions'!B10)),IF('Scenarios_10'!C13="electricity_only_pct",('Inputs_Data'!C6*(1-MIN('Scenarios_10'!G13,'Assumptions'!B10)))+'Inputs_Data'!D6,0+('Inputs_Data'!D6*(1-AVERAGE('Assumptions'!B6,'Assumptions'!B7,'Assumptions'!B8,'Assumptions'!B9))))) | F14: ='Inputs_Data'!E6 | G14: =((MAX(0,'Scenarios_10'!D13-'Scenarios_10'!E13/'Scenarios_10'!B13)-(IF('Scenarios_10'!C13="uniform_pct",'Inputs_Data'!E6*(1-MIN('Scenarios_10'!G13,'Assumptions'!B10)),IF('Scenarios_10'!C13="electricity_only_pct",('Inputs_Data'!C6*(1-MIN('Scenarios_10'!G13,'Assumptions'!B10)))+'Inputs_Data'!D6,0+('Inputs_Data'!D6*(1-AVERAGE('Assumptions'!B6,'Assumptions'!B7,'Assumptions'!B8,'Assumptions'!B9)))))+'Inputs_Data'!F6))-('Inputs_Data'!B6-('Inputs_Data'!E6+'Inputs_Data'!F6))) | H14: =IF((MAX(0,'Scenarios_10'!D13-'Scenarios_10'!E13/'Scenarios_10'!B13)-(IF('Scenarios_10'!C13="uniform_pct",'Inputs_Data'!E6*(1-MIN('Scenarios_10'!G13,'Assumptions'!B10)),IF('Scenarios_10'!C13="electricity_only_pct",('Inputs_Data'!C6*(1-MIN('Scenarios_10'!G13,'Assumptions'!B10)))+'Inputs_Data'!D6,0+('Inputs_Data'!D6*(1-AVERAGE('Assumptions'!B6,'Assumptions'!B7,'Assumptions'!B8,'Assumptions'!B9)))))))<=0,999,ROUNDUP('Inputs_Data'!H5/((MAX(0,'Scenarios_10'!D13-'Scenarios_10'!E13/'Scenarios_10'!B13)-(IF('Scenarios_10'!C13="uniform_pct",'Inputs_Data'!E6*(1-MIN('Scenarios_10'!G13,'Assumptions'!B10)),IF('Scenarios_10'!C13="electricity_only_pct",('Inputs_Data'!C6*(1-MIN('Scenarios_10'!G13,'Assumptions'!B10)))+'Inputs_Data'!D6,0+('Inputs_Data'!D6*(1-AVERAGE('Assumptions'!B6,'Assumptions'!B7,'Assumptions'!B8,'Assumptions'!B9)))))))/12),0)) | I14: =AND(MAX(0,'Scenarios_10'!D13-'Scenarios_10'!E13/'Scenarios_10'!B13)<='Inputs_Data'!B6,((MAX(0,'Scenarios_10'!D13-'Scenarios_10'!E13/'Scenarios_10'!B13)-(IF('Scenarios_10'!C13="uniform_pct",'Inputs_Data'!E6*(1-MIN('Scenarios_10'!G13,'Assumptions'!B10)),IF('Scenarios_10'!C13="electricity_only_pct",('Inputs_Data'!C6*(1-MIN('Scenarios_10'!G13,'Assumptions'!B10)))+'Inputs_Data'!D6,0+('Inputs_Data'!D6*(1-AVERAGE('Assumptions'!B6,'Assumptions'!B7,'Assumptions'!B8,'Assumptions'!B9)))))+'Inputs_Data'!F6))-('Inputs_Data'!B6-('Inputs_Data'!E6+'Inputs_Data'!F6)))>=0,IF((MAX(0,'Scenarios_10'!D13-'Scenarios_10'!E13/'Scenarios_10'!B13)-(IF('Scenarios_10'!C13="uniform_pct",'Inputs_Data'!E6*(1-MIN('Scenarios_10'!G13,'Assumptions'!B10)),IF('Scenarios_10'!C13="electricity_only_pct",('Inputs_Data'!C6*(1-MIN('Scenarios_10'!G13,'Assumptions'!B10)))+'Inputs_Data'!D6,0+('Inputs_Data'!D6*(1-AVERAGE('Assumptions'!B6,'Assumptions'!B7,'Assumptions'!B8,'Assumptions'!B9)))))))<=0,999,ROUNDUP('Inputs_Data'!H5/((MAX(0,'Scenarios_10'!D13-'Scenarios_10'!E13/'Scenarios_10'!B13)-(IF('Scenarios_10'!C13="uniform_pct",'Inputs_Data'!E6*(1-MIN('Scenarios_10'!G13,'Assumptions'!B10)),IF('Scenarios_10'!C13="electricity_only_pct",('Inputs_Data'!C6*(1-MIN('Scenarios_10'!G13,'Assumptions'!B10)))+'Inputs_Data'!D6,0+('Inputs_Data'!D6*(1-AVERAGE('Assumptions'!B6,'Assumptions'!B7,'Assumptions'!B8,'Assumptions'!B9)))))))/12),0))<=36)
A15: ='Scenarios_10'!A14 | B15: =MAX(0,'Scenarios_10'!D14-'Scenarios_10'!E14/'Scenarios_10'!B14) | C15: ='Inputs_Data'!B6 | D15: =('Inputs_Data'!B6-(MAX(0,'Scenarios_10'!D14-'Scenarios_10'!E14/'Scenarios_10'!B14))) | E15: =IF('Scenarios_10'!C14="uniform_pct",'Inputs_Data'!E6*(1-MIN('Scenarios_10'!G14,'Assumptions'!B10)),IF('Scenarios_10'!C14="electricity_only_pct",('Inputs_Data'!C6*(1-MIN('Scenarios_10'!G14,'Assumptions'!B10)))+'Inputs_Data'!D6,0+('Inputs_Data'!D6*(1-AVERAGE('Assumptions'!B6,'Assumptions'!B7,'Assumptions'!B8,'Assumptions'!B9))))) | F15: ='Inputs_Data'!E6 | G15: =((MAX(0,'Scenarios_10'!D14-'Scenarios_10'!E14/'Scenarios_10'!B14)-(IF('Scenarios_10'!C14="uniform_pct",'Inputs_Data'!E6*(1-MIN('Scenarios_10'!G14,'Assumptions'!B10)),IF('Scenarios_10'!C14="electricity_only_pct",('Inputs_Data'!C6*(1-MIN('Scenarios_10'!G14,'Assumptions'!B10)))+'Inputs_Data'!D6,0+('Inputs_Data'!D6*(1-AVERAGE('Assumptions'!B6,'Assumptions'!B7,'Assumptions'!B8,'Assumptions'!B9)))))+'Inputs_Data'!F6))-('Inputs_Data'!B6-('Inputs_Data'!E6+'Inputs_Data'!F6))) | H15: =IF((MAX(0,'Scenarios_10'!D14-'Scenarios_10'!E14/'Scenarios_10'!B14)-(IF('Scenarios_10'!C14="uniform_pct",'Inputs_Data'!E6*(1-MIN('Scenarios_10'!G14,'Assumptions'!B10)),IF('Scenarios_10'!C14="electricity_only_pct",('Inputs_Data'!C6*(1-MIN('Scenarios_10'!G14,'Assumptions'!B10)))+'Inputs_Data'!D6,0+('Inputs_Data'!D6*(1-AVERAGE('Assumptions'!B6,'Assumptions'!B7,'Assumptions'!B8,'Assumptions'!B9)))))))<=0,999,ROUNDUP('Inputs_Data'!H5/((MAX(0,'Scenarios_10'!D14-'Scenarios_10'!E14/'Scenarios_10'!B14)-(IF('Scenarios_10'!C14="uniform_pct",'Inputs_Data'!E6*(1-MIN('Scenarios_10'!G14,'Assumptions'!B10)),IF('Scenarios_10'!C14="electricity_only_pct",('Inputs_Data'!C6*(1-MIN('Scenarios_10'!G14,'Assumptions'!B10)))+'Inputs_Data'!D6,0+('Inputs_Data'!D6*(1-AVERAGE('Assumptions'!B6,'Assumptions'!B7,'Assumptions'!B8,'Assumptions'!B9)))))))/12),0)) | I15: =AND(MAX(0,'Scenarios_10'!D14-'Scenarios_10'!E14/'Scenarios_10'!B14)<='Inputs_Data'!B6,((MAX(0,'Scenarios_10'!D14-'Scenarios_10'!E14/'Scenarios_10'!B14)-(IF('Scenarios_10'!C14="uniform_pct",'Inputs_Data'!E6*(1-MIN('Scenarios_10'!G14,'Assumptions'!B10)),IF('Scenarios_10'!C14="electricity_only_pct",('Inputs_Data'!C6*(1-MIN('Scenarios_10'!G14,'Assumptions'!B10)))+'Inputs_Data'!D6,0+('Inputs_Data'!D6*(1-AVERAGE('Assumptions'!B6,'Assumptions'!B7,'Assumptions'!B8,'Assumptions'!B9)))))+'Inputs_Data'!F6))-('Inputs_Data'!B6-('Inputs_Data'!E6+'Inputs_Data'!F6)))>=0,IF((MAX(0,'Scenarios_10'!D14-'Scenarios_10'!E14/'Scenarios_10'!B14)-(IF('Scenarios_10'!C14="uniform_pct",'Inputs_Data'!E6*(1-MIN('Scenarios_10'!G14,'Assumptions'!B10)),IF('Scenarios_10'!C14="electricity_only_pct",('Inputs_Data'!C6*(1-MIN('Scenarios_10'!G14,'Assumptions'!B10)))+'Inputs_Data'!D6,0+('Inputs_Data'!D6*(1-AVERAGE('Assumptions'!B6,'Assumptions'!B7,'Assumptions'!B8,'Assumptions'!B9)))))))<=0,999,ROUNDUP('Inputs_Data'!H5/((MAX(0,'Scenarios_10'!D14-'Scenarios_10'!E14/'Scenarios_10'!B14)-(IF('Scenarios_10'!C14="uniform_pct",'Inputs_Data'!E6*(1-MIN('Scenarios_10'!G14,'Assumptions'!B10)),IF('Scenarios_10'!C14="electricity_only_pct",('Inputs_Data'!C6*(1-MIN('Scenarios_10'!G14,'Assumptions'!B10)))+'Inputs_Data'!D6,0+('Inputs_Data'!D6*(1-AVERAGE('Assumptions'!B6,'Assumptions'!B7,'Assumptions'!B8,'Assumptions'!B9)))))))/12),0))<=36)
A18: Chart: Client payment vs baseline (Year 1)
A19: Tier | B19: ClientPay_Y1 | C19: BaselinePay_Y1
A20: =Model_Calc!A5 | B20: =Model_Calc!B5 | C20: =Model_Calc!C5
A21: =Model_Calc!A6 | B21: =Model_Calc!B6 | C21: =Model_Calc!C6
A22: =Model_Calc!A7 | B22: =Model_Calc!B7 | C22: =Model_Calc!C7
A23: =Model_Calc!A8 | B23: =Model_Calc!B8 | C23: =Model_Calc!C8
A24: =Model_Calc!A9 | B24: =Model_Calc!B9 | C24: =Model_Calc!C9
A25: =Model_Calc!A10 | B25: =Model_Calc!B10 | C25: =Model_Calc!C10
A26: =Model_Calc!A11 | B26: =Model_Calc!B11 | C26: =Model_Calc!C11
A27: =Model_Calc!A12 | B27: =Model_Calc!B12 | C27: =Model_Calc!C12
A28: =Model_Calc!A13 | B28: =Model_Calc!B13 | C28: =Model_Calc!C13
A29: =Model_Calc!A14 | B29: =Model_Calc!B14 | C29: =Model_Calc!C14

Sheet Scenario_Tables
A1: Scenario cashflow tables (all formulas)
A2: Baseline vs LaaS year-by-year cashflow; same structure for all 10 tiers.
A5: Tier: ='Scenarios_10'!A5
A6: year | B6: trust_capex | C6: trust_fee | D6: trust_cash_opex | E6: trust_net_cf | F6: trust_cum_cf | G6: laas_capex | H6: laas_fee | I6: laas_upfront | J6: laas_cash_opex | K6: laas_net_cf | L6: laas_cum_cf
A7: 0 | B7: =IF(0=0,-'Inputs_Data'!H5,0) | C7: =IF(0=0,0,'Inputs_Data'!B5) | D7: =IF(0=0,0,'Inputs_Data'!E5) | E7: =(IF(0=0,-'Inputs_Data'!H5,0))+(IF(0=0,0,'Inputs_Data'!B5))-(IF(0=0,0,'Inputs_Data'!E5)) | F7: =(0)+(E7) | G7: =IF(0=0,-'Inputs_Data'!H5,0) | H7: =IF(AND(0>=1,0<='Scenarios_10'!B5),MAX(0,(MAX(0,'Scenarios_10'!D5-'Scenarios_10'!E5/'Scenarios_10'!B5))-IF(AND(0>('Scenarios_10'!B5-4),0<='Scenarios_10'!B5),'Scenarios_10'!F5,0)),0) | I7: =IF(0=0,'Scenarios_10'!E5,0) | J7: =IF(0=0,0,IF('Scenarios_10'!C5="uniform_pct",'Inputs_Data'!E5*(1-(MIN('Scenarios_10'!G5,'Assumptions'!B10))),IF('Scenarios_10'!C5="electricity_only_pct",('Inputs_Data'!C5*(1-(MIN('Scenarios_10'!G5,'Assumptions'!B10))))+'Inputs_Data'!D5,0+('Inputs_Data'!D5*(1-AVERAGE('Assumptions'!B6,'Assumptions'!B7,'Assumptions'!B8,'Assumptions'!B9)))))) | K7: =(IF(0=0,-'Inputs_Data'!H5,0))+(IF(AND(0>=1,0<='Scenarios_10'!B5),MAX(0,(MAX(0,'Scenarios_10'!D5-'Scenarios_10'!E5/'Scenarios_10'!B5))-IF(AND(0>('Scenarios_10'!B5-4),0<='Scenarios_10'!B5),'Scenarios_10'!F5,0)),0))+(IF(0=0,'Scenarios_10'!E5,0))-(IF(0=0,0,IF('Scenarios_10'!C5="uniform_pct",'Inputs_Data'!E5*(1-(MIN('Scenarios_10'!G5,'Assumptions'!B10))),IF('Scenarios_10'!C5="electricity_only_pct",('Inputs_Data'!C5*(1-(MIN('Scenarios_10'!G5,'Assumptions'!B10))))+'Inputs_Data'!D5,0+('Inputs_Data'!D5*(1-AVERAGE('Assumptions'!B6,'Assumptions'!B7,'Assumptions'!B8,'Assumptions'!B9))))))) | L7: =(0)+(K7)
A8: 1 | B8: =IF(1=0,-'Inputs_Data'!H5,0) | C8: =IF(1=0,0,'Inputs_Data'!B6) | D8: =IF(1=0,0,'Inputs_Data'!E6) | E8: =(IF(1=0,-'Inputs_Data'!H5,0))+(IF(1=0,0,'Inputs_Data'!B6))-(IF(1=0,0,'Inputs_Data'!E6)) | F8: =(F7)+(E8) | G8: =IF(1=0,-'Inputs_Data'!H5,0) | H8: =IF(AND(1>=1,1<='Scenarios_10'!B5),MAX(0,(MAX(0,'Scenarios_10'!D5-'Scenarios_10'!E5/'Scenarios_10'!B5))-IF(AND(1>('Scenarios_10'!B5-4),1<='Scenarios_10'!B5),'Scenarios_10'!F5,0)),0) | I8: =IF(1=0,'Scenarios_10'!E5,0) | J8: =IF(1=0,0,IF('Scenarios_10'!C5="uniform_pct",'Inputs_Data'!E6*(1-(MIN('Scenarios_10'!G5,'Assumptions'!B10))),IF('Scenarios_10'!C5="electricity_only_pct",('Inputs_Data'!C6*(1-(MIN('Scenarios_10'!G5,'Assumptions'!B10))))+'Inputs_Data'!D6,0+('Inputs_Data'!D6*(1-AVERAGE('Assumptions'!B6,'Assumptions'!B7,'Assumptions'!B8,'Assumptions'!B9)))))) | K8: =(IF(1=0,-'Inputs_Data'!H5,0))+(IF(AND(1>=1,1<='Scenarios_10'!B5),MAX(0,(MAX(0,'Scenarios_10'!D5-'Scenarios_10'!E5/'Scenarios_10'!B5))-IF(AND(1>('Scenarios_10'!B5-4),1<='Scenarios_10'!B5),'Scenarios_10'!F5,0)),0))+(IF(1=0,'Scenarios_10'!E5,0))-(IF(1=0,0,IF('Scenarios_10'!C5="uniform_pct",'Inputs_Data'!E6*(1-(MIN('Scenarios_10'!G5,'Assumptions'!B10))),IF('Scenarios_10'!C5="electricity_only_pct",('Inputs_Data'!C6*(1-(MIN('Scenarios_10'!G5,'Assumptions'!B10))))+'Inputs_Data'!D6,0+('Inputs_Data'!D6*(1-AVERAGE('Assumptions'!B6,'Assumptions'!B7,'Assumptions'!B8,'Assumptions'!B9))))))) | L8: =(L7)+(K8)
A9: 2 | B9: =IF(2=0,-'Inputs_Data'!H5,0) | C9: =IF(2=0,0,'Inputs_Data'!B7) | D9: =IF(2=0,0,'Inputs_Data'!E7) | E9: =(IF(2=0,-'Inputs_Data'!H5,0))+(IF(2=0,0,'Inputs_Data'!B7))-(IF(2=0,0,'Inputs_Data'!E7)) | F9: =(F8)+(E9) | G9: =IF(2=0,-'Inputs_Data'!H5,0) | H9: =IF(AND(2>=1,2<='Scenarios_10'!B5),MAX(0,(MAX(0,'Scenarios_10'!D5-'Scenarios_10'!E5/'Scenarios_10'!B5))-IF(AND(2>('Scenarios_10'!B5-4),2<='Scenarios_10'!B5),'Scenarios_10'!F5,0)),0) | I9: =IF(2=0,'Scenarios_10'!E5,0) | J9: =IF(2=0,0,IF('Scenarios_10'!C5="uniform_pct",'Inputs_Data'!E7*(1-(MIN('Scenarios_10'!G5,'Assumptions'!B10))),IF('Scenarios_10'!C5="electricity_only_pct",('Inputs_Data'!C7*(1-(MIN('Scenarios_10'!G5,'Assumptions'!B10))))+'Inputs_Data'!D7,0+('Inputs_Data'!D7*(1-AVERAGE('Assumptions'!B6,'Assumptions'!B7,'Assumptions'!B8,'Assumptions'!B9)))))) | K9: =(IF(2=0,-'Inputs_Data'!H5,0))+(IF(AND(2>=1,2<='Scenarios_10'!B5),MAX(0,(MAX(0,'Scenarios_10'!D5-'Scenarios_10'!E5/'Scenarios_10'!B5))-IF(AND(2>('Scenarios_10'!B5-4),2<='Scenarios_10'!B5),'Scenarios_10'!F5,0)),0))+(IF(2=0,'Scenarios_10'!E5,0))-(IF(2=0,0,IF('Scenarios_10'!C5="uniform_pct",'Inputs_Data'!E7*(1-(MIN('Scenarios_10'!G5,'Assumptions'!B10))),IF('Scenarios_10'!C5="electricity_only_pct",('Inputs_Data'!C7*(1-(MIN('Scenarios_10'!G5,'Assumptions'!B10))))+'Inputs_Data'!D7,0+('Inputs_Data'!D7*(1-AVERAGE('Assumptions'!B6,'Assumptions'!B7,'Assumptions'!B8,'Assumptions'!B9))))))) | L9: =(L8)+(K9)
A10: 3 | B10: =IF(3=0,-'Inputs_Data'!H5,0) | C10: =IF(3=0,0,'Inputs_Data'!B8) | D10: =IF(3=0,0,'Inputs_Data'!E8) | E10: =(IF(3=0,-'Inputs_Data'!H5,0))+(IF(3=0,0,'Inputs_Data'!B8))-(IF(3=0,0,'Inputs_Data'!E8)) | F10: =(F9)+(E10) | G10: =IF(3=0,-'Inputs_Data'!H5,0) | H10: =IF(AND(3>=1,3<='Scenarios_10'!B5),MAX(0,(MAX(0,'Scenarios_10'!D5-'Scenarios_10'!E5/'Scenarios_10'!B5))-IF(AND(3>('Scenarios_10'!B5-4),3<='Scenarios_10'!B5),'Scenarios_10'!F5,0)),0) | I10: =IF(3=0,'Scenarios_10'!E5,0) | J10: =IF(3=0,0,IF('Scenarios_10'!C5="uniform_pct",'Inputs_Data'!E8*(1-(MIN('Scenarios_10'!G5,'Assumptions'!B10))),IF('Scenarios_10'!C5="electricity_only_pct",('Inputs_Data'!C8*(1-(MIN('Scenarios_10'!G5,'Assumptions'!B10))))+'Inputs_Data'!D8,0+('Inputs_Data'!D8*(1-AVERAGE('Assumptions'!B6,'Assumptions'!B7,'Assumptions'!B8,'Assumptions'!B9)))))) | K10: =(IF(3=0,-'Inputs_Data'!H5,0))+(IF(AND(3>=1,3<='Scenarios_10'!B5),MAX(0,(MAX(0,'Scenarios_10'!D5-'Scenarios_10'!E5/'Scenarios_10'!B5))-IF(AND(3>('Scenarios_10'!B5-4),3<='Scenarios_10'!B5),'Scenarios_10'!F5,0)),0))+(IF(3=0,'Scenarios_10'!E5,0))-(IF(3=0,0,IF('Scenarios_10'!C5="uniform_pct",'Inputs_Data'!E8*(1-(MIN('Scenarios_10'!G5,'Assumptions'!B10))),IF('Scenarios_10'!C5="electricity_only_pct",('Inputs_Data'!C8*(1-(MIN('Scenarios_10'!G5,'Assumptions'!B10))))+'Inputs_Data'!D8,0+('Inputs_Data'!D8*(1-AVERAGE('Assumptions'!B6,'Assumptions'!B7,'Assumptions'!B8,'Assumptions'!B9))))))) | L10: =(L9)+(K10)
A11: 4 | B11: =IF(4=0,-'Inputs_Data'!H5,0) | C11: =IF(4=0,0,'Inputs_Data'!B9) | D11: =IF(4=0,0,'Inputs_Data'!E9) | E11: =(IF(4=0,-'Inputs_Data'!H5,0))+(IF(4=0,0,'Inputs_Data'!B9))-(IF(4=0,0,'Inputs_Data'!E9)) | F11: =(F10)+(E11) | G11: =IF(4=0,-'Inputs_Data'!H5,0) | H11: =IF(AND(4>=1,4<='Scenarios_10'!B5),MAX(0,(MAX(0,'Scenarios_10'!D5-'Scenarios_10'!E5/'Scenarios_10'!B5))-IF(AND(4>('Scenarios_10'!B5-4),4<='Scenarios_10'!B5),'Scenarios_10'!F5,0)),0) | I11: =IF(4=0,'Scenarios_10'!E5,0) | J11: =IF(4=0,0,IF('Scenarios_10'!C5="uniform_pct",'Inputs_Data'!E9*(1-(MIN('Scenarios_10'!G5,'Assumptions'!B10))),IF('Scenarios_10'!C5="electricity_only_pct",('Inputs_Data'!C9*(1-(MIN('Scenarios_10'!G5,'Assumptions'!B10))))+'Inputs_Data'!D9,0+('Inputs_Data'!D9*(1-AVERAGE('Assumptions'!B6,'Assumptions'!B7,'Assumptions'!B8,'Assumptions'!B9)))))) | K11: =(IF(4=0,-'Inputs_Data'!H5,0))+(IF(AND(4>=1,4<='Scenarios_10'!B5),MAX(0,(MAX(0,'Scenarios_10'!D5-'Scenarios_10'!E5/'Scenarios_10'!B5))-IF(AND(4>('Scenarios_10'!B5-4),4<='Scenarios_10'!B5),'Scenarios_10'!F5,0)),0))+(IF(4=0,'Scenarios_10'!E5,0))-(IF(4=0,0,IF('Scenarios_10'!C5="uniform_pct",'Inputs_Data'!E9*(1-(MIN('Scenarios_10'!G5,'Assumptions'!B10))),IF('Scenarios_10'!C5="electricity_only_pct",('Inputs_Data'!C9*(1-(MIN('Scenarios_10'!G5,'Assumptions'!B10))))+'Inputs_Data'!D9,0+('Inputs_Data'!D9*(1-AVERAGE('Assumptions'!B6,'Assumptions'!B7,'Assumptions'!B8,'Assumptions'!B9))))))) | L11: =(L10)+(K11)
A12: 5 | B12: =IF(5=0,-'Inputs_Data'!H5,0) | C12: =IF(5=0,0,'Inputs_Data'!B10) | D12: =IF(5=0,0,'Inputs_Data'!E10) | E12: =(IF(5=0,-'Inputs_Data'!H5,0))+(IF(5=0,0,'Inputs_Data'!B10))-(IF(5=0,0,'Inputs_Data'!E10)) | F12: =(F11)+(E12) | G12: =IF(5=0,-'Inputs_Data'!H5,0) | H12: =IF(AND(5>=1,5<='Scenarios_10'!B5),MAX(0,(MAX(0,'Scenarios_10'!D5-'Scenarios_10'!E5/'Scenarios_10'!B5))-IF(AND(5>('Scenarios_10'!B5-4),5<='Scenarios_10'!B5),'Scenarios_10'!F5,0)),0) | I12: =IF(5=0,'Scenarios_10'!E5,0) | J12: =IF(5=0,0,IF('Scenarios_10'!C5="uniform_pct",'Inputs_Data'!E10*(1-(MIN('Scenarios_10'!G5,'Assumptions'!B10))),IF('Scenarios_10'!C5="electricity_only_pct",('Inputs_Data'!C10*(1-(MIN('Scenarios_10'!G5,'Assumptions'!B10))))+'Inputs_Data'!D10,0+('Inputs_Data'!D10*(1-AVERAGE('Assumptions'!B6,'Assumptions'!B7,'Assumptions'!B8,'Assumptions'!B9)))))) | K12: =(IF(5=0,-'Inputs_Data'!H5,0))+(IF(AND(5>=1,5<='Scenarios_10'!B5),MAX(0,(MAX(0,'Scenarios_10'!D5-'Scenarios_10'!E5/'Scenarios_10'!B5))-IF(AND(5>('Scenarios_10'!B5-4),5<='Scenarios_10'!B5),'Scenarios_10'!F5,0)),0))+(IF(5=0,'Scenarios_10'!E5,0))-(IF(5=0,0,IF('Scenarios_10'!C5="uniform_pct",'Inputs_Data'!E10*(1-(MIN('Scenarios_10'!G5,'Assumptions'!B10))),IF('Scenarios_10'!C5="electricity_only_pct",('Inputs_Data'!C10*(1-(MIN('Scenarios_10'!G5,'Assumptions'!B10))))+'Inputs_Data'!D10,0+('Inputs_Data'!D10*(1-AVERAGE('Assumptions'!B6,'Assumptions'!B7,'Assumptions'!B8,'Assumptions'!B9))))))) | L12: =(L11)+(K12)
A13: 6 | B13: =IF(6=0,-'Inputs_Data'!H5,0) | C13: =IF(6=0,0,'Inputs_Data'!B11) | D13: =IF(6=0,0,'Inputs_Data'!E11) | E13: =(IF(6=0,-'Inputs_Data'!H5,0))+(IF(6=0,0,'Inputs_Data'!B11))-(IF(6=0,0,'Inputs_Data'!E11)) | F13: =(F12)+(E13) | G13: =IF(6=0,-'Inputs_Data'!H5,0) | H13: =IF(AND(6>=1,6<='Scenarios_10'!B5),MAX(0,(MAX(0,'Scenarios_10'!D5-'Scenarios_10'!E5/'Scenarios_10'!B5))-IF(AND(6>('Scenarios_10'!B5-4),6<='Scenarios_10'!B5),'Scenarios_10'!F5,0)),0) | I13: =IF(6=0,'Scenarios_10'!E5,0) | J13: =IF(6=0,0,IF('Scenarios_10'!C5="uniform_pct",'Inputs_Data'!E11*(1-(MIN('Scenarios_10'!G5,'Assumptions'!B10))),IF('Scenarios_10'!C5="electricity_only_pct",('Inputs_Data'!C11*(1-(MIN('Scenarios_10'!G5,'Assumptions'!B10))))+'Inputs_Data'!D11,0+('Inputs_Data'!D11*(1-AVERAGE('Assumptions'!B6,'Assumptions'!B7,'Assumptions'!B8,'Assumptions'!B9)))))) | K13: =(IF(6=0,-'Inputs_Data'!H5,0))+(IF(AND(6>=1,6<='Scenarios_10'!B5),MAX(0,(MAX(0,'Scenarios_10'!D5-'Scenarios_10'!E5/'Scenarios_10'!B5))-IF(AND(6>('Scenarios_10'!B5-4),6<='Scenarios_10'!B5),'Scenarios_10'!F5,0)),0))+(IF(6=0,'Scenarios_10'!E5,0))-(IF(6=0,0,IF('Scenarios_10'!C5="uniform_pct",'Inputs_Data'!E11*(1-(MIN('Scenarios_10'!G5,'Assumptions'!B10))),IF('Scenarios_10'!C5="electricity_only_pct",('Inputs_Data'!C11*(1-(MIN('Scenarios_10'!G5,'Assumptions'!B10))))+'Inputs_Data'!D11,0+('Inputs_Data'!D11*(1-AVERAGE('Assumptions'!B6,'Assumptions'!B7,'Assumptions'!B8,'Assumptions'!B9))))))) | L13: =(L12)+(K13)
A14: 7 | B14: =IF(7=0,-'Inputs_Data'!H5,0) | C14: =IF(7=0,0,'Inputs_Data'!B12) | D14: =IF(7=0,0,'Inputs_Data'!E12) | E14: =(IF(7=0,-'Inputs_Data'!H5,0))+(IF(7=0,0,'Inputs_Data'!B12))-(IF(7=0,0,'Inputs_Data'!E12)) | F14: =(F13)+(E14) | G14: =IF(7=0,-'Inputs_Data'!H5,0) | H14: =IF(AND(7>=1,7<='Scenarios_10'!B5),MAX(0,(MAX(0,'Scenarios_10'!D5-'Scenarios_10'!E5/'Scenarios_10'!B5))-IF(AND(7>('Scenarios_10'!B5-4),7<='Scenarios_10'!B5),'Scenarios_10'!F5,0)),0) | I14: =IF(7=0,'Scenarios_10'!E5,0) | J14: =IF(7=0,0,IF('Scenarios_10'!C5="uniform_pct",'Inputs_Data'!E12*(1-(MIN('Scenarios_10'!G5,'Assumptions'!B10))),IF('Scenarios_10'!C5="electricity_only_pct",('Inputs_Data'!C12*(1-(MIN('Scenarios_10'!G5,'Assumptions'!B10))))+'Inputs_Data'!D12,0+('Inputs_Data'!D12*(1-AVERAGE('Assumptions'!B6,'Assumptions'!B7,'Assumptions'!B8,'Assumptions'!B9)))))) | K14: =(IF(7=0,-'Inputs_Data'!H5,0))+(IF(AND(7>=1,7<='Scenarios_10'!B5),MAX(0,(MAX(0,'Scenarios_10'!D5-'Scenarios_10'!E5/'Scenarios_10'!B5))-IF(AND(7>('Scenarios_10'!B5-4),7<='Scenarios_10'!B5),'Scenarios_10'!F5,0)),0))+(IF(7=0,'Scenarios_10'!E5,0))-(IF(7=0,0,IF('Scenarios_10'!C5="uniform_pct",'Inputs_Data'!E12*(1-(MIN('Scenarios_10'!G5,'Assumptions'!B10))),IF('Scenarios_10'!C5="electricity_only_pct",('Inputs_Data'!C12*(1-(MIN('Scenarios_10'!G5,'Assumptions'!B10))))+'Inputs_Data'!D12,0+('Inputs_Data'!D12*(1-AVERAGE('Assumptions'!B6,'Assumptions'!B7,'Assumptions'!B8,'Assumptions'!B9))))))) | L14: =(L13)+(K14)
A15: 8 | B15: =IF(8=0,-'Inputs_Data'!H5,0) | C15: =IF(8=0,0,'Inputs_Data'!B13) | D15: =IF(8=0,0,'Inputs_Data'!E13) | E15: =(IF(8=0,-'Inputs_Data'!H5,0))+(IF(8=0,0,'Inputs_Data'!B13))-(IF(8=0,0,'Inputs_Data'!E13)) | F15: =(F14)+(E15) | G15: =IF(8=0,-'Inputs_Data'!H5,0) | H15: =IF(AND(8>=1,8<='Scenarios_10'!B5),MAX(0,(MAX(0,'Scenarios_10'!D5-'Scenarios_10'!E5/'Scenarios_10'!B5))-IF(AND(8>('Scenarios_10'!B5-4),8<='Scenarios_10'!B5),'Scenarios_10'!F5,0)),0) | I15: =IF(8=0,'Scenarios_10'!E5,0) | J15: =IF(8=0,0,IF('Scenarios_10'!C5="uniform_pct",'Inputs_Data'!E13*(1-(MIN('Scenarios_10'!G5,'Assumptions'!B10))),IF('Scenarios_10'!C5="electricity_only_pct",('Inputs_Data'!C13*(1-(MIN('Scenarios_10'!G5,'Assumptions'!B10))))+'Inputs_Data'!D13,0+('Inputs_Data'!D13*(1-AVERAGE('Assumptions'!B6,'Assumptions'!B7,'Assumptions'!B8,'Assumptions'!B9)))))) | K15: =(IF(8=0,-'Inputs_Data'!H5,0))+(IF(AND(8>=1,8<='Scenarios_10'!B5),MAX(0,(MAX(0,'Scenarios_10'!D5-'Scenarios_10'!E5/'Scenarios_10'!B5))-IF(AND(8>('Scenarios_10'!B5-4),8<='Scenarios_10'!B5),'Scenarios_10'!F5,0)),0))+(IF(8=0,'Scenarios_10'!E5,0))-(IF(8=0,0,IF('Scenarios_10'!C5="uniform_pct",'Inputs_Data'!E13*(1-(MIN('Scenarios_10'!G5,'Assumptions'!B10))),IF('Scenarios_10'!C5="electricity_only_pct",('Inputs_Data'!C13*(1-(MIN('Scenarios_10'!G5,'Assumptions'!B10))))+'Inputs_Data'!D13,0+('Inputs_Data'!D13*(1-AVERAGE('Assumptions'!B6,'Assumptions'!B7,'Assumptions'!B8,'Assumptions'!B9))))))) | L15: =(L14)+(K15)
A16: 9 | B16: =IF(9=0,-'Inputs_Data'!H5,0) | C16: =IF(9=0,0,'Inputs_Data'!B14) | D16: =IF(9=0,0,'Inputs_Data'!E14) | E16: =(IF(9=0,-'Inputs_Data'!H5,0))+(IF(9=0,0,'Inputs_Data'!B14))-(IF(9=0,0,'Inputs_Data'!E14)) | F16: =(F15)+(E16) | G16: =IF(9=0,-'Inputs_Data'!H5,0) | H16: =IF(AND(9>=1,9<='Scenarios_10'!B5),MAX(0,(MAX(0,'Scenarios_10'!D5-'Scenarios_10'!E5/'Scenarios_10'!B5))-IF(AND(9>('Scenarios_10'!B5-4),9<='Scenarios_10'!B5),'Scenarios_10'!F5,0)),0) | I16: =IF(9=0,'Scenarios_10'!E5,0) | J16: =IF(9=0,0,IF('Scenarios_10'!C5="uniform_pct",'Inputs_Data'!E14*(1-(MIN('Scenarios_10'!G5,'Assumptions'!B10))),IF('Scenarios_10'!C5="electricity_only_pct",('Inputs_Data'!C14*(1-(MIN('Scenarios_10'!G5,'Assumptions'!B10))))+'Inputs_Data'!D14,0+('Inputs_Data'!D14*(1-AVERAGE('Assumptions'!B6,'Assumptions'!B7,'Assumptions'!B8,'Assumptions'!B9)))))) | K16: =(IF(9=0,-'Inputs_Data'!H5,0))+(IF(AND(9>=1,9<='Scenarios_10'!B5),MAX(0,(MAX(0,'Scenarios_10'!D5-'Scenarios_10'!E5/'Scenarios_10'!B5))-IF(AND(9>('Scenarios_10'!B5-4),9<='Scenarios_10'!B5),'Scenarios_10'!F5,0)),0))+(IF(9=0,'Scenarios_10'!E5,0))-(IF(9=0,0,IF('Scenarios_10'!C5="uniform_pct",'Inputs_Data'!E14*(1-(MIN('Scenarios_10'!G5,'Assumptions'!B10))),IF('Scenarios_10'!C5="electricity_only_pct",('Inputs_Data'!C14*(1-(MIN('Scenarios_10'!G5,'Assumptions'!B10))))+'Inputs_Data'!D14,0+('Inputs_Data'!D14*(1-AVERAGE('Assumptions'!B6,'Assumptions'!B7,'Assumptions'!B8,'Assumptions'!B9))))))) | L16: =(L15)+(K16)
A17: 10 | B17: =IF(10=0,-'Inputs_Data'!H5,0) | C17: =IF(10=0,0,'Inputs_Data'!B15) | D17: =IF(10=0,0,'Inputs_Data'!E15) | E17: =(IF(10=0,-'Inputs_Data'!H5,0))+(IF(10=0,0,'Inputs_Data'!B15))-(IF(10=0,0,'Inputs_Data'!E15)) | F17: =(F16)+(E17) | G17: =IF(10=0,-'Inputs_Data'!H5,0) | H17: =IF(AND(10>=1,10<='Scenarios_10'!B5),MAX(0,(MAX(0,'Scenarios_10'!D5-'Scenarios_10'!E5/'Scenarios_10'!B5))-IF(AND(10>('Scenarios_10'!B5-4),10<='Scenarios_10'!B5),'Scenarios_10'!F5,0)),0) | I17: =IF(10=0,'Scenarios_10'!E5,0) | J17: =IF(10=0,0,IF('Scenarios_10'!C5="uniform_pct",'Inputs_Data'!E15*(1-(MIN('Scenarios_10'!G5,'Assumptions'!B10))),IF('Scenarios_10'!C5="electricity_only_pct",('Inputs_Data'!C15*(1-(MIN('Scenarios_10'!G5,'Assumptions'!B10))))+'Inputs_Data'!D15,0+('Inputs_Data'!D15*(1-AVERAGE('Assumptions'!B6,'Assumptions'!B7,'Assumptions'!B8,'Assumptions'!B9)))))) | K17: =(IF(10=0,-'Inputs_Data'!H5,0))+(IF(AND(10>=1,10<='Scenarios_10'!B5),MAX(0,(MAX(0,'Scenarios_10'!D5-'Scenarios_10'!E5/'Scenarios_10'!B5))-IF(AND(10>('Scenarios_10'!B5-4),10<='Scenarios_10'!B5),'Scenarios_10'!F5,0)),0))+(IF(10=0,'Scenarios_10'!E5,0))-(IF(10=0,0,IF('Scenarios_10'!C5="uniform_pct",'Inputs_Data'!E15*(1-(MIN('Scenarios_10'!G5,'Assumptions'!B10))),IF('Scenarios_10'!C5="electricity_only_pct",('Inputs_Data'!C15*(1-(MIN('Scenarios_10'!G5,'Assumptions'!B10))))+'Inputs_Data'!D15,0+('Inputs_Data'!D15*(1-AVERAGE('Assumptions'!B6,'Assumptions'!B7,'Assumptions'!B8,'Assumptions'!B9))))))) | L17: =(L16)+(K17)
A20: Tier: ='Scenarios_10'!A6
A21: year | B21: trust_capex | C21: trust_fee | D21: trust_cash_opex | E21: trust_net_cf | F21: trust_cum_cf | G21: laas_capex | H21: laas_fee | I21: laas_upfront | J21: laas_cash_opex | K21: laas_net_cf | L21: laas_cum_cf
A22: 0 | B22: =IF(0=0,-'Inputs_Data'!H5,0) | C22: =IF(0=0,0,'Inputs_Data'!B5) | D22: =IF(0=0,0,'Inputs_Data'!E5) | E22: =(IF(0=0,-'Inputs_Data'!H5,0))+(IF(0=0,0,'Inputs_Data'!B5))-(IF(0=0,0,'Inputs_Data'!E5)) | F22: =(0)+(E22) | G22: =IF(0=0,-'Inputs_Data'!H5,0) | H22: =IF(AND(0>=1,0<='Scenarios_10'!B6),MAX(0,(MAX(0,'Scenarios_10'!D6-'Scenarios_10'!E6/'Scenarios_10'!B6))-IF(AND(0>('Scenarios_10'!B6-4),0<='Scenarios_10'!B6),'Scenarios_10'!F6,0)),0) | I22: =IF(0=0,'Scenarios_10'!E6,0) | J22: =IF(0=0,0,IF('Scenarios_10'!C6="uniform_pct",'Inputs_Data'!E5*(1-(MIN('Scenarios_10'!G6,'Assumptions'!B10))),IF('Scenarios_10'!C6="electricity_only_pct",('Inputs_Data'!C5*(1-(MIN('Scenarios_10'!G6,'Assumptions'!B10))))+'Inputs_Data'!D5,0+('Inputs_Data'!D5*(1-AVERAGE('Assumptions'!B6,'Assumptions'!B7,'Assumptions'!B8,'Assumptions'!B9)))))) | K22: =(IF(0=0,-'Inputs_Data'!H5,0))+(IF(AND(0>=1,0<='Scenarios_10'!B6),MAX(0,(MAX(0,'Scenarios_10'!D6-'Scenarios_10'!E6/'Scenarios_10'!B6))-IF(AND(0>('Scenarios_10'!B6-4),0<='Scenarios_10'!B6),'Scenarios_10'!F6,0)),0))+(IF(0=0,'Scenarios_10'!E6,0))-(IF(0=0,0,IF('Scenarios_10'!C6="uniform_pct",'Inputs_Data'!E5*(1-(MIN('Scenarios_10'!G6,'Assumptions'!B10))),IF('Scenarios_10'!C6="electricity_only_pct",('Inputs_Data'!C5*(1-(MIN('Scenarios_10'!G6,'Assumptions'!B10))))+'Inputs_Data'!D5,0+('Inputs_Data'!D5*(1-AVERAGE('Assumptions'!B6,'Assumptions'!B7,'Assumptions'!B8,'Assumptions'!B9))))))) | L22: =(0)+(K22)
A23: 1 | B23: =IF(1=0,-'Inputs_Data'!H5,0) | C23: =IF(1=0,0,'Inputs_Data'!B6) | D23: =IF(1=0,0,'Inputs_Data'!E6) | E23: =(IF(1=0,-'Inputs_Data'!H5,0))+(IF(1=0,0,'Inputs_Data'!B6))-(IF(1=0,0,'Inputs_Data'!E6)) | F23: =(F22)+(E23) | G23: =IF(1=0,-'Inputs_Data'!H5,0) | H23: =IF(AND(1>=1,1<='Scenarios_10'!B6),MAX(0,(MAX(0,'Scenarios_10'!D6-'Scenarios_10'!E6/'Scenarios_10'!B6))-IF(AND(1>('Scenarios_10'!B6-4),1<='Scenarios_10'!B6),'Scenarios_10'!F6,0)),0) | I23: =IF(1=0,'Scenarios_10'!E6,0) | J23: =IF(1=0,0,IF('Scenarios_10'!C6="uniform_pct",'Inputs_Data'!E6*(1-(MIN('Scenarios_10'!G6,'Assumptions'!B10))),IF('Scenarios_10'!C6="electricity_only_pct",('Inputs_Data'!C6*(1-(MIN('Scenarios_10'!G6,'Assumptions'!B10))))+'Inputs_Data'!D6,0+('Inputs_Data'!D6*(1-AVERAGE('Assumptions'!B6,'Assumptions'!B7,'Assumptions'!B8,'Assumptions'!B9)))))) | K23: =(IF(1=0,-'Inputs_Data'!H5,0))+(IF(AND(1>=1,1<='Scenarios_10'!B6),MAX(0,(MAX(0,'Scenarios_10'!D6-'Scenarios_10'!E6/'Scenarios_10'!B6))-IF(AND(1>('Scenarios_10'!B6-4),1<='Scenarios_10'!B6),'Scenarios_10'!F6,0)),0))+(IF(1=0,'Scenarios_10'!E6,0))-(IF(1=0,0,IF('Scenarios_10'!C6="uniform_pct",'Inputs_Data'!E6*(1-(MIN('Scenarios_10'!G6,'Assumptions'!B10))),IF('Scenarios_10'!C6="electricity_only_pct",('Inputs_Data'!C6*(1-(MIN('Scenarios_10'!G6,'Assumptions'!B10))))+'Inputs_Data'!D6,0+('Inputs_Data'!D6*(1-AVERAGE('Assumptions'!B6,'Assumptions'!B7,'Assumptions'!B8,'Assumptions'!B9))))))) | L23: =(L22)+(K23)
A24: 2 | B24: =IF(2=0,-'Inputs_Data'!H5,0) | C24: =IF(2=0,0,'Inputs_Data'!B7) | D24: =IF(2=0,0,'Inputs_Data'!E7) | E24: =(IF(2=0,-'Inputs_Data'!H5,0))+(IF(2=0,0,'Inputs_Data'!B7))-(IF(2=0,0,'Inputs_Data'!E7)) | F24: =(F23)+(E24) | G24: =IF(2=0,-'Inputs_Data'!H5,0) | H24: =IF(AND(2>=1,2<='Scenarios_10'!B6),MAX(0,(MAX(0,'Scenarios_10'!D6-'Scenarios_10'!E6/'Scenarios_10'!B6))-IF(AND(2>('Scenarios_10'!B6-4),2<='Scenarios_10'!B6),'Scenarios_10'!F6,0)),0) | I24: =IF(2=0,'Scenarios_10'!E6,0) | J24: =IF(2=0,0,IF('Scenarios_10'!C6="uniform_pct",'Inputs_Data'!E7*(1-(MIN('Scenarios_10'!G6,'Assumptions'!B10))),IF('Scenarios_10'!C6="electricity_only_pct",('Inputs_Data'!C7*(1-(MIN('Scenarios_10'!G6,'Assumptions'!B10))))+'Inputs_Data'!D7,0+('Inputs_Data'!D7*(1-AVERAGE('Assumptions'!B6,'Assumptions'!B7,'Assumptions'!B8,'Assumptions'!B9)))))) | K24: =(IF(2=0,-'Inputs_Data'!H5,0))+(IF(AND(2>=1,2<='Scenarios_10'!B6),MAX(0,(MAX(0,'Scenarios_10'!D6-'Scenarios_10'!E6/'Scenarios_10'!B6))-IF(AND(2>('Scenarios_10'!B6-4),2<='Scenarios_10'!B6),'Scenarios_10'!F6,0)),0))+(IF(2=0,'Scenarios_10'!E6,0))-(IF(2=0,0,IF('Scenarios_10'!C6="uniform_pct",'Inputs_Data'!E7*(1-(MIN('Scenarios_10'!G6,'Assumptions'!B10))),IF('Scenarios_10'!C6="electricity_only_pct",('Inputs_Data'!C7*(1-(MIN('Scenarios_10'!G6,'Assumptions'!B10))))+'Inputs_Data'!D7,0+('Inputs_Data'!D7*(1-AVERAGE('Assumptions'!B6,'Assumptions'!B7,'Assumptions'!B8,'Assumptions'!B9))))))) | L24: =(L23)+(K24)
